Workbook

Sheet 日报总览
A1: KA大盘出货数据日报总览
A2: 总览页汇总所有主题sheet情况：出货大盘、单品出货/POS、库存周转、超60天门店排名，并提供源数据完整性提示。
B3: 统计日期 | C3: =MAX(销售明细!A2:A500) -> 46172 | E3: KA系统 | F3: 全部 | H3: 大区 | I3: 全部
B5: 出货数量 | D5: 出货金额 | H5: POS销售额 | J5: 出货/POS额 | M5: 超60天门店 | P5: 平均周转天数
B6: =SUM('1-KA大盘出货数据'!C7:C14) -> #VALUE! | D6: =SUM('1-KA大盘出货数据'!D7:D14) -> #VALUE! | H6: =SUM('1-KA大盘出货数据'!F7:F14) -> 182960 | J6: =IFERROR(D6/H6,0) -> 0 | M6: =SUM('4-超60天门店排名'!D7:D11) -> 0 | P6: =AVERAGE('3-门店库存周转天数'!G7:G12) -> 7.963512
B7: 自动汇总 | D7: 自动汇总 | H7: 自动汇总 | J7: 自动汇总 | M7: 自动汇总 | P7: 自动汇总
B10: 主题页情况一览
B11: 主题页 | C11: 关键词 | D11: 汇总指标 | E11: 图表数 | F11: 原始数据区 | G11: 当前状态 | H11: 跳转提示
B12: 1-KA大盘出货数据 | C12: 出货数量/金额、by单品、by渠道 | D12: =SUM('1-KA大盘出货数据'!D7:D14) -> #VALUE! | E12: 2 | F12: 出货退货明细 | G12: =IF(C12=0,"出货金额缺失","可用") -> 可用 | H12: 查看系统/单品/渠道出货
B13: 2-单品出货POS对比 | C13: 出货额、POS额、差异、比例 | D13: =SUM('2-单品出货POS对比'!F7:F12) -> 137220 | E13: 2 | F13: POS销售明细与出货明细 | G13: =IF(C13=0,"POS额缺失","可用") -> 可用 | H13: 查看单品差异
B14: 3-门店库存周转天数 | C14: 大区、单品、近7日均销、周转 | D14: =AVERAGE('3-门店库存周转天数'!G7:G12) -> 7.963512 | E14: 2 | F14: 库存明细 | G14: =IF(C14>60,"高风险","可用") -> 高风险 | H14: 查看周转风险
B15: 4-超60天门店排名 | C15: 大区、超60天门店数、排名 | D15: =SUM('4-超60天门店排名'!D7:D11) -> 0 | E15: 2 | F15: 超60天门店明细 | G15: =IF(C15>0,"需处理","正常") -> 需处理 | H15: 查看区域排名
B18: KA系统 | C18: 出货金额 | D18: POS销售额 | E18: 出货/POS额 | H18: 商品 | I18: 出货额 | J18: POS额 | K18: 出货/POS额
B19: ='1-KA大盘出货数据'!B7 -> 大润发 | C19: ='1-KA大盘出货数据'!D7 -> #VALUE! | D19: ='1-KA大盘出货数据'!F7 -> 22870 | E19: =IFERROR(C19/D19,0) -> 0 | H19: ='2-单品出货POS对比'!D7 -> 脱骨侠无骨鸡爪(柠檬味) | I19: ='2-单品出货POS对比'!E7 -> #VALUE! | J19: ='2-单品出货POS对比'!F7 -> 22870 | K19: ='2-单品出货POS对比'!H7 -> 0
B20: ='1-KA大盘出货数据'!B8 -> 盒马 | C20: ='1-KA大盘出货数据'!D8 -> #VALUE! | D20: ='1-KA大盘出货数据'!F8 -> 22870 | E20: =IFERROR(C20/D20,0) -> 0 | H20: ='2-单品出货POS对比'!D8 -> 脱骨侠虎皮凤爪(白松露味) | I20: ='2-单品出货POS对比'!E8 -> #VALUE! | J20: ='2-单品出货POS对比'!F8 -> 22870 | K20: ='2-单品出货POS对比'!H8 -> 0
B21: ='1-KA大盘出货数据'!B9 -> 华润 | C21: ='1-KA大盘出货数据'!D9 -> #VALUE! | D21: ='1-KA大盘出货数据'!F9 -> 22870 | E21: =IFERROR(C21/D21,0) -> 0 | H21: ='2-单品出货POS对比'!D9 -> 常温脱骨侠无骨鸡爪柠檬 | I21: ='2-单品出货POS对比'!E9 -> #VALUE! | J21: ='2-单品出货POS对比'!F9 -> 22870 | K21: ='2-单品出货POS对比'!H9 -> 0
B22: ='1-KA大盘出货数据'!B10 -> 沃尔玛 | C22: ='1-KA大盘出货数据'!D10 -> #VALUE! | D22: ='1-KA大盘出货数据'!F10 -> 22870 | E22: =IFERROR(C22/D22,0) -> 0 | H22: ='2-单品出货POS对比'!D10 -> 盒马工坊 蒜香无骨鸡爪 230g | I22: ='2-单品出货POS对比'!E10 -> #VALUE! | J22: ='2-单品出货POS对比'!F10 -> 22870 | K22: ='2-单品出货POS对比'!H10 -> 0
B23: ='1-KA大盘出货数据'!B11 -> 永辉 | C23: ='1-KA大盘出货数据'!D11 -> #VALUE! | D23: ='1-KA大盘出货数据'!F11 -> 22870 | E23: =IFERROR(C23/D23,0) -> 0 | H23: ='2-单品出货POS对比'!D11 -> 脱骨侠双椒无骨鸭掌 | I23: ='2-单品出货POS对比'!E11 -> #VALUE! | J23: ='2-单品出货POS对比'!F11 -> 22870 | K23: ='2-单品出货POS对比'!H11 -> 0
B24: ='1-KA大盘出货数据'!B12 -> 天虹 | C24: ='1-KA大盘出货数据'!D12 -> #VALUE! | D24: ='1-KA大盘出货数据'!F12 -> 22870 | E24: =IFERROR(C24/D24,0) -> 0 | H24: ='2-单品出货POS对比'!D12 -> 脱骨侠酸辣柠檬无骨鸡爪780g | I24: ='2-单品出货POS对比'!E12 -> #VALUE! | J24: ='2-单品出货POS对比'!F12 -> 22870 | K24: ='2-单品出货POS对比'!H12 -> 0
B25: ='1-KA大盘出货数据'!B13 -> 比优特 | C25: ='1-KA大盘出货数据'!D13 -> #VALUE! | D25: ='1-KA大盘出货数据'!F13 -> 22870 | E25: =IFERROR(C25/D25,0) -> 0
B26: ='1-KA大盘出货数据'!B14 -> 家得福 | C26: ='1-KA大盘出货数据'!D14 -> #VALUE! | D26: ='1-KA大盘出货数据'!F14 -> 22870 | E26: =IFERROR(C26/D26,0) -> 0
B30: 大区-单品 | C30: 门店库存 | D30: 近7日均销 | E30: 周转天数 | H30: 大区 | I30: 超60天门店数 | J30: 平均周转天数
B31: ='3-门店库存周转天数'!B7&"-"&'3-门店库存周转天数'!D7 -> 华东-脱骨侠无骨鸡爪(柠檬味) | C31: ='3-门店库存周转天数'!E7 -> 181584 | D31: ='3-门店库存周转天数'!F7 -> 22802 | E31: ='3-门店库存周转天数'!G7 -> 7.963512 | H31: ='4-超60天门店排名'!C7 | I31: ='4-超60天门店排名'!D7 -> 0 | J31: ='4-超60天门店排名'!G7
B32: ='3-门店库存周转天数'!B8&"-"&'3-门店库存周转天数'!D8 -> 华南-脱骨侠虎皮凤爪(白松露味) | C32: ='3-门店库存周转天数'!E8 -> 181584 | D32: ='3-门店库存周转天数'!F8 -> 22802 | E32: ='3-门店库存周转天数'!G8 -> 7.963512 | H32: ='4-超60天门店排名'!C8 | I32: ='4-超60天门店排名'!D8 -> 0 | J32: ='4-超60天门店排名'!G8
B33: ='3-门店库存周转天数'!B9&"-"&'3-门店库存周转天数'!D9 -> 华南-常温脱骨侠无骨鸡爪柠檬 | C33: ='3-门店库存周转天数'!E9 -> 181584 | D33: ='3-门店库存周转天数'!F9 -> 22802 | E33: ='3-门店库存周转天数'!G9 -> 7.963512 | H33: ='4-超60天门店排名'!C9 | I33: ='4-超60天门店排名'!D9 -> 0 | J33: ='4-超60天门店排名'!G9
B34: ='3-门店库存周转天数'!B10&"-"&'3-门店库存周转天数'!D10 -> 华北-脱骨侠无骨鸡爪(柠檬味)158g | C34: ='3-门店库存周转天数'!E10 -> 181584 | D34: ='3-门店库存周转天数'!F10 -> 22802 | E34: ='3-门店库存周转天数'!G10 -> 7.963512 | H34: ='4-超60天门店排名'!C10 | I34: ='4-超60天门店排名'!D10 -> 0 | J34: ='4-超60天门店排名'!G10
B35: ='3-门店库存周转天数'!B11&"-"&'3-门店库存周转天数'!D11 -> 华中-盒马工坊 蒜香无骨鸡爪 230g | C35: ='3-门店库存周转天数'!E11 -> 181584 | D35: ='3-门店库存周转天数'!F11 -> 22802 | E35: ='3-门店库存周转天数'!G11 -> 7.963512 | H35: ='4-超60天门店排名'!C11 | I35: ='4-超60天门店排名'!D11 -> 0 | J35: ='4-超60天门店排名'!G11
B36: ='3-门店库存周转天数'!B12&"-"&'3-门店库存周转天数'!D12 -> 华东-脱骨侠酸辣柠檬无骨鸡爪780g | C36: ='3-门店库存周转天数'!E12 -> 181584 | D36: ='3-门店库存周转天数'!F12 -> 22802 | E36: ='3-门店库存周转天数'!G12 -> 7.963512
B42: 源数据页 | C42: 记录数 | D42: 关键字段
B43: 销售明细 | C43: =COUNTA(销售明细!A2:A500) -> 15 | D43: 日期、系统、大区、门店、商品、渠道、销售数量、销售金额
B44: 库存明细 | C44: =COUNTA(库存明细!A2:A500) -> 9 | D44: 日期、系统、大区、门店、商品、库存、近7日平均销量、周转天数
B45: 出货退货 | C45: =COUNTA(出货退货!A2:A500) -> 4 | D45: 日期、系统、大区、门店、商品、出货数量、出货金额、退货
B54: 数据质量与业务提醒
B55: 检查项 | C55: 结果 | D55: 说明
B56: 销售明细行数 | C56: =COUNTA(销售明细!A2:A500) -> 15 | D56: POS销售、渠道、门店、商品字段来源
B57: 库存明细行数 | C57: =COUNTA(库存明细!A2:A500) -> 9 | D57: 库存、近7日平均销量、周转天数字段来源
B58: 出货退货行数 | C58: =COUNTA(出货退货!A2:A500) -> 4 | D58: 出货数量/金额、退货数量/金额字段来源
B59: 缺出货金额系统数 | C59: =COUNTIF('1-KA大盘出货数据'!J7:J14,"缺出货金额") -> 0 | D59: 出货金额缺失会影响出货/POS对比
B60: 超60天风险 | C60: =IF(SUM('4-超60天门店排名'!D7:D11)>0,"存在风险","正常") -> 正常 | D60: 优先处理超60天且库存高的门店

Sheet 1-KA大盘出货数据
A1: KA大盘出货数据
A2: 关键词：系统每天出货数量、出货金额；by单品、by渠道、by数量、by金额。
B3: 统计日期 | C3: =MAX(销售明细!A2:A500) -> 46172 | E3: KA系统 | F3: 全部 | H3: 大区 | I3: 全部 | K3: 省份 | L3: 全部
B5: 汇总：系统每天出货数量、出货金额（by系统/by数量/by金额）
B6: KA系统 | C6: 出货数量 | D6: 出货金额 | E6: POS销售数量 | F6: POS销售额 | G6: 出货/POS额 | H6: 退货数量 | I6: 退货金额 | J6: 数据状态
B7: 大润发 | C7: =SUMPRODUCT((出货退货!$A$2:$A$500=$C$3)*--((出货退货!$B$2:$B$500=B7)>0)*--((($I$3="全部")+(出货退货!$C$2:$C$500=$I$3))>0)*--((($L$3="全部")+(出货退货!$D$2:$D$500=$L$3))>0)*出货退货!$I$2:$I$500) -> #VALUE! | D7: =SUMPRODUCT((出货退货!$A$2:$A$500=$C$3)*--((出货退货!$B$2:$B$500=B7)>0)*--((($I$3="全部")+(出货退货!$C$2:$C$500=$I$3))>0)*--((($L$3="全部")+(出货退货!$D$2:$D$500=$L$3))>0)*出货退货!$J$2:$J$500) -> #VALUE! | E7: =SUMPRODUCT((销售明细!$A$2:$A$500=$C$3)*--((销售明细!$B$2:$B$500=B7)>0)*--((($I$3="全部")+(销售明细!$C$2:$C$500=$I$3))>0)*--((($L$3="全部")+(销售明细!$D$2:$D$500=$L$3))>0)*销售明细!$N$2:$N$500) -> 1423 | F7: =SUMPRODUCT((销售明细!$A$2:$A$500=$C$3)*--((销售明细!$B$2:$B$500=B7)>0)*--((($I$3="全部")+(销售明细!$C$2:$C$500=$I$3))>0)*--((($L$3="全部")+(销售明细!$D$2:$D$500=$L$3))>0)*销售明细!$O$2:$O$500) -> 22870 | G7: =IFERROR(D7/F7,0) -> 0 | H7: =SUMPRODUCT((出货退货!$A$2:$A$500=$C$3)*--((出货退货!$B$2:$B$500=B7)>0)*--((($I$3="全部")+(出货退货!$C$2:$C$500=$I$3))>0)*--((($L$3="全部")+(出货退货!$D$2:$D$500=$L$3))>0)*出货退货!$K$2:$K$500) -> #VALUE! | I7: =SUMPRODUCT((出货退货!$A$2:$A$500=$C$3)*--((出货退货!$B$2:$B$500=B7)>0)*--((($I$3="全部")+(出货退货!$C$2:$C$500=$I$3))>0)*--((($L$3="全部")+(出货退货!$D$2:$D$500=$L$3))>0)*出货退货!$L$2:$L$500) -> #VALUE! | J7: =IF(D7=0,"缺出货金额",IF(C7=0,"缺出货数量","可用")) -> #VALUE!
B8: 盒马 | C8: =SUMPRODUCT((出货退货!$A$2:$A$500=$C$3)*--((出货退货!$B$2:$B$500=B8)>0)*--((($I$3="全部")+(出货退货!$C$2:$C$500=$I$3))>0)*--((($L$3="全部")+(出货退货!$D$2:$D$500=$L$3))>0)*出货退货!$I$2:$I$500) -> #VALUE! | D8: =SUMPRODUCT((出货退货!$A$2:$A$500=$C$3)*--((出货退货!$B$2:$B$500=B8)>0)*--((($I$3="全部")+(出货退货!$C$2:$C$500=$I$3))>0)*--((($L$3="全部")+(出货退货!$D$2:$D$500=$L$3))>0)*出货退货!$J$2:$J$500) -> #VALUE! | E8: =SUMPRODUCT((销售明细!$A$2:$A$500=$C$3)*--((销售明细!$B$2:$B$500=B8)>0)*--((($I$3="全部")+(销售明细!$C$2:$C$500=$I$3))>0)*--((($L$3="全部")+(销售明细!$D$2:$D$500=$L$3))>0)*销售明细!$N$2:$N$500) -> 1423 | F8: =SUMPRODUCT((销售明细!$A$2:$A$500=$C$3)*--((销售明细!$B$2:$B$500=B8)>0)*--((($I$3="全部")+(销售明细!$C$2:$C$500=$I$3))>0)*--((($L$3="全部")+(销售明细!$D$2:$D$500=$L$3))>0)*销售明细!$O$2:$O$500) -> 22870 | G8: =IFERROR(D8/F8,0) -> 0 | H8: =SUMPRODUCT((出货退货!$A$2:$A$500=$C$3)*--((出货退货!$B$2:$B$500=B8)>0)*--((($I$3="全部")+(出货退货!$C$2:$C$500=$I$3))>0)*--((($L$3="全部")+(出货退货!$D$2:$D$500=$L$3))>0)*出货退货!$K$2:$K$500) -> #VALUE! | I8: =SUMPRODUCT((出货退货!$A$2:$A$500=$C$3)*--((出货退货!$B$2:$B$500=B8)>0)*--((($I$3="全部")+(出货退货!$C$2:$C$500=$I$3))>0)*--((($L$3="全部")+(出货退货!$D$2:$D$500=$L$3))>0)*出货退货!$L$2:$L$500) -> #VALUE! | J8: =IF(D8=0,"缺出货金额",IF(C8=0,"缺出货数量","可用")) -> #VALUE!
B9: 华润 | C9: =SUMPRODUCT((出货退货!$A$2:$A$500=$C$3)*--((出货退货!$B$2:$B$500=B9)>0)*--((($I$3="全部")+(出货退货!$C$2:$C$500=$I$3))>0)*--((($L$3="全部")+(出货退货!$D$2:$D$500=$L$3))>0)*出货退货!$I$2:$I$500) -> #VALUE! | D9: =SUMPRODUCT((出货退货!$A$2:$A$500=$C$3)*--((出货退货!$B$2:$B$500=B9)>0)*--((($I$3="全部")+(出货退货!$C$2:$C$500=$I$3))>0)*--((($L$3="全部")+(出货退货!$D$2:$D$500=$L$3))>0)*出货退货!$J$2:$J$500) -> #VALUE! | E9: =SUMPRODUCT((销售明细!$A$2:$A$500=$C$3)*--((销售明细!$B$2:$B$500=B9)>0)*--((($I$3="全部")+(销售明细!$C$2:$C$500=$I$3))>0)*--((($L$3="全部")+(销售明细!$D$2:$D$500=$L$3))>0)*销售明细!$N$2:$N$500) -> 1423 | F9: =SUMPRODUCT((销售明细!$A$2:$A$500=$C$3)*--((销售明细!$B$2:$B$500=B9)>0)*--((($I$3="全部")+(销售明细!$C$2:$C$500=$I$3))>0)*--((($L$3="全部")+(销售明细!$D$2:$D$500=$L$3))>0)*销售明细!$O$2:$O$500) -> 22870 | G9: =IFERROR(D9/F9,0) -> 0 | H9: =SUMPRODUCT((出货退货!$A$2:$A$500=$C$3)*--((出货退货!$B$2:$B$500=B9)>0)*--((($I$3="全部")+(出货退货!$C$2:$C$500=$I$3))>0)*--((($L$3="全部")+(出货退货!$D$2:$D$500=$L$3))>0)*出货退货!$K$2:$K$500) -> #VALUE! | I9: =SUMPRODUCT((出货退货!$A$2:$A$500=$C$3)*--((出货退货!$B$2:$B$500=B9)>0)*--((($I$3="全部")+(出货退货!$C$2:$C$500=$I$3))>0)*--((($L$3="全部")+(出货退货!$D$2:$D$500=$L$3))>0)*出货退货!$L$2:$L$500) -> #VALUE! | J9: =IF(D9=0,"缺出货金额",IF(C9=0,"缺出货数量","可用")) -> #VALUE!
B10: 沃尔玛 | C10: =SUMPRODUCT((出货退货!$A$2:$A$500=$C$3)*--((出货退货!$B$2:$B$500=B10)>0)*--((($I$3="全部")+(出货退货!$C$2:$C$500=$I$3))>0)*--((($L$3="全部")+(出货退货!$D$2:$D$500=$L$3))>0)*出货退货!$I$2:$I$500) -> #VALUE! | D10: =SUMPRODUCT((出货退货!$A$2:$A$500=$C$3)*--((出货退货!$B$2:$B$500=B10)>0)*--((($I$3="全部")+(出货退货!$C$2:$C$500=$I$3))>0)*--((($L$3="全部")+(出货退货!$D$2:$D$500=$L$3))>0)*出货退货!$J$2:$J$500) -> #VALUE! | E10: =SUMPRODUCT((销售明细!$A$2:$A$500=$C$3)*--((销售明细!$B$2:$B$500=B10)>0)*--((($I$3="全部")+(销售明细!$C$2:$C$500=$I$3))>0)*--((($L$3="全部")+(销售明细!$D$2:$D$500=$L$3))>0)*销售明细!$N$2:$N$500) -> 1423 | F10: =SUMPRODUCT((销售明细!$A$2:$A$500=$C$3)*--((销售明细!$B$2:$B$500=B10)>0)*--((($I$3="全部")+(销售明细!$C$2:$C$500=$I$3))>0)*--((($L$3="全部")+(销售明细!$D$2:$D$500=$L$3))>0)*销售明细!$O$2:$O$500) -> 22870 | G10: =IFERROR(D10/F10,0) -> 0 | H10: =SUMPRODUCT((出货退货!$A$2:$A$500=$C$3)*--((出货退货!$B$2:$B$500=B10)>0)*--((($I$3="全部")+(出货退货!$C$2:$C$500=$I$3))>0)*--((($L$3="全部")+(出货退货!$D$2:$D$500=$L$3))>0)*出货退货!$K$2:$K$500) -> #VALUE! | I10: =SUMPRODUCT((出货退货!$A$2:$A$500=$C$3)*--((出货退货!$B$2:$B$500=B10)>0)*--((($I$3="全部")+(出货退货!$C$2:$C$500=$I$3))>0)*--((($L$3="全部")+(出货退货!$D$2:$D$500=$L$3))>0)*出货退货!$L$2:$L$500) -> #VALUE! | J10: =IF(D10=0,"缺出货金额",IF(C10=0,"缺出货数量","可用")) -> #VALUE!
B11: 永辉 | C11: =SUMPRODUCT((出货退货!$A$2:$A$500=$C$3)*--((出货退货!$B$2:$B$500=B11)>0)*--((($I$3="全部")+(出货退货!$C$2:$C$500=$I$3))>0)*--((($L$3="全部")+(出货退货!$D$2:$D$500=$L$3))>0)*出货退货!$I$2:$I$500) -> #VALUE! | D11: =SUMPRODUCT((出货退货!$A$2:$A$500=$C$3)*--((出货退货!$B$2:$B$500=B11)>0)*--((($I$3="全部")+(出货退货!$C$2:$C$500=$I$3))>0)*--((($L$3="全部")+(出货退货!$D$2:$D$500=$L$3))>0)*出货退货!$J$2:$J$500) -> #VALUE! | E11: =SUMPRODUCT((销售明细!$A$2:$A$500=$C$3)*--((销售明细!$B$2:$B$500=B11)>0)*--((($I$3="全部")+(销售明细!$C$2:$C$500=$I$3))>0)*--((($L$3="全部")+(销售明细!$D$2:$D$500=$L$3))>0)*销售明细!$N$2:$N$500) -> 1423 | F11: =SUMPRODUCT((销售明细!$A$2:$A$500=$C$3)*--((销售明细!$B$2:$B$500=B11)>0)*--((($I$3="全部")+(销售明细!$C$2:$C$500=$I$3))>0)*--((($L$3="全部")+(销售明细!$D$2:$D$500=$L$3))>0)*销售明细!$O$2:$O$500) -> 22870 | G11: =IFERROR(D11/F11,0) -> 0 | H11: =SUMPRODUCT((出货退货!$A$2:$A$500=$C$3)*--((出货退货!$B$2:$B$500=B11)>0)*--((($I$3="全部")+(出货退货!$C$2:$C$500=$I$3))>0)*--((($L$3="全部")+(出货退货!$D$2:$D$500=$L$3))>0)*出货退货!$K$2:$K$500) -> #VALUE! | I11: =SUMPRODUCT((出货退货!$A$2:$A$500=$C$3)*--((出货退货!$B$2:$B$500=B11)>0)*--((($I$3="全部")+(出货退货!$C$2:$C$500=$I$3))>0)*--((($L$3="全部")+(出货退货!$D$2:$D$500=$L$3))>0)*出货退货!$L$2:$L$500) -> #VALUE! | J11: =IF(D11=0,"缺出货金额",IF(C11=0,"缺出货数量","可用")) -> #VALUE!
B12: 天虹 | C12: =SUMPRODUCT((出货退货!$A$2:$A$500=$C$3)*--((出货退货!$B$2:$B$500=B12)>0)*--((($I$3="全部")+(出货退货!$C$2:$C$500=$I$3))>0)*--((($L$3="全部")+(出货退货!$D$2:$D$500=$L$3))>0)*出货退货!$I$2:$I$500) -> #VALUE! | D12: =SUMPRODUCT((出货退货!$A$2:$A$500=$C$3)*--((出货退货!$B$2:$B$500=B12)>0)*--((($I$3="全部")+(出货退货!$C$2:$C$500=$I$3))>0)*--((($L$3="全部")+(出货退货!$D$2:$D$500=$L$3))>0)*出货退货!$J$2:$J$500) -> #VALUE! | E12: =SUMPRODUCT((销售明细!$A$2:$A$500=$C$3)*--((销售明细!$B$2:$B$500=B12)>0)*--((($I$3="全部")+(销售明细!$C$2:$C$500=$I$3))>0)*--((($L$3="全部")+(销售明细!$D$2:$D$500=$L$3))>0)*销售明细!$N$2:$N$500) -> 1423 | F12: =SUMPRODUCT((销售明细!$A$2:$A$500=$C$3)*--((销售明细!$B$2:$B$500=B12)>0)*--((($I$3="全部")+(销售明细!$C$2:$C$500=$I$3))>0)*--((($L$3="全部")+(销售明细!$D$2:$D$500=$L$3))>0)*销售明细!$O$2:$O$500) -> 22870 | G12: =IFERROR(D12/F12,0) -> 0 | H12: =SUMPRODUCT((出货退货!$A$2:$A$500=$C$3)*--((出货退货!$B$2:$B$500=B12)>0)*--((($I$3="全部")+(出货退货!$C$2:$C$500=$I$3))>0)*--((($L$3="全部")+(出货退货!$D$2:$D$500=$L$3))>0)*出货退货!$K$2:$K$500) -> #VALUE! | I12: =SUMPRODUCT((出货退货!$A$2:$A$500=$C$3)*--((出货退货!$B$2:$B$500=B12)>0)*--((($I$3="全部")+(出货退货!$C$2:$C$500=$I$3))>0)*--((($L$3="全部")+(出货退货!$D$2:$D$500=$L$3))>0)*出货退货!$L$2:$L$500) -> #VALUE! | J12: =IF(D12=0,"缺出货金额",IF(C12=0,"缺出货数量","可用")) -> #VALUE!
B13: 比优特 | C13: =SUMPRODUCT((出货退货!$A$2:$A$500=$C$3)*--((出货退货!$B$2:$B$500=B13)>0)*--((($I$3="全部")+(出货退货!$C$2:$C$500=$I$3))>0)*--((($L$3="全部")+(出货退货!$D$2:$D$500=$L$3))>0)*出货退货!$I$2:$I$500) -> #VALUE! | D13: =SUMPRODUCT((出货退货!$A$2:$A$500=$C$3)*--((出货退货!$B$2:$B$500=B13)>0)*--((($I$3="全部")+(出货退货!$C$2:$C$500=$I$3))>0)*--((($L$3="全部")+(出货退货!$D$2:$D$500=$L$3))>0)*出货退货!$J$2:$J$500) -> #VALUE! | E13: =SUMPRODUCT((销售明细!$A$2:$A$500=$C$3)*--((销售明细!$B$2:$B$500=B13)>0)*--((($I$3="全部")+(销售明细!$C$2:$C$500=$I$3))>0)*--((($L$3="全部")+(销售明细!$D$2:$D$500=$L$3))>0)*销售明细!$N$2:$N$500) -> 1423 | F13: =SUMPRODUCT((销售明细!$A$2:$A$500=$C$3)*--((销售明细!$B$2:$B$500=B13)>0)*--((($I$3="全部")+(销售明细!$C$2:$C$500=$I$3))>0)*--((($L$3="全部")+(销售明细!$D$2:$D$500=$L$3))>0)*销售明细!$O$2:$O$500) -> 22870 | G13: =IFERROR(D13/F13,0) -> 0 | H13: =SUMPRODUCT((出货退货!$A$2:$A$500=$C$3)*--((出货退货!$B$2:$B$500=B13)>0)*--((($I$3="全部")+(出货退货!$C$2:$C$500=$I$3))>0)*--((($L$3="全部")+(出货退货!$D$2:$D$500=$L$3))>0)*出货退货!$K$2:$K$500) -> #VALUE! | I13: =SUMPRODUCT((出货退货!$A$2:$A$500=$C$3)*--((出货退货!$B$2:$B$500=B13)>0)*--((($I$3="全部")+(出货退货!$C$2:$C$500=$I$3))>0)*--((($L$3="全部")+(出货退货!$D$2:$D$500=$L$3))>0)*出货退货!$L$2:$L$500) -> #VALUE! | J13: =IF(D13=0,"缺出货金额",IF(C13=0,"缺出货数量","可用")) -> #VALUE!
B14: 家得福 | C14: =SUMPRODUCT((出货退货!$A$2:$A$500=$C$3)*--((出货退货!$B$2:$B$500=B14)>0)*--((($I$3="全部")+(出货退货!$C$2:$C$500=$I$3))>0)*--((($L$3="全部")+(出货退货!$D$2:$D$500=$L$3))>0)*出货退货!$I$2:$I$500) -> #VALUE! | D14: =SUMPRODUCT((出货退货!$A$2:$A$500=$C$3)*--((出货退货!$B$2:$B$500=B14)>0)*--((($I$3="全部")+(出货退货!$C$2:$C$500=$I$3))>0)*--((($L$3="全部")+(出货退货!$D$2:$D$500=$L$3))>0)*出货退货!$J$2:$J$500) -> #VALUE! | E14: =SUMPRODUCT((销售明细!$A$2:$A$500=$C$3)*--((销售明细!$B$2:$B$500=B14)>0)*--((($I$3="全部")+(销售明细!$C$2:$C$500=$I$3))>0)*--((($L$3="全部")+(销售明细!$D$2:$D$500=$L$3))>0)*销售明细!$N$2:$N$500) -> 1423 | F14: =SUMPRODUCT((销售明细!$A$2:$A$500=$C$3)*--((销售明细!$B$2:$B$500=B14)>0)*--((($I$3="全部")+(销售明细!$C$2:$C$500=$I$3))>0)*--((($L$3="全部")+(销售明细!$D$2:$D$500=$L$3))>0)*销售明细!$O$2:$O$500) -> 22870 | G14: =IFERROR(D14/F14,0) -> 0 | H14: =SUMPRODUCT((出货退货!$A$2:$A$500=$C$3)*--((出货退货!$B$2:$B$500=B14)>0)*--((($I$3="全部")+(出货退货!$C$2:$C$500=$I$3))>0)*--((($L$3="全部")+(出货退货!$D$2:$D$500=$L$3))>0)*出货退货!$K$2:$K$500) -> #VALUE! | I14: =SUMPRODUCT((出货退货!$A$2:$A$500=$C$3)*--((出货退货!$B$2:$B$500=B14)>0)*--((($I$3="全部")+(出货退货!$C$2:$C$500=$I$3))>0)*--((($L$3="全部")+(出货退货!$D$2:$D$500=$L$3))>0)*出货退货!$L$2:$L$500) -> #VALUE! | J14: =IF(D14=0,"缺出货金额",IF(C14=0,"缺出货数量","可用")) -> #VALUE!
B17: 汇总：by单品
B18: 商品编码 | C18: 商品名称 | D18: KA系统 | E18: 出货数量 | F18: 出货金额 | G18: POS销售数量 | H18: POS销售额 | I18: 出货/POS额 | J18: 备注
B19: 4354168 | C19: 脱骨侠无骨鸡爪(柠檬味) | D19: 大润发 | E19: =SUMPRODUCT((出货退货!$A$2:$A$500=$C$3)*--((($F$3="全部")+(出货退货!$B$2:$B$500=$F$3))>0)*--((($I$3="全部")+(出货退货!$C$2:$C$500=$I$3))>0)*--((($L$3="全部")+(出货退货!$D$2:$D$500=$L$3))>0)*--((出货退货!$G$2:$G$500=B19)>0)*出货退货!$I$2:$I$500) -> #VALUE! | F19: =SUMPRODUCT((出货退货!$A$2:$A$500=$C$3)*--((($F$3="全部")+(出货退货!$B$2:$B$500=$F$3))>0)*--((($I$3="全部")+(出货退货!$C$2:$C$500=$I$3))>0)*--((($L$3="全部")+(出货退货!$D$2:$D$500=$L$3))>0)*--((出货退货!$G$2:$G$500=B19)>0)*出货退货!$J$2:$J$500) -> #VALUE! | G19: =SUMPRODUCT((销售明细!$A$2:$A$500=$C$3)*--((($F$3="全部")+(销售明细!$B$2:$B$500=$F$3))>0)*--((($I$3="全部")+(销售明细!$C$2:$C$500=$I$3))>0)*--((($L$3="全部")+(销售明细!$D$2:$D$500=$L$3))>0)*--((销售明细!$H$2:$H$500=B19)>0)*销售明细!$N$2:$N$500) -> 1423 | H19: =SUMPRODUCT((销售明细!$A$2:$A$500=$C$3)*--((($F$3="全部")+(销售明细!$B$2:$B$500=$F$3))>0)*--((($I$3="全部")+(销售明细!$C$2:$C$500=$I$3))>0)*--((($L$3="全部")+(销售明细!$D$2:$D$500=$L$3))>0)*--((销售明细!$H$2:$H$500=B19)>0)*销售明细!$O$2:$O$500) -> 22870 | I19: =IFERROR(F19/H19,0) -> 0 | J19: =IF(F19=0,"缺出货源","") -> #VALUE!
B20: 4502138 | C20: 脱骨侠虎皮凤爪(白松露味) | D20: 大润发 | E20: =SUMPRODUCT((出货退货!$A$2:$A$500=$C$3)*--((($F$3="全部")+(出货退货!$B$2:$B$500=$F$3))>0)*--((($I$3="全部")+(出货退货!$C$2:$C$500=$I$3))>0)*--((($L$3="全部")+(出货退货!$D$2:$D$500=$L$3))>0)*--((出货退货!$G$2:$G$500=B20)>0)*出货退货!$I$2:$I$500) -> #VALUE! | F20: =SUMPRODUCT((出货退货!$A$2:$A$500=$C$3)*--((($F$3="全部")+(出货退货!$B$2:$B$500=$F$3))>0)*--((($I$3="全部")+(出货退货!$C$2:$C$500=$I$3))>0)*--((($L$3="全部")+(出货退货!$D$2:$D$500=$L$3))>0)*--((出货退货!$G$2:$G$500=B20)>0)*出货退货!$J$2:$J$500) -> #VALUE! | G20: =SUMPRODUCT((销售明细!$A$2:$A$500=$C$3)*--((($F$3="全部")+(销售明细!$B$2:$B$500=$F$3))>0)*--((($I$3="全部")+(销售明细!$C$2:$C$500=$I$3))>0)*--((($L$3="全部")+(销售明细!$D$2:$D$500=$L$3))>0)*--((销售明细!$H$2:$H$500=B20)>0)*销售明细!$N$2:$N$500) -> 1423 | H20: =SUMPRODUCT((销售明细!$A$2:$A$500=$C$3)*--((($F$3="全部")+(销售明细!$B$2:$B$500=$F$3))>0)*--((($I$3="全部")+(销售明细!$C$2:$C$500=$I$3))>0)*--((($L$3="全部")+(销售明细!$D$2:$D$500=$L$3))>0)*--((销售明细!$H$2:$H$500=B20)>0)*销售明细!$O$2:$O$500) -> 22870 | I20: =IFERROR(F20/H20,0) -> 0 | J20: =IF(F20=0,"缺出货源","") -> #VALUE!
B21: 25354863 | C21: 常温脱骨侠无骨鸡爪柠檬 | D21: 沃尔玛 | E21: =SUMPRODUCT((出货退货!$A$2:$A$500=$C$3)*--((($F$3="全部")+(出货退货!$B$2:$B$500=$F$3))>0)*--((($I$3="全部")+(出货退货!$C$2:$C$500=$I$3))>0)*--((($L$3="全部")+(出货退货!$D$2:$D$500=$L$3))>0)*--((出货退货!$G$2:$G$500=B21)>0)*出货退货!$I$2:$I$500) -> #VALUE! | F21: =SUMPRODUCT((出货退货!$A$2:$A$500=$C$3)*--((($F$3="全部")+(出货退货!$B$2:$B$500=$F$3))>0)*--((($I$3="全部")+(出货退货!$C$2:$C$500=$I$3))>0)*--((($L$3="全部")+(出货退货!$D$2:$D$500=$L$3))>0)*--((出货退货!$G$2:$G$500=B21)>0)*出货退货!$J$2:$J$500) -> #VALUE! | G21: =SUMPRODUCT((销售明细!$A$2:$A$500=$C$3)*--((($F$3="全部")+(销售明细!$B$2:$B$500=$F$3))>0)*--((($I$3="全部")+(销售明细!$C$2:$C$500=$I$3))>0)*--((($L$3="全部")+(销售明细!$D$2:$D$500=$L$3))>0)*--((销售明细!$H$2:$H$500=B21)>0)*销售明细!$N$2:$N$500) -> 1423 | H21: =SUMPRODUCT((销售明细!$A$2:$A$500=$C$3)*--((($F$3="全部")+(销售明细!$B$2:$B$500=$F$3))>0)*--((($I$3="全部")+(销售明细!$C$2:$C$500=$I$3))>0)*--((($L$3="全部")+(销售明细!$D$2:$D$500=$L$3))>0)*--((销售明细!$H$2:$H$500=B21)>0)*销售明细!$O$2:$O$500) -> 22870 | I21: =IFERROR(F21/H21,0) -> 0 | J21: =IF(F21=0,"缺出货源","") -> #VALUE!
B22: 431448153 | C22: 盒马工坊 蒜香无骨鸡爪 230g | D22: 盒马 | E22: =SUMPRODUCT((出货退货!$A$2:$A$500=$C$3)*--((($F$3="全部")+(出货退货!$B$2:$B$500=$F$3))>0)*--((($I$3="全部")+(出货退货!$C$2:$C$500=$I$3))>0)*--((($L$3="全部")+(出货退货!$D$2:$D$500=$L$3))>0)*--((出货退货!$G$2:$G$500=B22)>0)*出货退货!$I$2:$I$500) -> #VALUE! | F22: =SUMPRODUCT((出货退货!$A$2:$A$500=$C$3)*--((($F$3="全部")+(出货退货!$B$2:$B$500=$F$3))>0)*--((($I$3="全部")+(出货退货!$C$2:$C$500=$I$3))>0)*--((($L$3="全部")+(出货退货!$D$2:$D$500=$L$3))>0)*--((出货退货!$G$2:$G$500=B22)>0)*出货退货!$J$2:$J$500) -> #VALUE! | G22: =SUMPRODUCT((销售明细!$A$2:$A$500=$C$3)*--((($F$3="全部")+(销售明细!$B$2:$B$500=$F$3))>0)*--((($I$3="全部")+(销售明细!$C$2:$C$500=$I$3))>0)*--((($L$3="全部")+(销售明细!$D$2:$D$500=$L$3))>0)*--((销售明细!$H$2:$H$500=B22)>0)*销售明细!$N$2:$N$500) -> 1423 | H22: =SUMPRODUCT((销售明细!$A$2:$A$500=$C$3)*--((($F$3="全部")+(销售明细!$B$2:$B$500=$F$3))>0)*--((($I$3="全部")+(销售明细!$C$2:$C$500=$I$3))>0)*--((($L$3="全部")+(销售明细!$D$2:$D$500=$L$3))>0)*--((销售明细!$H$2:$H$500=B22)>0)*销售明细!$O$2:$O$500) -> 22870 | I22: =IFERROR(F22/H22,0) -> 0 | J22: =IF(F22=0,"缺出货源","") -> #VALUE!
B23: v000110869 | C23: 脱骨侠双椒无骨鸭掌 | D23: 天虹 | E23: =SUMPRODUCT((出货退货!$A$2:$A$500=$C$3)*--((($F$3="全部")+(出货退货!$B$2:$B$500=$F$3))>0)*--((($I$3="全部")+(出货退货!$C$2:$C$500=$I$3))>0)*--((($L$3="全部")+(出货退货!$D$2:$D$500=$L$3))>0)*--((出货退货!$G$2:$G$500=B23)>0)*出货退货!$I$2:$I$500) -> #VALUE! | F23: =SUMPRODUCT((出货退货!$A$2:$A$500=$C$3)*--((($F$3="全部")+(出货退货!$B$2:$B$500=$F$3))>0)*--((($I$3="全部")+(出货退货!$C$2:$C$500=$I$3))>0)*--((($L$3="全部")+(出货退货!$D$2:$D$500=$L$3))>0)*--((出货退货!$G$2:$G$500=B23)>0)*出货退货!$J$2:$J$500) -> #VALUE! | G23: =SUMPRODUCT((销售明细!$A$2:$A$500=$C$3)*--((($F$3="全部")+(销售明细!$B$2:$B$500=$F$3))>0)*--((($I$3="全部")+(销售明细!$C$2:$C$500=$I$3))>0)*--((($L$3="全部")+(销售明细!$D$2:$D$500=$L$3))>0)*--((销售明细!$H$2:$H$500=B23)>0)*销售明细!$N$2:$N$500) -> 1423 | H23: =SUMPRODUCT((销售明细!$A$2:$A$500=$C$3)*--((($F$3="全部")+(销售明细!$B$2:$B$500=$F$3))>0)*--((($I$3="全部")+(销售明细!$C$2:$C$500=$I$3))>0)*--((($L$3="全部")+(销售明细!$D$2:$D$500=$L$3))>0)*--((销售明细!$H$2:$H$500=B23)>0)*销售明细!$O$2:$O$500) -> 22870 | I23: =IFERROR(F23/H23,0) -> 0 | J23: =IF(F23=0,"缺出货源","") -> #VALUE!
B24: 10081319 | C24: 脱骨侠酸辣柠檬无骨鸡爪780g | D24: 家得福 | E24: =SUMPRODUCT((出货退货!$A$2:$A$500=$C$3)*--((($F$3="全部")+(出货退货!$B$2:$B$500=$F$3))>0)*--((($I$3="全部")+(出货退货!$C$2:$C$500=$I$3))>0)*--((($L$3="全部")+(出货退货!$D$2:$D$500=$L$3))>0)*--((出货退货!$G$2:$G$500=B24)>0)*出货退货!$I$2:$I$500) -> #VALUE! | F24: =SUMPRODUCT((出货退货!$A$2:$A$500=$C$3)*--((($F$3="全部")+(出货退货!$B$2:$B$500=$F$3))>0)*--((($I$3="全部")+(出货退货!$C$2:$C$500=$I$3))>0)*--((($L$3="全部")+(出货退货!$D$2:$D$500=$L$3))>0)*--((出货退货!$G$2:$G$500=B24)>0)*出货退货!$J$2:$J$500) -> #VALUE! | G24: =SUMPRODUCT((销售明细!$A$2:$A$500=$C$3)*--((($F$3="全部")+(销售明细!$B$2:$B$500=$F$3))>0)*--((($I$3="全部")+(销售明细!$C$2:$C$500=$I$3))>0)*--((($L$3="全部")+(销售明细!$D$2:$D$500=$L$3))>0)*--((销售明细!$H$2:$H$500=B24)>0)*销售明细!$N$2:$N$500) -> 1423 | H24: =SUMPRODUCT((销售明细!$A$2:$A$500=$C$3)*--((($F$3="全部")+(销售明细!$B$2:$B$500=$F$3))>0)*--((($I$3="全部")+(销售明细!$C$2:$C$500=$I$3))>0)*--((($L$3="全部")+(销售明细!$D$2:$D$500=$L$3))>0)*--((销售明细!$H$2:$H$500=B24)>0)*销售明细!$O$2:$O$500) -> 22870 | I24: =IFERROR(F24/H24,0) -> 0 | J24: =IF(F24=0,"缺出货源","") -> #VALUE!
B27: 汇总：by渠道
B28: 渠道 | C28: POS销售数量 | D28: POS销售额 | E28: 出货数量 | F28: 出货金额 | G28: 出货/POS额 | H28: 说明
B29: POS | C29: =SUMPRODUCT((销售明细!$A$2:$A$500=$C$3)*--((($F$3="全部")+(销售明细!$B$2:$B$500=$F$3))>0)*--((($I$3="全部")+(销售明细!$C$2:$C$500=$I$3))>0)*--((($L$3="全部")+(销售明细!$D$2:$D$500=$L$3))>0)*--((销售明细!$M$2:$M$500=B29)>0)*销售明细!$N$2:$N$500) -> 1423 | D29: =SUMPRODUCT((销售明细!$A$2:$A$500=$C$3)*--((($F$3="全部")+(销售明细!$B$2:$B$500=$F$3))>0)*--((($I$3="全部")+(销售明细!$C$2:$C$500=$I$3))>0)*--((($L$3="全部")+(销售明细!$D$2:$D$500=$L$3))>0)*--((销售明细!$M$2:$M$500=B29)>0)*销售明细!$O$2:$O$500) -> 22870 | E29: =SUMPRODUCT((出货退货!$A$2:$A$500=$C$3)*--((($F$3="全部")+(出货退货!$B$2:$B$500=$F$3))>0)*--((($I$3="全部")+(出货退货!$C$2:$C$500=$I$3))>0)*--((($L$3="全部")+(出货退货!$D$2:$D$500=$L$3))>0)*出货退货!$I$2:$I$500) -> #VALUE! | F29: =SUMPRODUCT((出货退货!$A$2:$A$500=$C$3)*--((($F$3="全部")+(出货退货!$B$2:$B$500=$F$3))>0)*--((($I$3="全部")+(出货退货!$C$2:$C$500=$I$3))>0)*--((($L$3="全部")+(出货退货!$D$2:$D$500=$L$3))>0)*出货退货!$J$2:$J$500) -> #VALUE! | G29: =IFERROR(F29/D29,0) -> 0 | H29: 渠道出货需出货源提供渠道字段；当前出货按筛选总额展示
B30: 线下 | C30: =SUMPRODUCT((销售明细!$A$2:$A$500=$C$3)*--((($F$3="全部")+(销售明细!$B$2:$B$500=$F$3))>0)*--((($I$3="全部")+(销售明细!$C$2:$C$500=$I$3))>0)*--((($L$3="全部")+(销售明细!$D$2:$D$500=$L$3))>0)*--((销售明细!$M$2:$M$500=B30)>0)*销售明细!$N$2:$N$500) -> 1423 | D30: =SUMPRODUCT((销售明细!$A$2:$A$500=$C$3)*--((($F$3="全部")+(销售明细!$B$2:$B$500=$F$3))>0)*--((($I$3="全部")+(销售明细!$C$2:$C$500=$I$3))>0)*--((($L$3="全部")+(销售明细!$D$2:$D$500=$L$3))>0)*--((销售明细!$M$2:$M$500=B30)>0)*销售明细!$O$2:$O$500) -> 22870 | E30: =SUMPRODUCT((出货退货!$A$2:$A$500=$C$3)*--((($F$3="全部")+(出货退货!$B$2:$B$500=$F$3))>0)*--((($I$3="全部")+(出货退货!$C$2:$C$500=$I$3))>0)*--((($L$3="全部")+(出货退货!$D$2:$D$500=$L$3))>0)*出货退货!$I$2:$I$500) -> #VALUE! | F30: =SUMPRODUCT((出货退货!$A$2:$A$500=$C$3)*--((($F$3="全部")+(出货退货!$B$2:$B$500=$F$3))>0)*--((($I$3="全部")+(出货退货!$C$2:$C$500=$I$3))>0)*--((($L$3="全部")+(出货退货!$D$2:$D$500=$L$3))>0)*出货退货!$J$2:$J$500) -> #VALUE! | G30: =IFERROR(F30/D30,0) -> 0 | H30: 渠道出货需出货源提供渠道字段；当前出货按筛选总额展示
B31: 京东到家 | C31: =SUMPRODUCT((销售明细!$A$2:$A$500=$C$3)*--((($F$3="全部")+(销售明细!$B$2:$B$500=$F$3))>0)*--((($I$3="全部")+(销售明细!$C$2:$C$500=$I$3))>0)*--((($L$3="全部")+(销售明细!$D$2:$D$500=$L$3))>0)*--((销售明细!$M$2:$M$500=B31)>0)*销售明细!$N$2:$N$500) -> 1423 | D31: =SUMPRODUCT((销售明细!$A$2:$A$500=$C$3)*--((($F$3="全部")+(销售明细!$B$2:$B$500=$F$3))>0)*--((($I$3="全部")+(销售明细!$C$2:$C$500=$I$3))>0)*--((($L$3="全部")+(销售明细!$D$2:$D$500=$L$3))>0)*--((销售明细!$M$2:$M$500=B31)>0)*销售明细!$O$2:$O$500) -> 22870 | E31: =SUMPRODUCT((出货退货!$A$2:$A$500=$C$3)*--((($F$3="全部")+(出货退货!$B$2:$B$500=$F$3))>0)*--((($I$3="全部")+(出货退货!$C$2:$C$500=$I$3))>0)*--((($L$3="全部")+(出货退货!$D$2:$D$500=$L$3))>0)*出货退货!$I$2:$I$500) -> #VALUE! | F31: =SUMPRODUCT((出货退货!$A$2:$A$500=$C$3)*--((($F$3="全部")+(出货退货!$B$2:$B$500=$F$3))>0)*--((($I$3="全部")+(出货退货!$C$2:$C$500=$I$3))>0)*--((($L$3="全部")+(出货退货!$D$2:$D$500=$L$3))>0)*出货退货!$J$2:$J$500) -> #VALUE! | G31: =IFERROR(F31/D31,0) -> 0 | H31: 渠道出货需出货源提供渠道字段；当前出货按筛选总额展示
B32: 美团 | C32: =SUMPRODUCT((销售明细!$A$2:$A$500=$C$3)*--((($F$3="全部")+(销售明细!$B$2:$B$500=$F$3))>0)*--((($I$3="全部")+(销售明细!$C$2:$C$500=$I$3))>0)*--((($L$3="全部")+(销售明细!$D$2:$D$500=$L$3))>0)*--((销售明细!$M$2:$M$500=B32)>0)*销售明细!$N$2:$N$500) -> 1423 | D32: =SUMPRODUCT((销售明细!$A$2:$A$500=$C$3)*--((($F$3="全部")+(销售明细!$B$2:$B$500=$F$3))>0)*--((($I$3="全部")+(销售明细!$C$2:$C$500=$I$3))>0)*--((($L$3="全部")+(销售明细!$D$2:$D$500=$L$3))>0)*--((销售明细!$M$2:$M$500=B32)>0)*销售明细!$O$2:$O$500) -> 22870 | E32: =SUMPRODUCT((出货退货!$A$2:$A$500=$C$3)*--((($F$3="全部")+(出货退货!$B$2:$B$500=$F$3))>0)*--((($I$3="全部")+(出货退货!$C$2:$C$500=$I$3))>0)*--((($L$3="全部")+(出货退货!$D$2:$D$500=$L$3))>0)*出货退货!$I$2:$I$500) -> #VALUE! | F32: =SUMPRODUCT((出货退货!$A$2:$A$500=$C$3)*--((($F$3="全部")+(出货退货!$B$2:$B$500=$F$3))>0)*--((($I$3="全部")+(出货退货!$C$2:$C$500=$I$3))>0)*--((($L$3="全部")+(出货退货!$D$2:$D$500=$L$3))>0)*出货退货!$J$2:$J$500) -> #VALUE! | G32: =IFERROR(F32/D32,0) -> 0 | H32: 渠道出货需出货源提供渠道字段；当前出货按筛选总额展示
B33: 天虹到家 | C33: =SUMPRODUCT((销售明细!$A$2:$A$500=$C$3)*--((($F$3="全部")+(销售明细!$B$2:$B$500=$F$3))>0)*--((($I$3="全部")+(销售明细!$C$2:$C$500=$I$3))>0)*--((($L$3="全部")+(销售明细!$D$2:$D$500=$L$3))>0)*--((销售明细!$M$2:$M$500=B33)>0)*销售明细!$N$2:$N$500) -> 1423 | D33: =SUMPRODUCT((销售明细!$A$2:$A$500=$C$3)*--((($F$3="全部")+(销售明细!$B$2:$B$500=$F$3))>0)*--((($I$3="全部")+(销售明细!$C$2:$C$500=$I$3))>0)*--((($L$3="全部")+(销售明细!$D$2:$D$500=$L$3))>0)*--((销售明细!$M$2:$M$500=B33)>0)*销售明细!$O$2:$O$500) -> 22870 | E33: =SUMPRODUCT((出货退货!$A$2:$A$500=$C$3)*--((($F$3="全部")+(出货退货!$B$2:$B$500=$F$3))>0)*--((($I$3="全部")+(出货退货!$C$2:$C$500=$I$3))>0)*--((($L$3="全部")+(出货退货!$D$2:$D$500=$L$3))>0)*出货退货!$I$2:$I$500) -> #VALUE! | F33: =SUMPRODUCT((出货退货!$A$2:$A$500=$C$3)*--((($F$3="全部")+(出货退货!$B$2:$B$500=$F$3))>0)*--((($I$3="全部")+(出货退货!$C$2:$C$500=$I$3))>0)*--((($L$3="全部")+(出货退货!$D$2:$D$500=$L$3))>0)*出货退货!$J$2:$J$500) -> #VALUE! | G33: =IFERROR(F33/D33,0) -> 0 | H33: 渠道出货需出货源提供渠道字段；当前出货按筛选总额展示
B36: 原始数据：出货退货明细
B37: 数据日期 | C37: KA系统 | D37: 大区 | E37: 省份 | F37: 门店编码 | G37: 门店名称 | H37: 商品编码 | I37: 商品名称 | J37: 出货数量 | K37: 出货金额 | L37: 退货数量 | M37: 退货金额 | N37: 来源
B38: =出货退货!A2 -> 46172 | C38: =出货退货!B2 -> 盒马 | D38: =出货退货!C2 -> 华中 | E38: =出货退货!D2 -> 湖北 | F38: =出货退货!E2 -> HM001 | G38: =出货退货!F2 -> 武汉珞狮路店 | H38: =出货退货!G2 -> 431448153 | I38: =出货退货!H2 -> 盒马工坊 蒜香无骨鸡爪 230g | ... N38: =出货退货!M2 -> 当天入库采购件数数量
B39: =出货退货!A3 -> 46172 | C39: =出货退货!B3 -> 家得福 | D39: =出货退货!C3 -> 华东 | E39: =出货退货!D3 -> 江苏 | F39: =出货退货!E3 -> 1001 | G39: =出货退货!F3 -> 家得福海棠店 | H39: =出货退货!G3 -> 10081319 | I39: =出货退货!H3 -> 脱骨侠酸辣柠檬无骨鸡爪780g | ... N39: =出货退货!M3 -> 进货数量/含税进货金额
B40: =出货退货!A4 -> 46172 | C40: =出货退货!B4 -> 大润发 | D40: =出货退货!C4 -> 华东 | E40: =出货退货!D4 -> 上海 | F40: =出货退货!E4 -> 1001 | G40: =出货退货!F4 -> 闸北店 | H40: =出货退货!G4 -> 4354168 | I40: =出货退货!H4 -> 脱骨侠无骨鸡爪(柠檬味) | ... N40: =出货退货!M4 -> 待收
B41: =出货退货!A5 -> 46172 | C41: =出货退货!B5 -> 沃尔玛 | D41: =出货退货!C5 -> 华南 | E41: =出货退货!D5 -> 广东 | F41: =出货退货!E5 -> 101 | G41: =出货退货!F5 -> 沃尔玛广州天河店 | H41: =出货退货!G5 -> 25354863 | I41: =出货退货!H5 -> 常温脱骨侠无骨鸡爪柠檬 | ... N41: =出货退货!M5 -> 缺进货源
B42: =出货退货!A6 -> 0 | C42: =出货退货!B6 -> 0 | D42: =出货退货!C6 -> 0 | E42: =出货退货!D6 -> 0 | F42: =出货退货!E6 -> 0 | G42: =出货退货!F6 -> 0 | H42: =出货退货!G6 -> 0 | I42: =出货退货!H6 -> 0 | ... N42: =出货退货!M6 -> 0
B43: =出货退货!A7 -> 0 | C43: =出货退货!B7 -> 0 | D43: =出货退货!C7 -> 0 | E43: =出货退货!D7 -> 0 | F43: =出货退货!E7 -> 0 | G43: =出货退货!F7 -> 0 | H43: =出货退货!G7 -> 0 | I43: =出货退货!H7 -> 0 | ... N43: =出货退货!M7 -> 0
B44: =出货退货!A8 -> 0 | C44: =出货退货!B8 -> 0 | D44: =出货退货!C8 -> 0 | E44: =出货退货!D8 -> 0 | F44: =出货退货!E8 -> 0 | G44: =出货退货!F8 -> 0 | H44: =出货退货!G8 -> 0 | I44: =出货退货!H8 -> 0 | ... N44: =出货退货!M8 -> 0
B45: =出货退货!A9 -> 0 | C45: =出货退货!B9 -> 0 | D45: =出货退货!C9 -> 0 | E45: =出货退货!D9 -> 0 | F45: =出货退货!E9 -> 0 | G45: =出货退货!F9 -> 0 | H45: =出货退货!G9 -> 0 | I45: =出货退货!H9 -> 0 | ... N45: =出货退货!M9 -> 0
B46: =出货退货!A10 -> 0 | C46: =出货退货!B10 -> 0 | D46: =出货退货!C10 -> 0 | E46: =出货退货!D10 -> 0 | F46: =出货退货!E10 -> 0 | G46: =出货退货!F10 -> 0 | H46: =出货退货!G10 -> 0 | I46: =出货退货!H10 -> 0 | ... N46: =出货退货!M10 -> 0
B47: =出货退货!A11 -> 0 | C47: =出货退货!B11 -> 0 | D47: =出货退货!C11 -> 0 | E47: =出货退货!D11 -> 0 | F47: =出货退货!E11 -> 0 | G47: =出货退货!F11 -> 0 | H47: =出货退货!G11 -> 0 | I47: =出货退货!H11 -> 0 | ... N47: =出货退货!M11 -> 0
...

Sheet 2-单品出货POS对比
A1: 系统单品出货额和POS额对比
A2: 关键词：系统、单品、出货额、POS额、差异、比例。
B3: 统计日期 | C3: =MAX(销售明细!A2:A500) -> 46172 | E3: KA系统 | F3: 全部 | H3: 大区 | I3: 全部 | K3: 省份 | L3: 全部
B5: 汇总：系统单品出货额和POS额对比
B6: KA系统 | C6: 商品编码 | D6: 商品名称 | E6: 出货额 | F6: POS额 | G6: 差异 | H6: 出货/POS额 | I6: 出货数量 | J6: POS销量 | K6: 状态
B7: 大润发 | C7: 4354168 | D7: 脱骨侠无骨鸡爪(柠檬味) | E7: =SUMPRODUCT((出货退货!$A$2:$A$500=$C$3)*--((($F$3="全部")+(出货退货!$B$2:$B$500=$F$3))>0)*--((($I$3="全部")+(出货退货!$C$2:$C$500=$I$3))>0)*--((($L$3="全部")+(出货退货!$D$2:$D$500=$L$3))>0)*--((出货退货!$B$2:$B$500=B7)>0)*--((出货退货!$G$2:$G$500=C7)>0)*出货退货!$J$2:$J$500) -> #VALUE! | F7: =SUMPRODUCT((销售明细!$A$2:$A$500=$C$3)*--((($F$3="全部")+(销售明细!$B$2:$B$500=$F$3))>0)*--((($I$3="全部")+(销售明细!$C$2:$C$500=$I$3))>0)*--((($L$3="全部")+(销售明细!$D$2:$D$500=$L$3))>0)*--((销售明细!$B$2:$B$500=B7)>0)*--((销售明细!$H$2:$H$500=C7)>0)*销售明细!$O$2:$O$500) -> 22870 | G7: =E7-F7 -> #VALUE! | H7: =IFERROR(E7/F7,0) -> 0 | I7: =SUMPRODUCT((出货退货!$A$2:$A$500=$C$3)*--((($F$3="全部")+(出货退货!$B$2:$B$500=$F$3))>0)*--((($I$3="全部")+(出货退货!$C$2:$C$500=$I$3))>0)*--((($L$3="全部")+(出货退货!$D$2:$D$500=$L$3))>0)*--((出货退货!$B$2:$B$500=B7)>0)*--((出货退货!$G$2:$G$500=C7)>0)*出货退货!$I$2:$I$500) -> #VALUE! | J7: =SUMPRODUCT((销售明细!$A$2:$A$500=$C$3)*--((($F$3="全部")+(销售明细!$B$2:$B$500=$F$3))>0)*--((($I$3="全部")+(销售明细!$C$2:$C$500=$I$3))>0)*--((($L$3="全部")+(销售明细!$D$2:$D$500=$L$3))>0)*--((销售明细!$B$2:$B$500=B7)>0)*--((销售明细!$H$2:$H$500=C7)>0)*销售明细!$N$2:$N$500) -> 1423 | K7: =IF(E7=0,"缺出货源",IF(H7<0.8,"出货低于POS",IF(H7>1.2,"出货高于POS","匹配"))) -> #VALUE!
B8: 大润发 | C8: 4502138 | D8: 脱骨侠虎皮凤爪(白松露味) | E8: =SUMPRODUCT((出货退货!$A$2:$A$500=$C$3)*--((($F$3="全部")+(出货退货!$B$2:$B$500=$F$3))>0)*--((($I$3="全部")+(出货退货!$C$2:$C$500=$I$3))>0)*--((($L$3="全部")+(出货退货!$D$2:$D$500=$L$3))>0)*--((出货退货!$B$2:$B$500=B8)>0)*--((出货退货!$G$2:$G$500=C8)>0)*出货退货!$J$2:$J$500) -> #VALUE! | F8: =SUMPRODUCT((销售明细!$A$2:$A$500=$C$3)*--((($F$3="全部")+(销售明细!$B$2:$B$500=$F$3))>0)*--((($I$3="全部")+(销售明细!$C$2:$C$500=$I$3))>0)*--((($L$3="全部")+(销售明细!$D$2:$D$500=$L$3))>0)*--((销售明细!$B$2:$B$500=B8)>0)*--((销售明细!$H$2:$H$500=C8)>0)*销售明细!$O$2:$O$500) -> 22870 | G8: =E8-F8 -> #VALUE! | H8: =IFERROR(E8/F8,0) -> 0 | I8: =SUMPRODUCT((出货退货!$A$2:$A$500=$C$3)*--((($F$3="全部")+(出货退货!$B$2:$B$500=$F$3))>0)*--((($I$3="全部")+(出货退货!$C$2:$C$500=$I$3))>0)*--((($L$3="全部")+(出货退货!$D$2:$D$500=$L$3))>0)*--((出货退货!$B$2:$B$500=B8)>0)*--((出货退货!$G$2:$G$500=C8)>0)*出货退货!$I$2:$I$500) -> #VALUE! | J8: =SUMPRODUCT((销售明细!$A$2:$A$500=$C$3)*--((($F$3="全部")+(销售明细!$B$2:$B$500=$F$3))>0)*--((($I$3="全部")+(销售明细!$C$2:$C$500=$I$3))>0)*--((($L$3="全部")+(销售明细!$D$2:$D$500=$L$3))>0)*--((销售明细!$B$2:$B$500=B8)>0)*--((销售明细!$H$2:$H$500=C8)>0)*销售明细!$N$2:$N$500) -> 1423 | K8: =IF(E8=0,"缺出货源",IF(H8<0.8,"出货低于POS",IF(H8>1.2,"出货高于POS","匹配"))) -> #VALUE!
B9: 沃尔玛 | C9: 25354863 | D9: 常温脱骨侠无骨鸡爪柠檬 | E9: =SUMPRODUCT((出货退货!$A$2:$A$500=$C$3)*--((($F$3="全部")+(出货退货!$B$2:$B$500=$F$3))>0)*--((($I$3="全部")+(出货退货!$C$2:$C$500=$I$3))>0)*--((($L$3="全部")+(出货退货!$D$2:$D$500=$L$3))>0)*--((出货退货!$B$2:$B$500=B9)>0)*--((出货退货!$G$2:$G$500=C9)>0)*出货退货!$J$2:$J$500) -> #VALUE! | F9: =SUMPRODUCT((销售明细!$A$2:$A$500=$C$3)*--((($F$3="全部")+(销售明细!$B$2:$B$500=$F$3))>0)*--((($I$3="全部")+(销售明细!$C$2:$C$500=$I$3))>0)*--((($L$3="全部")+(销售明细!$D$2:$D$500=$L$3))>0)*--((销售明细!$B$2:$B$500=B9)>0)*--((销售明细!$H$2:$H$500=C9)>0)*销售明细!$O$2:$O$500) -> 22870 | G9: =E9-F9 -> #VALUE! | H9: =IFERROR(E9/F9,0) -> 0 | I9: =SUMPRODUCT((出货退货!$A$2:$A$500=$C$3)*--((($F$3="全部")+(出货退货!$B$2:$B$500=$F$3))>0)*--((($I$3="全部")+(出货退货!$C$2:$C$500=$I$3))>0)*--((($L$3="全部")+(出货退货!$D$2:$D$500=$L$3))>0)*--((出货退货!$B$2:$B$500=B9)>0)*--((出货退货!$G$2:$G$500=C9)>0)*出货退货!$I$2:$I$500) -> #VALUE! | J9: =SUMPRODUCT((销售明细!$A$2:$A$500=$C$3)*--((($F$3="全部")+(销售明细!$B$2:$B$500=$F$3))>0)*--((($I$3="全部")+(销售明细!$C$2:$C$500=$I$3))>0)*--((($L$3="全部")+(销售明细!$D$2:$D$500=$L$3))>0)*--((销售明细!$B$2:$B$500=B9)>0)*--((销售明细!$H$2:$H$500=C9)>0)*销售明细!$N$2:$N$500) -> 1423 | K9: =IF(E9=0,"缺出货源",IF(H9<0.8,"出货低于POS",IF(H9>1.2,"出货高于POS","匹配"))) -> #VALUE!
B10: 盒马 | C10: 431448153 | D10: 盒马工坊 蒜香无骨鸡爪 230g | E10: =SUMPRODUCT((出货退货!$A$2:$A$500=$C$3)*--((($F$3="全部")+(出货退货!$B$2:$B$500=$F$3))>0)*--((($I$3="全部")+(出货退货!$C$2:$C$500=$I$3))>0)*--((($L$3="全部")+(出货退货!$D$2:$D$500=$L$3))>0)*--((出货退货!$B$2:$B$500=B10)>0)*--((出货退货!$G$2:$G$500=C10)>0)*出货退货!$J$2:$J$500) -> #VALUE! | F10: =SUMPRODUCT((销售明细!$A$2:$A$500=$C$3)*--((($F$3="全部")+(销售明细!$B$2:$B$500=$F$3))>0)*--((($I$3="全部")+(销售明细!$C$2:$C$500=$I$3))>0)*--((($L$3="全部")+(销售明细!$D$2:$D$500=$L$3))>0)*--((销售明细!$B$2:$B$500=B10)>0)*--((销售明细!$H$2:$H$500=C10)>0)*销售明细!$O$2:$O$500) -> 22870 | G10: =E10-F10 -> #VALUE! | H10: =IFERROR(E10/F10,0) -> 0 | I10: =SUMPRODUCT((出货退货!$A$2:$A$500=$C$3)*--((($F$3="全部")+(出货退货!$B$2:$B$500=$F$3))>0)*--((($I$3="全部")+(出货退货!$C$2:$C$500=$I$3))>0)*--((($L$3="全部")+(出货退货!$D$2:$D$500=$L$3))>0)*--((出货退货!$B$2:$B$500=B10)>0)*--((出货退货!$G$2:$G$500=C10)>0)*出货退货!$I$2:$I$500) -> #VALUE! | J10: =SUMPRODUCT((销售明细!$A$2:$A$500=$C$3)*--((($F$3="全部")+(销售明细!$B$2:$B$500=$F$3))>0)*--((($I$3="全部")+(销售明细!$C$2:$C$500=$I$3))>0)*--((($L$3="全部")+(销售明细!$D$2:$D$500=$L$3))>0)*--((销售明细!$B$2:$B$500=B10)>0)*--((销售明细!$H$2:$H$500=C10)>0)*销售明细!$N$2:$N$500) -> 1423 | K10: =IF(E10=0,"缺出货源",IF(H10<0.8,"出货低于POS",IF(H10>1.2,"出货高于POS","匹配"))) -> #VALUE!
B11: 天虹 | C11: v000110869 | D11: 脱骨侠双椒无骨鸭掌 | E11: =SUMPRODUCT((出货退货!$A$2:$A$500=$C$3)*--((($F$3="全部")+(出货退货!$B$2:$B$500=$F$3))>0)*--((($I$3="全部")+(出货退货!$C$2:$C$500=$I$3))>0)*--((($L$3="全部")+(出货退货!$D$2:$D$500=$L$3))>0)*--((出货退货!$B$2:$B$500=B11)>0)*--((出货退货!$G$2:$G$500=C11)>0)*出货退货!$J$2:$J$500) -> #VALUE! | F11: =SUMPRODUCT((销售明细!$A$2:$A$500=$C$3)*--((($F$3="全部")+(销售明细!$B$2:$B$500=$F$3))>0)*--((($I$3="全部")+(销售明细!$C$2:$C$500=$I$3))>0)*--((($L$3="全部")+(销售明细!$D$2:$D$500=$L$3))>0)*--((销售明细!$B$2:$B$500=B11)>0)*--((销售明细!$H$2:$H$500=C11)>0)*销售明细!$O$2:$O$500) -> 22870 | G11: =E11-F11 -> #VALUE! | H11: =IFERROR(E11/F11,0) -> 0 | I11: =SUMPRODUCT((出货退货!$A$2:$A$500=$C$3)*--((($F$3="全部")+(出货退货!$B$2:$B$500=$F$3))>0)*--((($I$3="全部")+(出货退货!$C$2:$C$500=$I$3))>0)*--((($L$3="全部")+(出货退货!$D$2:$D$500=$L$3))>0)*--((出货退货!$B$2:$B$500=B11)>0)*--((出货退货!$G$2:$G$500=C11)>0)*出货退货!$I$2:$I$500) -> #VALUE! | J11: =SUMPRODUCT((销售明细!$A$2:$A$500=$C$3)*--((($F$3="全部")+(销售明细!$B$2:$B$500=$F$3))>0)*--((($I$3="全部")+(销售明细!$C$2:$C$500=$I$3))>0)*--((($L$3="全部")+(销售明细!$D$2:$D$500=$L$3))>0)*--((销售明细!$B$2:$B$500=B11)>0)*--((销售明细!$H$2:$H$500=C11)>0)*销售明细!$N$2:$N$500) -> 1423 | K11: =IF(E11=0,"缺出货源",IF(H11<0.8,"出货低于POS",IF(H11>1.2,"出货高于POS","匹配"))) -> #VALUE!
B12: 家得福 | C12: 10081319 | D12: 脱骨侠酸辣柠檬无骨鸡爪780g | E12: =SUMPRODUCT((出货退货!$A$2:$A$500=$C$3)*--((($F$3="全部")+(出货退货!$B$2:$B$500=$F$3))>0)*--((($I$3="全部")+(出货退货!$C$2:$C$500=$I$3))>0)*--((($L$3="全部")+(出货退货!$D$2:$D$500=$L$3))>0)*--((出货退货!$B$2:$B$500=B12)>0)*--((出货退货!$G$2:$G$500=C12)>0)*出货退货!$J$2:$J$500) -> #VALUE! | F12: =SUMPRODUCT((销售明细!$A$2:$A$500=$C$3)*--((($F$3="全部")+(销售明细!$B$2:$B$500=$F$3))>0)*--((($I$3="全部")+(销售明细!$C$2:$C$500=$I$3))>0)*--((($L$3="全部")+(销售明细!$D$2:$D$500=$L$3))>0)*--((销售明细!$B$2:$B$500=B12)>0)*--((销售明细!$H$2:$H$500=C12)>0)*销售明细!$O$2:$O$500) -> 22870 | G12: =E12-F12 -> #VALUE! | H12: =IFERROR(E12/F12,0) -> 0 | I12: =SUMPRODUCT((出货退货!$A$2:$A$500=$C$3)*--((($F$3="全部")+(出货退货!$B$2:$B$500=$F$3))>0)*--((($I$3="全部")+(出货退货!$C$2:$C$500=$I$3))>0)*--((($L$3="全部")+(出货退货!$D$2:$D$500=$L$3))>0)*--((出货退货!$B$2:$B$500=B12)>0)*--((出货退货!$G$2:$G$500=C12)>0)*出货退货!$I$2:$I$500) -> #VALUE! | J12: =SUMPRODUCT((销售明细!$A$2:$A$500=$C$3)*--((($F$3="全部")+(销售明细!$B$2:$B$500=$F$3))>0)*--((($I$3="全部")+(销售明细!$C$2:$C$500=$I$3))>0)*--((($L$3="全部")+(销售明细!$D$2:$D$500=$L$3))>0)*--((销售明细!$B$2:$B$500=B12)>0)*--((销售明细!$H$2:$H$500=C12)>0)*销售明细!$N$2:$N$500) -> 1423 | K12: =IF(E12=0,"缺出货源",IF(H12<0.8,"出货低于POS",IF(H12>1.2,"出货高于POS","匹配"))) -> #VALUE!
B15: 原始数据：POS销售明细与出货明细
B16: 来源 | C16: 数据日期 | D16: KA系统 | E16: 商品编码 | F16: 商品名称 | G16: 门店名称 | H16: 数量 | I16: 金额 | J16: 渠道/来源字段
B18: POS | C18: =销售明细!A2 -> 46166 | D18: =销售明细!B2 -> 大润发 | E18: =销售明细!H2 -> 4354168 | F18: =销售明细!J2 -> 脱骨侠无骨鸡爪(柠檬味) | G18: =销售明细!F2 -> 闸北店 | H18: =销售明细!N2 -> 210 | I18: =销售明细!O2 -> 4675 | J18: =销售明细!M2 -> 线下
B19: POS | C19: =销售明细!A3 -> 46166 | D19: =销售明细!B3 -> 大润发 | E19: =销售明细!H3 -> 4354169 | F19: =销售明细!J3 -> 脱骨侠无骨鸡爪(泡椒味) | G19: =销售明细!F3 -> 杨浦店 | H19: =销售明细!N3 -> 86 | I19: =销售明细!O3 -> 1978 | J19: =销售明细!M3 -> 京东到家
B20: POS | C20: =销售明细!A4 -> 46167 | D20: =销售明细!B4 -> 大润发 | E20: =销售明细!H4 -> 4502138 | F20: =销售明细!J4 -> 脱骨侠虎皮凤爪(白松露味) | G20: =销售明细!F4 -> 广州天河店 | H20: =销售明细!N4 -> 134 | I20: =销售明细!O4 -> 3350 | J20: =销售明细!M4 -> 美团
B21: POS | C21: =销售明细!A5 -> 46167 | D21: =销售明细!B5 -> 沃尔玛 | E21: =销售明细!H5 -> 25354863 | F21: =销售明细!J5 -> 常温脱骨侠无骨鸡爪柠檬 | G21: =销售明细!F5 -> 沃尔玛广州天河店 | H21: =销售明细!N5 -> 190 | I21: =销售明细!O5 -> 3800 | J21: =销售明细!M5 -> POS
B22: POS | C22: =销售明细!A6 -> 46168 | D22: =销售明细!B6 -> 华润 | E22: =销售明细!H6 -> 5150673 | F22: =销售明细!J6 -> 脱骨侠无骨鸡爪(柠檬味)158g | G22: =销售明细!F6 -> 皇姑店 | H22: =销售明细!N6 -> 150 | I22: =销售明细!O6 -> 2895 | J22: =销售明细!M6 -> 线下
B23: POS | C23: =销售明细!A7 -> 46168 | D23: =销售明细!B7 -> 盒马 | E23: =销售明细!H7 -> 431448153 | F23: =销售明细!J7 -> 盒马工坊 蒜香无骨鸡爪 230g | G23: =销售明细!F7 -> 武汉珞狮路店 | H23: =销售明细!N7 -> 980 | I23: =销售明细!O7 -> 12740 | J23: =销售明细!M7 -> POS
B24: POS | C24: =销售明细!A8 -> 46169 | D24: =销售明细!B8 -> 永辉 | E24: =销售明细!H8 -> 1830795 | F24: =销售明细!J8 -> 脱骨侠蒜香酸甜辣无骨鸡爪780g | G24: =销售明细!F8 -> 滨江区龙湖天街店 | H24: =销售明细!N8 -> 52 | I24: =销售明细!O8 -> 2225 | J24: =销售明细!M8 -> POS
B25: POS | C25: =销售明细!A9 -> 46169 | D25: =销售明细!B9 -> 天虹 | E25: =销售明细!H9 -> v000110869 | F25: =销售明细!J9 -> 脱骨侠双椒无骨鸭掌 | G25: =销售明细!F9 -> 深圳创业天虹 | H25: =销售明细!N9 -> 72 | I25: =销售明细!O9 -> 2729 | J25: =销售明细!M9 -> 天虹到家
B26: POS | C26: =销售明细!A10 -> 46170 | D26: =销售明细!B10 -> 比优特 | E26: =销售明细!H10 -> 1156752 | F26: =销售明细!J10 -> 脱骨侠无骨鸡爪蒜香酸甜辣780g | G26: =销售明细!F10 -> 麓林山店 | H26: =销售明细!N10 -> 18 | I26: =销售明细!O10 -> 629 | J26: =销售明细!M10 -> POS
B27: POS | C27: =销售明细!A11 -> 46170 | D27: =销售明细!B11 -> 家得福 | E27: =销售明细!H11 -> 10081319 | F27: =销售明细!J11 -> 脱骨侠酸辣柠檬无骨鸡爪780g | G27: =销售明细!F11 -> 家得福海棠店 | H27: =销售明细!N11 -> 35 | I27: =销售明细!O11 -> 1033 | J27: =销售明细!M11 -> POS
B28: POS | C28: =销售明细!A12 -> 46171 | D28: =销售明细!B12 -> 大润发 | E28: =销售明细!H12 -> 4354172 | F28: =销售明细!J12 -> 脱骨侠盐焗鸡爪 | G28: =销售明细!F12 -> 天津南开店 | H28: =销售明细!N12 -> 98 | I28: =销售明细!O12 -> 1421 | J28: =销售明细!M12 -> 线下
B29: POS | C29: =销售明细!A13 -> 46171 | D29: =销售明细!B13 -> 沃尔玛 | E29: =销售明细!H13 -> 25325573 | F29: =销售明细!J13 -> 冷藏蒜香凤爪 | G29: =销售明细!F13 -> 沃尔玛赤峰玉龙大街店 | H29: =销售明细!N13 -> 79 | I29: =销售明细!O13 -> 2500 | J29: =销售明细!M13 -> POS
... B32: POS | C32: =销售明细!A16 -> 46172 | D32: =销售明细!B16 -> 天虹 | E32: =销售明细!H16 -> v000110869 | F32: =销售明细!J16 -> 脱骨侠双椒无骨鸭掌 | G32: =销售明细!F16 -> 深圳创业天虹 | H32: =销售明细!N16 -> 88 | I32: =销售明细!O16 -> 3335 | J32: =销售明细!M16 -> 京东到家
B35: 出货 | C35: =出货退货!A2 -> 46172 | D35: =出货退货!B2 -> 盒马 | E35: =出货退货!G2 -> 431448153 | F35: =出货退货!H2 -> 盒马工坊 蒜香无骨鸡爪 230g | G35: =出货退货!F2 -> 武汉珞狮路店 | H35: =出货退货!I2 -> 24043 | I35: =出货退货!J2 | J35: =出货退货!M2 -> 当天入库采购件数数量
B36: 出货 | C36: =出货退货!A3 -> 46172 | D36: =出货退货!B3 -> 家得福 | E36: =出货退货!G3 -> 10081319 | F36: =出货退货!H3 -> 脱骨侠酸辣柠檬无骨鸡爪780g | G36: =出货退货!F3 -> 家得福海棠店 | H36: =出货退货!I3 -> 315 | I36: =出货退货!J3 -> 9050 | J36: =出货退货!M3 -> 进货数量/含税进货金额
B37: 出货 | C37: =出货退货!A4 -> 46172 | D37: =出货退货!B4 -> 大润发 | E37: =出货退货!G4 -> 4354168 | F37: =出货退货!H4 -> 脱骨侠无骨鸡爪(柠檬味) | G37: =出货退货!F4 -> 闸北店 | H37: =出货退货!I4 -> 725 | I37: =出货退货!J4 | J37: =出货退货!M4 -> 待收
B38: 出货 | C38: =出货退货!A5 -> 46172 | D38: =出货退货!B5 -> 沃尔玛 | E38: =出货退货!G5 -> 25354863 | F38: =出货退货!H5 -> 常温脱骨侠无骨鸡爪柠檬 | G38: =出货退货!F5 -> 沃尔玛广州天河店 | H38: =出货退货!I5 | I38: =出货退货!J5 | J38: =出货退货!M5 -> 缺进货源
B39: 出货 | C39: =出货退货!A6 -> 0 | D39: =出货退货!B6 -> 0 | E39: =出货退货!G6 -> 0 | F39: =出货退货!H6 -> 0 | G39: =出货退货!F6 -> 0 | H39: =出货退货!I6 -> 0 | I39: =出货退货!J6 -> 0 | J39: =出货退货!M6 -> 0

Sheet 3-门店库存周转天数
A1: 门店端库存周转天数
A2: 关键词：POS数据、门店端库存、各大区、各单品、数据日前7天平均。
B3: 统计日期 | C3: =MAX(销售明细!A2:A500) -> 46172 | E3: KA系统 | F3: 全部 | H3: 大区 | I3: 全部 | K3: 省份 | L3: 全部
B5: 汇总：各大区区分各单品库存周转天数
B6: 大区 | C6: 商品编码 | D6: 商品名称 | E6: 门店库存 | F6: 近7日平均销量 | G6: 库存周转天数 | H6: 有库存门店数 | I6: 动销门店数 | J6: 风险
B7: 华东 | C7: 4354168 | D7: 脱骨侠无骨鸡爪(柠檬味) | E7: =SUMPRODUCT((库存明细!$A$2:$A$500=$C$3)*--((($F$3="全部")+(库存明细!$B$2:$B$500=$F$3))>0)*--((($I$3="全部")+(库存明细!$C$2:$C$500=$I$3))>0)*--((($L$3="全部")+(库存明细!$D$2:$D$500=$L$3))>0)*--((库存明细!$C$2:$C$500=B7)>0)*--((库存明细!$H$2:$H$500=C7)>0)*库存明细!$J$2:$J$500) -> 181584 | F7: =SUMPRODUCT((库存明细!$A$2:$A$500=$C$3)*--((($F$3="全部")+(库存明细!$B$2:$B$500=$F$3))>0)*--((($I$3="全部")+(库存明细!$C$2:$C$500=$I$3))>0)*--((($L$3="全部")+(库存明细!$D$2:$D$500=$L$3))>0)*--((库存明细!$C$2:$C$500=B7)>0)*--((库存明细!$H$2:$H$500=C7)>0)*库存明细!$M$2:$M$500) -> 22802 | G7: =IFERROR(E7/F7,"") -> 7.963512 | H7: =COUNTIFS(库存明细!$A$2:$A$500,$C$3,库存明细!$C$2:$C$500,B7,库存明细!$H$2:$H$500,C7,库存明细!$J$2:$J$500,">0") -> 1 | I7: =COUNTIFS(销售明细!$A$2:$A$500,$C$3,销售明细!$C$2:$C$500,B7,销售明细!$H$2:$H$500,C7,销售明细!$N$2:$N$500,">0") -> 1 | J7: =IF(G7="","无动销",IF(G7>60,"高风险","正常")) -> 正常
B8: 华南 | C8: 4502138 | D8: 脱骨侠虎皮凤爪(白松露味) | E8: =SUMPRODUCT((库存明细!$A$2:$A$500=$C$3)*--((($F$3="全部")+(库存明细!$B$2:$B$500=$F$3))>0)*--((($I$3="全部")+(库存明细!$C$2:$C$500=$I$3))>0)*--((($L$3="全部")+(库存明细!$D$2:$D$500=$L$3))>0)*--((库存明细!$C$2:$C$500=B8)>0)*--((库存明细!$H$2:$H$500=C8)>0)*库存明细!$J$2:$J$500) -> 181584 | F8: =SUMPRODUCT((库存明细!$A$2:$A$500=$C$3)*--((($F$3="全部")+(库存明细!$B$2:$B$500=$F$3))>0)*--((($I$3="全部")+(库存明细!$C$2:$C$500=$I$3))>0)*--((($L$3="全部")+(库存明细!$D$2:$D$500=$L$3))>0)*--((库存明细!$C$2:$C$500=B8)>0)*--((库存明细!$H$2:$H$500=C8)>0)*库存明细!$M$2:$M$500) -> 22802 | G8: =IFERROR(E8/F8,"") -> 7.963512 | H8: =COUNTIFS(库存明细!$A$2:$A$500,$C$3,库存明细!$C$2:$C$500,B8,库存明细!$H$2:$H$500,C8,库存明细!$J$2:$J$500,">0") -> 1 | I8: =COUNTIFS(销售明细!$A$2:$A$500,$C$3,销售明细!$C$2:$C$500,B8,销售明细!$H$2:$H$500,C8,销售明细!$N$2:$N$500,">0") -> 0 | J8: =IF(G8="","无动销",IF(G8>60,"高风险","正常")) -> 正常
B9: 华南 | C9: 25354863 | D9: 常温脱骨侠无骨鸡爪柠檬 | E9: =SUMPRODUCT((库存明细!$A$2:$A$500=$C$3)*--((($F$3="全部")+(库存明细!$B$2:$B$500=$F$3))>0)*--((($I$3="全部")+(库存明细!$C$2:$C$500=$I$3))>0)*--((($L$3="全部")+(库存明细!$D$2:$D$500=$L$3))>0)*--((库存明细!$C$2:$C$500=B9)>0)*--((库存明细!$H$2:$H$500=C9)>0)*库存明细!$J$2:$J$500) -> 181584 | F9: =SUMPRODUCT((库存明细!$A$2:$A$500=$C$3)*--((($F$3="全部")+(库存明细!$B$2:$B$500=$F$3))>0)*--((($I$3="全部")+(库存明细!$C$2:$C$500=$I$3))>0)*--((($L$3="全部")+(库存明细!$D$2:$D$500=$L$3))>0)*--((库存明细!$C$2:$C$500=B9)>0)*--((库存明细!$H$2:$H$500=C9)>0)*库存明细!$M$2:$M$500) -> 22802 | G9: =IFERROR(E9/F9,"") -> 7.963512 | H9: =COUNTIFS(库存明细!$A$2:$A$500,$C$3,库存明细!$C$2:$C$500,B9,库存明细!$H$2:$H$500,C9,库存明细!$J$2:$J$500,">0") -> 1 | I9: =COUNTIFS(销售明细!$A$2:$A$500,$C$3,销售明细!$C$2:$C$500,B9,销售明细!$H$2:$H$500,C9,销售明细!$N$2:$N$500,">0") -> 0 | J9: =IF(G9="","无动销",IF(G9>60,"高风险","正常")) -> 正常
B10: 华北 | C10: 5150673 | D10: 脱骨侠无骨鸡爪(柠檬味)158g | E10: =SUMPRODUCT((库存明细!$A$2:$A$500=$C$3)*--((($F$3="全部")+(库存明细!$B$2:$B$500=$F$3))>0)*--((($I$3="全部")+(库存明细!$C$2:$C$500=$I$3))>0)*--((($L$3="全部")+(库存明细!$D$2:$D$500=$L$3))>0)*--((库存明细!$C$2:$C$500=B10)>0)*--((库存明细!$H$2:$H$500=C10)>0)*库存明细!$J$2:$J$500) -> 181584 | F10: =SUMPRODUCT((库存明细!$A$2:$A$500=$C$3)*--((($F$3="全部")+(库存明细!$B$2:$B$500=$F$3))>0)*--((($I$3="全部")+(库存明细!$C$2:$C$500=$I$3))>0)*--((($L$3="全部")+(库存明细!$D$2:$D$500=$L$3))>0)*--((库存明细!$C$2:$C$500=B10)>0)*--((库存明细!$H$2:$H$500=C10)>0)*库存明细!$M$2:$M$500) -> 22802 | G10: =IFERROR(E10/F10,"") -> 7.963512 | H10: =COUNTIFS(库存明细!$A$2:$A$500,$C$3,库存明细!$C$2:$C$500,B10,库存明细!$H$2:$H$500,C10,库存明细!$J$2:$J$500,">0") -> 1 | I10: =COUNTIFS(销售明细!$A$2:$A$500,$C$3,销售明细!$C$2:$C$500,B10,销售明细!$H$2:$H$500,C10,销售明细!$N$2:$N$500,">0") -> 0 | J10: =IF(G10="","无动销",IF(G10>60,"高风险","正常")) -> 正常
B11: 华中 | C11: 431448153 | D11: 盒马工坊 蒜香无骨鸡爪 230g | E11: =SUMPRODUCT((库存明细!$A$2:$A$500=$C$3)*--((($F$3="全部")+(库存明细!$B$2:$B$500=$F$3))>0)*--((($I$3="全部")+(库存明细!$C$2:$C$500=$I$3))>0)*--((($L$3="全部")+(库存明细!$D$2:$D$500=$L$3))>0)*--((库存明细!$C$2:$C$500=B11)>0)*--((库存明细!$H$2:$H$500=C11)>0)*库存明细!$J$2:$J$500) -> 181584 | F11: =SUMPRODUCT((库存明细!$A$2:$A$500=$C$3)*--((($F$3="全部")+(库存明细!$B$2:$B$500=$F$3))>0)*--((($I$3="全部")+(库存明细!$C$2:$C$500=$I$3))>0)*--((($L$3="全部")+(库存明细!$D$2:$D$500=$L$3))>0)*--((库存明细!$C$2:$C$500=B11)>0)*--((库存明细!$H$2:$H$500=C11)>0)*库存明细!$M$2:$M$500) -> 22802 | G11: =IFERROR(E11/F11,"") -> 7.963512 | H11: =COUNTIFS(库存明细!$A$2:$A$500,$C$3,库存明细!$C$2:$C$500,B11,库存明细!$H$2:$H$500,C11,库存明细!$J$2:$J$500,">0") -> 1 | I11: =COUNTIFS(销售明细!$A$2:$A$500,$C$3,销售明细!$C$2:$C$500,B11,销售明细!$H$2:$H$500,C11,销售明细!$N$2:$N$500,">0") -> 1 | J11: =IF(G11="","无动销",IF(G11>60,"高风险","正常")) -> 正常
B12: 华东 | C12: 10081319 | D12: 脱骨侠酸辣柠檬无骨鸡爪780g | E12: =SUMPRODUCT((库存明细!$A$2:$A$500=$C$3)*--((($F$3="全部")+(库存明细!$B$2:$B$500=$F$3))>0)*--((($I$3="全部")+(库存明细!$C$2:$C$500=$I$3))>0)*--((($L$3="全部")+(库存明细!$D$2:$D$500=$L$3))>0)*--((库存明细!$C$2:$C$500=B12)>0)*--((库存明细!$H$2:$H$500=C12)>0)*库存明细!$J$2:$J$500) -> 181584 | F12: =SUMPRODUCT((库存明细!$A$2:$A$500=$C$3)*--((($F$3="全部")+(库存明细!$B$2:$B$500=$F$3))>0)*--((($I$3="全部")+(库存明细!$C$2:$C$500=$I$3))>0)*--((($L$3="全部")+(库存明细!$D$2:$D$500=$L$3))>0)*--((库存明细!$C$2:$C$500=B12)>0)*--((库存明细!$H$2:$H$500=C12)>0)*库存明细!$M$2:$M$500) -> 22802 | G12: =IFERROR(E12/F12,"") -> 7.963512 | H12: =COUNTIFS(库存明细!$A$2:$A$500,$C$3,库存明细!$C$2:$C$500,B12,库存明细!$H$2:$H$500,C12,库存明细!$J$2:$J$500,">0") -> 1 | I12: =COUNTIFS(销售明细!$A$2:$A$500,$C$3,销售明细!$C$2:$C$500,B12,销售明细!$H$2:$H$500,C12,销售明细!$N$2:$N$500,">0") -> 0 | J12: =IF(G12="","无动销",IF(G12>60,"高风险","正常")) -> 正常
B15: 原始数据：库存明细
B16: 数据日期 | C16: KA系统 | D16: 大区 | E16: 省份 | F16: 门店编码 | G16: 门店名称 | H16: 商品编码 | I16: 商品名称 | J16: 门店库存 | K16: 近7日平均销量 | L16: 周转天数 | M16: 是否超60天
B18: =库存明细!A2 -> 46172 | C18: =库存明细!B2 -> 大润发 | D18: =库存明细!C2 -> 华东 | E18: =库存明细!D2 -> 上海 | F18: =库存明细!E2 -> 1001 | G18: =库存明细!F2 -> 闸北店 | H18: =库存明细!H2 -> 4354168 | I18: =库存明细!I2 -> 脱骨侠无骨鸡爪(柠檬味) | J18: =库存明细!J2 -> 15089 | K18: =库存明细!M2 -> 620 | L18: =库存明细!N2 -> 24.337097 | M18: =库存明细!O2 -> N
B19: =库存明细!A3 -> 46172 | C19: =库存明细!B3 -> 大润发 | D19: =库存明细!C3 -> 华南 | E19: =库存明细!D3 -> 广东 | F19: =库存明细!E3 -> 5001 | G19: =库存明细!F3 -> 广州天河店 | H19: =库存明细!H3 -> 4502138 | I19: =库存明细!I3 -> 脱骨侠虎皮凤爪(白松露味) | J19: =库存明细!J3 -> 13619 | K19: =库存明细!M3 -> 210 | L19: =库存明细!N3 -> 64.852381 | M19: =库存明细!O3 -> Y
B20: =库存明细!A4 -> 46172 | C20: =库存明细!B4 -> 沃尔玛 | D20: =库存明细!C4 -> 华南 | E20: =库存明细!D4 -> 广东 | F20: =库存明细!E4 -> 101 | G20: =库存明细!F4 -> 沃尔玛广州天河店 | H20: =库存明细!H4 -> 25354863 | I20: =库存明细!I4 -> 常温脱骨侠无骨鸡爪柠檬 | J20: =库存明细!J4 -> 30943 | K20: =库存明细!M4 -> 1408 | L20: =库存明细!N4 -> 21.976562 | M20: =库存明细!O4 -> N
B21: =库存明细!A5 -> 46172 | C21: =库存明细!B5 -> 华润 | D21: =库存明细!C5 -> 华北 | E21: =库存明细!D5 -> 北京 | F21: =库存明细!E5 -> 204392 | G21: =库存明细!F5 -> 皇姑店 | H21: =库存明细!H5 -> 5150673 | I21: =库存明细!I5 -> 脱骨侠无骨鸡爪(柠檬味)158g | J21: =库存明细!J5 -> 5233 | K21: =库存明细!M5 -> 245 | L21: =库存明细!N5 -> 21.359184 | M21: =库存明细!O5 -> N
B22: =库存明细!A6 -> 46172 | C22: =库存明细!B6 -> 盒马 | D22: =库存明细!C6 -> 华中 | E22: =库存明细!D6 -> 湖北 | F22: =库存明细!E6 -> HM001 | G22: =库存明细!F6 -> 武汉珞狮路店 | H22: =库存明细!H6 -> 431448153 | I22: =库存明细!I6 -> 盒马工坊 蒜香无骨鸡爪 230g | J22: =库存明细!J6 -> 94942 | K22: =库存明细!M6 -> 20146 | L22: =库存明细!N6 -> 4.7126973 | M22: =库存明细!O6 -> N
B23: =库存明细!A7 -> 46172 | C23: =库存明细!B7 -> 永辉 | D23: =库存明细!C7 -> 华东 | E23: =库存明细!D7 -> 浙江 | F23: =库存明细!E7 -> 9626 | G23: =库存明细!F7 -> 滨江区龙湖天街店 | H23: =库存明细!H7 -> 1830795 | I23: =库存明细!I7 -> 脱骨侠蒜香酸甜辣无骨鸡爪780g | J23: =库存明细!J7 -> 74 | K23: =库存明细!M7 -> 7 | L23: =库存明细!N7 -> 10.571429 | M23: =库存明细!O7 -> N
B24: =库存明细!A8 -> 46172 | C24: =库存明细!B8 -> 天虹 | D24: =库存明细!C8 -> 华南 | E24: =库存明细!D8 -> 广东 | F24: =库存明细!E8 -> 104 | G24: =库存明细!F8 -> 深圳创业天虹 | H24: =库存明细!H8 -> v000110869 | I24: =库存明细!I8 -> 脱骨侠双椒无骨鸭掌 | J24: =库存明细!J8 -> 5444 | K24: =库存明细!M8 -> 129 | L24: =库存明细!N8 -> 42.20155 | M24: =库存明细!O8 -> N
B25: =库存明细!A9 -> 46172 | C25: =库存明细!B9 -> 比优特 | D25: =库存明细!C9 -> 东北 | E25: =库存明细!D9 -> 黑龙江 | F25: =库存明细!E9 -> 2201 | G25: =库存明细!F9 -> 麓林山店 | H25: =库存明细!H9 -> 1156752 | I25: =库存明细!I9 -> 脱骨侠无骨鸡爪蒜香酸甜辣780g | J25: =库存明细!J9 -> 15925 | K25: =库存明细!M9 -> 31 | L25: =库存明细!N9 -> 513.70968 | M25: =库存明细!O9 -> Y
B26: =库存明细!A10 -> 46172 | C26: =库存明细!B10 -> 家得福 | D26: =库存明细!C10 -> 华东 | E26: =库存明细!D10 -> 江苏 | F26: =库存明细!E10 -> 1001 | G26: =库存明细!F10 -> 家得福海棠店 | H26: =库存明细!H10 -> 10081319 | I26: =库存明细!I10 -> 脱骨侠酸辣柠檬无骨鸡爪780g | J26: =库存明细!J10 -> 315 | K26: =库存明细!M10 -> 6 | L26: =库存明细!N10 -> 52.5 | M26: =库存明细!O10 -> N
B27: =库存明细!A11 -> 0 | C27: =库存明细!B11 -> 0 | D27: =库存明细!C11 -> 0 | E27: =库存明细!D11 -> 0 | F27: =库存明细!E11 -> 0 | G27: =库存明细!F11 -> 0 | H27: =库存明细!H11 -> 0 | I27: =库存明细!I11 -> 0 | J27: =库存明细!J11 -> 0 | K27: =库存明细!M11 -> 0 | L27: =库存明细!N11 -> 0 | M27: =库存明细!O11 -> 0
B28: =库存明细!A12 -> 0 | C28: =库存明细!B12 -> 0 | D28: =库存明细!C12 -> 0 | E28: =库存明细!D12 -> 0 | F28: =库存明细!E12 -> 0 | G28: =库存明细!F12 -> 0 | H28: =库存明细!H12 -> 0 | I28: =库存明细!I12 -> 0 | J28: =库存明细!J12 -> 0 | K28: =库存明细!M12 -> 0 | L28: =库存明细!N12 -> 0 | M28: =库存明细!O12 -> 0
B29: =库存明细!A13 -> 0 | C29: =库存明细!B13 -> 0 | D29: =库存明细!C13 -> 0 | E29: =库存明细!D13 -> 0 | F29: =库存明细!E13 -> 0 | G29: =库存明细!F13 -> 0 | H29: =库存明细!H13 -> 0 | I29: =库存明细!I13 -> 0 | J29: =库存明细!J13 -> 0 | K29: =库存明细!M13 -> 0 | L29: =库存明细!N13 -> 0 | M29: =库存明细!O13 -> 0
... B46: =库存明细!A30 -> 0 | C46: =库存明细!B30 -> 0 | D46: =库存明细!C30 -> 0 | E46: =库存明细!D30 -> 0 | F46: =库存明细!E30 -> 0 | G46: =库存明细!F30 -> 0 | H46: =库存明细!H30 -> 0 | I46: =库存明细!I30 -> 0 | J46: =库存明细!J30 -> 0 | K46: =库存明细!M30 -> 0 | L46: =库存明细!N30 -> 0 | M46: =库存明细!O30 -> 0

Sheet 4-超60天门店排名
A1: 超60天门店排名
A2: 关键词：各大区、库存周转天数超60天、门店数排名。
B3: 统计日期 | C3: =MAX(销售明细!A2:A500) -> 46172 | E3: KA系统 | F3: 全部 | H3: 大区 | I3: 全部 | K3: 省份 | L3: 全部
B5: 汇总：各大区库存周转天数超60天门店数排名
B6: 排名 | C6: 大区 | D6: 超60天门店数 | E6: 门店库存 | F6: 近7日平均销量 | G6: 平均周转天数 | H6: 主要风险单品 | I6: 处理建议
B7: 1 | C7: =IFERROR(INDEX($L$20:$L$24,MATCH(LARGE($M$20:$M$24,B7),$M$20:$M$24,0)),"") | D7: =IFERROR(INDEX($M$20:$M$24,MATCH(C7,$L$20:$L$24,0)),0) -> 0 | E7: =IFERROR(INDEX($N$20:$N$24,MATCH(C7,$L$20:$L$24,0)),0) -> 0 | F7: =IFERROR(INDEX($O$20:$O$24,MATCH(C7,$L$20:$L$24,0)),0) -> 0 | G7: =IFERROR(INDEX($P$20:$P$24,MATCH(C7,$L$20:$L$24,0)),"") | H7: =IFERROR(INDEX(库存明细!$I$2:$I$500,MATCH(_xlfn.MAXIFS(库存明细!$N$2:$N$500,库存明细!$C$2:$C$500,C7),库存明细!$N$2:$N$500,0)),"") | I7: =IF(D7>0,"优先清理无动销库存/调拨/促销","正常跟踪") -> 正常跟踪
B8: 2 | C8: =IFERROR(INDEX($L$20:$L$24,MATCH(LARGE($M$20:$M$24,B8),$M$20:$M$24,0)),"") | D8: =IFERROR(INDEX($M$20:$M$24,MATCH(C8,$L$20:$L$24,0)),0) -> 0 | E8: =IFERROR(INDEX($N$20:$N$24,MATCH(C8,$L$20:$L$24,0)),0) -> 0 | F8: =IFERROR(INDEX($O$20:$O$24,MATCH(C8,$L$20:$L$24,0)),0) -> 0 | G8: =IFERROR(INDEX($P$20:$P$24,MATCH(C8,$L$20:$L$24,0)),"") | H8: =IFERROR(INDEX(库存明细!$I$2:$I$500,MATCH(_xlfn.MAXIFS(库存明细!$N$2:$N$500,库存明细!$C$2:$C$500,C8),库存明细!$N$2:$N$500,0)),"") | I8: =IF(D8>0,"优先清理无动销库存/调拨/促销","正常跟踪") -> 正常跟踪
B9: 3 | C9: =IFERROR(INDEX($L$20:$L$24,MATCH(LARGE($M$20:$M$24,B9),$M$20:$M$24,0)),"") | D9: =IFERROR(INDEX($M$20:$M$24,MATCH(C9,$L$20:$L$24,0)),0) -> 0 | E9: =IFERROR(INDEX($N$20:$N$24,MATCH(C9,$L$20:$L$24,0)),0) -> 0 | F9: =IFERROR(INDEX($O$20:$O$24,MATCH(C9,$L$20:$L$24,0)),0) -> 0 | G9: =IFERROR(INDEX($P$20:$P$24,MATCH(C9,$L$20:$L$24,0)),"") | H9: =IFERROR(INDEX(库存明细!$I$2:$I$500,MATCH(_xlfn.MAXIFS(库存明细!$N$2:$N$500,库存明细!$C$2:$C$500,C9),库存明细!$N$2:$N$500,0)),"") | I9: =IF(D9>0,"优先清理无动销库存/调拨/促销","正常跟踪") -> 正常跟踪
B10: 4 | C10: =IFERROR(INDEX($L$20:$L$24,MATCH(LARGE($M$20:$M$24,B10),$M$20:$M$24,0)),"") | D10: =IFERROR(INDEX($M$20:$M$24,MATCH(C10,$L$20:$L$24,0)),0) -> 0 | E10: =IFERROR(INDEX($N$20:$N$24,MATCH(C10,$L$20:$L$24,0)),0) -> 0 | F10: =IFERROR(INDEX($O$20:$O$24,MATCH(C10,$L$20:$L$24,0)),0) -> 0 | G10: =IFERROR(INDEX($P$20:$P$24,MATCH(C10,$L$20:$L$24,0)),"") | H10: =IFERROR(INDEX(库存明细!$I$2:$I$500,MATCH(_xlfn.MAXIFS(库存明细!$N$2:$N$500,库存明细!$C$2:$C$500,C10),库存明细!$N$2:$N$500,0)),"") | I10: =IF(D10>0,"优先清理无动销库存/调拨/促销","正常跟踪") -> 正常跟踪
B11: 5 | C11: =IFERROR(INDEX($L$20:$L$24,MATCH(LARGE($M$20:$M$24,B11),$M$20:$M$24,0)),"") | D11: =IFERROR(INDEX($M$20:$M$24,MATCH(C11,$L$20:$L$24,0)),0) -> 0 | E11: =IFERROR(INDEX($N$20:$N$24,MATCH(C11,$L$20:$L$24,0)),0) -> 0 | F11: =IFERROR(INDEX($O$20:$O$24,MATCH(C11,$L$20:$L$24,0)),0) -> 0 | G11: =IFERROR(INDEX($P$20:$P$24,MATCH(C11,$L$20:$L$24,0)),"") | H11: =IFERROR(INDEX(库存明细!$I$2:$I$500,MATCH(_xlfn.MAXIFS(库存明细!$N$2:$N$500,库存明细!$C$2:$C$500,C11),库存明细!$N$2:$N$500,0)),"") | I11: =IF(D11>0,"优先清理无动销库存/调拨/促销","正常跟踪") -> 正常跟踪
B15: 原始数据：超60天门店明细
B16: 数据日期 | C16: KA系统 | D16: 大区 | E16: 省份 | F16: 门店编码 | G16: 门店名称 | H16: 商品编码 | I16: 商品名称 | J16: 门店库存 | K16: 近7日平均销量 | L16: 周转天数 | M16: 是否超60天
B18: =库存明细!A2 -> 46172 | C18: =库存明细!B2 -> 大润发 | D18: =库存明细!C2 -> 华东 | E18: =库存明细!D2 -> 上海 | F18: =库存明细!E2 -> 1001 | G18: =库存明细!F2 -> 闸北店 | H18: =库存明细!H2 -> 4354168 | I18: =库存明细!I2 -> 脱骨侠无骨鸡爪(柠檬味) | J18: =库存明细!J2 -> 15089 | K18: =库存明细!M2 -> 620 | L18: =库存明细!N2 -> 24.337097 | M18: =库存明细!O2 -> N
B19: =库存明细!A3 -> 46172 | C19: =库存明细!B3 -> 大润发 | D19: =库存明细!C3 -> 华南 | E19: =库存明细!D3 -> 广东 | F19: =库存明细!E3 -> 5001 | G19: =库存明细!F3 -> 广州天河店 | H19: =库存明细!H3 -> 4502138 | I19: =库存明细!I3 -> 脱骨侠虎皮凤爪(白松露味) | J19: =库存明细!J3 -> 13619 | K19: =库存明细!M3 -> 210 | L19: =库存明细!N3 -> 64.852381 | M19: =库存明细!O3 -> Y
B20: =库存明细!A4 -> 46172 | C20: =库存明细!B4 -> 沃尔玛 | D20: =库存明细!C4 -> 华南 | E20: =库存明细!D4 -> 广东 | F20: =库存明细!E4 -> 101 | G20: =库存明细!F4 -> 沃尔玛广州天河店 | H20: =库存明细!H4 -> 25354863 | I20: =库存明细!I4 -> 常温脱骨侠无骨鸡爪柠檬 | J20: =库存明细!J4 -> 30943 | K20: =库存明细!M4 -> 1408 | L20: =库存明细!N4 -> 21.976562 | M20: =库存明细!O4 -> N | N20: =SUMPRODUCT((库存明细!$A$2:$A$500=$C$3)*--((($F$3="全部")+(库存明细!$B$2:$B$500=$F$3))>0)*--((($I$3="全部")+(库存明细!$C$2:$C$500=$I$3))>0)*--((($L$3="全部")+(库存明细!$D$2:$D$500=$L$3))>0)*--((库存明细!$C$2:$C$500=L20)>0)*库存明细!$J$2:$J$500) -> 181584 | O20: =SUMPRODUCT((库存明细!$A$2:$A$500=$C$3)*--((($F$3="全部")+(库存明细!$B$2:$B$500=$F$3))>0)*--((($I$3="全部")+(库存明细!$C$2:$C$500=$I$3))>0)*--((($L$3="全部")+(库存明细!$D$2:$D$500=$L$3))>0)*--((库存明细!$C$2:$C$500=L20)>0)*库存明细!$M$2:$M$500) -> 22802 | P20: =IFERROR(N20/O20,"") -> 7.963512
B21: =库存明细!A5 -> 46172 | C21: =库存明细!B5 -> 华润 | D21: =库存明细!C5 -> 华北 | E21: =库存明细!D5 -> 北京 | F21: =库存明细!E5 -> 204392 | G21: =库存明细!F5 -> 皇姑店 | H21: =库存明细!H5 -> 5150673 | I21: =库存明细!I5 -> 脱骨侠无骨鸡爪(柠檬味)158g | J21: =库存明细!J5 -> 5233 | K21: =库存明细!M5 -> 245 | L21: =库存明细!N5 -> 21.359184 | M21: =库存明细!O5 -> N | N21: =SUMPRODUCT((库存明细!$A$2:$A$500=$C$3)*--((($F$3="全部")+(库存明细!$B$2:$B$500=$F$3))>0)*--((($I$3="全部")+(库存明细!$C$2:$C$500=$I$3))>0)*--((($L$3="全部")+(库存明细!$D$2:$D$500=$L$3))>0)*--((库存明细!$C$2:$C$500=L21)>0)*库存明细!$J$2:$J$500) -> 181584 | O21: =SUMPRODUCT((库存明细!$A$2:$A$500=$C$3)*--((($F$3="全部")+(库存明细!$B$2:$B$500=$F$3))>0)*--((($I$3="全部")+(库存明细!$C$2:$C$500=$I$3))>0)*--((($L$3="全部")+(库存明细!$D$2:$D$500=$L$3))>0)*--((库存明细!$C$2:$C$500=L21)>0)*库存明细!$M$2:$M$500) -> 22802 | P21: =IFERROR(N21/O21,"") -> 7.963512
B22: =库存明细!A6 -> 46172 | C22: =库存明细!B6 -> 盒马 | D22: =库存明细!C6 -> 华中 | E22: =库存明细!D6 -> 湖北 | F22: =库存明细!E6 -> HM001 | G22: =库存明细!F6 -> 武汉珞狮路店 | H22: =库存明细!H6 -> 431448153 | I22: =库存明细!I6 -> 盒马工坊 蒜香无骨鸡爪 230g | J22: =库存明细!J6 -> 94942 | K22: =库存明细!M6 -> 20146 | L22: =库存明细!N6 -> 4.7126973 | M22: =库存明细!O6 -> N | N22: =SUMPRODUCT((库存明细!$A$2:$A$500=$C$3)*--((($F$3="全部")+(库存明细!$B$2:$B$500=$F$3))>0)*--((($I$3="全部")+(库存明细!$C$2:$C$500=$I$3))>0)*--((($L$3="全部")+(库存明细!$D$2:$D$500=$L$3))>0)*--((库存明细!$C$2:$C$500=L22)>0)*库存明细!$J$2:$J$500) -> 181584 | O22: =SUMPRODUCT((库存明细!$A$2:$A$500=$C$3)*--((($F$3="全部")+(库存明细!$B$2:$B$500=$F$3))>0)*--((($I$3="全部")+(库存明细!$C$2:$C$500=$I$3))>0)*--((($L$3="全部")+(库存明细!$D$2:$D$500=$L$3))>0)*--((库存明细!$C$2:$C$500=L22)>0)*库存明细!$M$2:$M$500) -> 22802 | P22: =IFERROR(N22/O22,"") -> 7.963512
B23: =库存明细!A7 -> 46172 | C23: =库存明细!B7 -> 永辉 | D23: =库存明细!C7 -> 华东 | E23: =库存明细!D7 -> 浙江 | F23: =库存明细!E7 -> 9626 | G23: =库存明细!F7 -> 滨江区龙湖天街店 | H23: =库存明细!H7 -> 1830795 | I23: =库存明细!I7 -> 脱骨侠蒜香酸甜辣无骨鸡爪780g | J23: =库存明细!J7 -> 74 | K23: =库存明细!M7 -> 7 | L23: =库存明细!N7 -> 10.571429 | M23: =库存明细!O7 -> N | N23: =SUMPRODUCT((库存明细!$A$2:$A$500=$C$3)*--((($F$3="全部")+(库存明细!$B$2:$B$500=$F$3))>0)*--((($I$3="全部")+(库存明细!$C$2:$C$500=$I$3))>0)*--((($L$3="全部")+(库存明细!$D$2:$D$500=$L$3))>0)*--((库存明细!$C$2:$C$500=L23)>0)*库存明细!$J$2:$J$500) -> 181584 | O23: =SUMPRODUCT((库存明细!$A$2:$A$500=$C$3)*--((($F$3="全部")+(库存明细!$B$2:$B$500=$F$3))>0)*--((($I$3="全部")+(库存明细!$C$2:$C$500=$I$3))>0)*--((($L$3="全部")+(库存明细!$D$2:$D$500=$L$3))>0)*--((库存明细!$C$2:$C$500=L23)>0)*库存明细!$M$2:$M$500) -> 22802 | P23: =IFERROR(N23/O23,"") -> 7.963512
B24: =库存明细!A8 -> 46172 | C24: =库存明细!B8 -> 天虹 | D24: =库存明细!C8 -> 华南 | E24: =库存明细!D8 -> 广东 | F24: =库存明细!E8 -> 104 | G24: =库存明细!F8 -> 深圳创业天虹 | H24: =库存明细!H8 -> v000110869 | I24: =库存明细!I8 -> 脱骨侠双椒无骨鸭掌 | J24: =库存明细!J8 -> 5444 | K24: =库存明细!M8 -> 129 | L24: =库存明细!N8 -> 42.20155 | M24: =库存明细!O8 -> N | N24: =SUMPRODUCT((库存明细!$A$2:$A$500=$C$3)*--((($F$3="全部")+(库存明细!$B$2:$B$500=$F$3))>0)*--((($I$3="全部")+(库存明细!$C$2:$C$500=$I$3))>0)*--((($L$3="全部")+(库存明细!$D$2:$D$500=$L$3))>0)*--((库存明细!$C$2:$C$500=L24)>0)*库存明细!$J$2:$J$500) -> 181584 | O24: =SUMPRODUCT((库存明细!$A$2:$A$500=$C$3)*--((($F$3="全部")+(库存明细!$B$2:$B$500=$F$3))>0)*--((($I$3="全部")+(库存明细!$C$2:$C$500=$I$3))>0)*--((($L$3="全部")+(库存明细!$D$2:$D$500=$L$3))>0)*--((库存明细!$C$2:$C$500=L24)>0)*库存明细!$M$2:$M$500) -> 22802 | P24: =IFERROR(N24/O24,"") -> 7.963512
B25: =库存明细!A9 -> 46172 | C25: =库存明细!B9 -> 比优特 | D25: =库存明细!C9 -> 东北 | E25: =库存明细!D9 -> 黑龙江 | F25: =库存明细!E9 -> 2201 | G25: =库存明细!F9 -> 麓林山店 | H25: =库存明细!H9 -> 1156752 | I25: =库存明细!I9 -> 脱骨侠无骨鸡爪蒜香酸甜辣780g | J25: =库存明细!J9 -> 15925 | K25: =库存明细!M9 -> 31 | L25: =库存明细!N9 -> 513.70968 | M25: =库存明细!O9 -> Y
B26: =库存明细!A10 -> 46172 | C26: =库存明细!B10 -> 家得福 | D26: =库存明细!C10 -> 华东 | E26: =库存明细!D10 -> 江苏 | F26: =库存明细!E10 -> 1001 | G26: =库存明细!F10 -> 家得福海棠店 | H26: =库存明细!H10 -> 10081319 | I26: =库存明细!I10 -> 脱骨侠酸辣柠檬无骨鸡爪780g | J26: =库存明细!J10 -> 315 | K26: =库存明细!M10 -> 6 | L26: =库存明细!N10 -> 52.5 | M26: =库存明细!O10 -> N
B27: =库存明细!A11 -> 0 | C27: =库存明细!B11 -> 0 | D27: =库存明细!C11 -> 0 | E27: =库存明细!D11 -> 0 | F27: =库存明细!E11 -> 0 | G27: =库存明细!F11 -> 0 | H27: =库存明细!H11 -> 0 | I27: =库存明细!I11 -> 0 | J27: =库存明细!J11 -> 0 | K27: =库存明细!M11 -> 0 | L27: =库存明细!N11 -> 0 | M27: =库存明细!O11 -> 0
B28: =库存明细!A12 -> 0 | C28: =库存明细!B12 -> 0 | D28: =库存明细!C12 -> 0 | E28: =库存明细!D12 -> 0 | F28: =库存明细!E12 -> 0 | G28: =库存明细!F12 -> 0 | H28: =库存明细!H12 -> 0 | I28: =库存明细!I12 -> 0 | J28: =库存明细!J12 -> 0 | K28: =库存明细!M12 -> 0 | L28: =库存明细!N12 -> 0 | M28: =库存明细!O12 -> 0
B29: =库存明细!A13 -> 0 | C29: =库存明细!B13 -> 0 | D29: =库存明细!C13 -> 0 | E29: =库存明细!D13 -> 0 | F29: =库存明细!E13 -> 0 | G29: =库存明细!F13 -> 0 | H29: =库存明细!H13 -> 0 | I29: =库存明细!I13 -> 0 | J29: =库存明细!J13 -> 0 | K29: =库存明细!M13 -> 0 | L29: =库存明细!N13 -> 0 | M29: =库存明细!O13 -> 0
B30: =库存明细!A14 -> 0 | C30: =库存明细!B14 -> 0 | D30: =库存明细!C14 -> 0 | E30: =库存明细!D14 -> 0 | F30: =库存明细!E14 -> 0 | G30: =库存明细!F14 -> 0 | H30: =库存明细!H14 -> 0 | I30: =库存明细!I14 -> 0 | J30: =库存明细!J14 -> 0 | K30: =库存明细!M14 -> 0 | L30: =库存明细!N14 -> 0 | M30: =库存明细!O14 -> 0
B31: =库存明细!A15 -> 0 | C31: =库存明细!B15 -> 0 | D31: =库存明细!C15 -> 0 | E31: =库存明细!D15 -> 0 | F31: =库存明细!E15 -> 0 | G31: =库存明细!F15 -> 0 | H31: =库存明细!H15 -> 0 | I31: =库存明细!I15 -> 0 | J31: =库存明细!J15 -> 0 | K31: =库存明细!M15 -> 0 | L31: =库存明细!N15 -> 0 | M31: =库存明细!O15 -> 0
B32: =库存明细!A16 -> 0 | C32: =库存明细!B16 -> 0 | D32: =库存明细!C16 -> 0 | E32: =库存明细!D16 -> 0 | F32: =库存明细!E16 -> 0 | G32: =库存明细!F16 -> 0 | H32: =库存明细!H16 -> 0 | I32: =库存明细!I16 -> 0 | J32: =库存明细!J16 -> 0 | K32: =库存明细!M16 -> 0 | L32: =库存明细!N16 -> 0 | M32: =库存明细!O16 -> 0
