Workbook

Sheet 1-KA大盘出货数据
A1: KA大盘出货数据
A2: 关键词：系统每天出货数量、出货金额；by单品、by渠道、by数量、by金额。
B3: 统计日期 | C3: =MAX('销售明细'!A2:A500) | E3: KA系统 | F3: 全部 | H3: 大区 | I3: 全部 | K3: 省份 | L3: 全部
B5: 汇总：系统每天出货数量、出货金额（by系统/by数量/by金额）
B6: KA系统 | C6: 出货数量 | D6: 出货金额 | E6: POS销售数量 | F6: POS销售额 | G6: 出货/POS额 | H6: 退货数量 | I6: 退货金额 | J6: 数据状态
B7: 大润发 | C7: =SUMPRODUCT(('出货退货'!$A$2:$A$500=$C$3)*--(('出货退货'!$B$2:$B$500=B7)>0)*--((($I$3="全部")+('出货退货'!$C$2:$C$500=$I$3))>0)*--((($L$3="全部")+('出货退货'!$D$2:$D$500=$L$3))>0)*'出货退货'!$I$2:$I$500) | D7: =SUMPRODUCT(('出货退货'!$A$2:$A$500=$C$3)*--(('出货退货'!$B$2:$B$500=B7)>0)*--((($I$3="全部")+('出货退货'!$C$2:$C$500=$I$3))>0)*--((($L$3="全部")+('出货退货'!$D$2:$D$500=$L$3))>0)*'出货退货'!$J$2:$J$500) | E7: =SUMPRODUCT(('销售明细'!$A$2:$A$500=$C$3)*--(('销售明细'!$B$2:$B$500=B7)>0)*--((($I$3="全部")+('销售明细'!$C$2:$C$500=$I$3))>0)*--((($L$3="全部")+('销售明细'!$D$2:$D$500=$L$3))>0)*'销售明细'!$N$2:$N$500) | F7: =SUMPRODUCT(('销售明细'!$A$2:$A$500=$C$3)*--(('销售明细'!$B$2:$B$500=B7)>0)*--((($I$3="全部")+('销售明细'!$C$2:$C$500=$I$3))>0)*--((($L$3="全部")+('销售明细'!$D$2:$D$500=$L$3))>0)*'销售明细'!$O$2:$O$500) | G7: =IFERROR(D7/F7,0) | H7: =SUMPRODUCT(('出货退货'!$A$2:$A$500=$C$3)*--(('出货退货'!$B$2:$B$500=B7)>0)*--((($I$3="全部")+('出货退货'!$C$2:$C$500=$I$3))>0)*--((($L$3="全部")+('出货退货'!$D$2:$D$500=$L$3))>0)*'出货退货'!$K$2:$K$500) | I7: =SUMPRODUCT(('出货退货'!$A$2:$A$500=$C$3)*--(('出货退货'!$B$2:$B$500=B7)>0)*--((($I$3="全部")+('出货退货'!$C$2:$C$500=$I$3))>0)*--((($L$3="全部")+('出货退货'!$D$2:$D$500=$L$3))>0)*'出货退货'!$L$2:$L$500) | J7: =IF(D7=0,"缺出货金额",IF(C7=0,"缺出货数量","可用"))
B8: 盒马 | C8: =SUMPRODUCT(('出货退货'!$A$2:$A$500=$C$3)*--(('出货退货'!$B$2:$B$500=B8)>0)*--((($I$3="全部")+('出货退货'!$C$2:$C$500=$I$3))>0)*--((($L$3="全部")+('出货退货'!$D$2:$D$500=$L$3))>0)*'出货退货'!$I$2:$I$500) | D8: =SUMPRODUCT(('出货退货'!$A$2:$A$500=$C$3)*--(('出货退货'!$B$2:$B$500=B8)>0)*--((($I$3="全部")+('出货退货'!$C$2:$C$500=$I$3))>0)*--((($L$3="全部")+('出货退货'!$D$2:$D$500=$L$3))>0)*'出货退货'!$J$2:$J$500) | E8: =SUMPRODUCT(('销售明细'!$A$2:$A$500=$C$3)*--(('销售明细'!$B$2:$B$500=B8)>0)*--((($I$3="全部")+('销售明细'!$C$2:$C$500=$I$3))>0)*--((($L$3="全部")+('销售明细'!$D$2:$D$500=$L$3))>0)*'销售明细'!$N$2:$N$500) | F8: =SUMPRODUCT(('销售明细'!$A$2:$A$500=$C$3)*--(('销售明细'!$B$2:$B$500=B8)>0)*--((($I$3="全部")+('销售明细'!$C$2:$C$500=$I$3))>0)*--((($L$3="全部")+('销售明细'!$D$2:$D$500=$L$3))>0)*'销售明细'!$O$2:$O$500) | G8: =IFERROR(D8/F8,0) | H8: =SUMPRODUCT(('出货退货'!$A$2:$A$500=$C$3)*--(('出货退货'!$B$2:$B$500=B8)>0)*--((($I$3="全部")+('出货退货'!$C$2:$C$500=$I$3))>0)*--((($L$3="全部")+('出货退货'!$D$2:$D$500=$L$3))>0)*'出货退货'!$K$2:$K$500) | I8: =SUMPRODUCT(('出货退货'!$A$2:$A$500=$C$3)*--(('出货退货'!$B$2:$B$500=B8)>0)*--((($I$3="全部")+('出货退货'!$C$2:$C$500=$I$3))>0)*--((($L$3="全部")+('出货退货'!$D$2:$D$500=$L$3))>0)*'出货退货'!$L$2:$L$500) | J8: =IF(D8=0,"缺出货金额",IF(C8=0,"缺出货数量","可用"))
B9: 华润 | C9: =SUMPRODUCT(('出货退货'!$A$2:$A$500=$C$3)*--(('出货退货'!$B$2:$B$500=B9)>0)*--((($I$3="全部")+('出货退货'!$C$2:$C$500=$I$3))>0)*--((($L$3="全部")+('出货退货'!$D$2:$D$500=$L$3))>0)*'出货退货'!$I$2:$I$500) | D9: =SUMPRODUCT(('出货退货'!$A$2:$A$500=$C$3)*--(('出货退货'!$B$2:$B$500=B9)>0)*--((($I$3="全部")+('出货退货'!$C$2:$C$500=$I$3))>0)*--((($L$3="全部")+('出货退货'!$D$2:$D$500=$L$3))>0)*'出货退货'!$J$2:$J$500) | E9: =SUMPRODUCT(('销售明细'!$A$2:$A$500=$C$3)*--(('销售明细'!$B$2:$B$500=B9)>0)*--((($I$3="全部")+('销售明细'!$C$2:$C$500=$I$3))>0)*--((($L$3="全部")+('销售明细'!$D$2:$D$500=$L$3))>0)*'销售明细'!$N$2:$N$500) | F9: =SUMPRODUCT(('销售明细'!$A$2:$A$500=$C$3)*--(('销售明细'!$B$2:$B$500=B9)>0)*--((($I$3="全部")+('销售明细'!$C$2:$C$500=$I$3))>0)*--((($L$3="全部")+('销售明细'!$D$2:$D$500=$L$3))>0)*'销售明细'!$O$2:$O$500) | G9: =IFERROR(D9/F9,0) | H9: =SUMPRODUCT(('出货退货'!$A$2:$A$500=$C$3)*--(('出货退货'!$B$2:$B$500=B9)>0)*--((($I$3="全部")+('出货退货'!$C$2:$C$500=$I$3))>0)*--((($L$3="全部")+('出货退货'!$D$2:$D$500=$L$3))>0)*'出货退货'!$K$2:$K$500) | I9: =SUMPRODUCT(('出货退货'!$A$2:$A$500=$C$3)*--(('出货退货'!$B$2:$B$500=B9)>0)*--((($I$3="全部")+('出货退货'!$C$2:$C$500=$I$3))>0)*--((($L$3="全部")+('出货退货'!$D$2:$D$500=$L$3))>0)*'出货退货'!$L$2:$L$500) | J9: =IF(D9=0,"缺出货金额",IF(C9=0,"缺出货数量","可用"))
B10: 沃尔玛 | C10: =SUMPRODUCT(('出货退货'!$A$2:$A$500=$C$3)*--(('出货退货'!$B$2:$B$500=B10)>0)*--((($I$3="全部")+('出货退货'!$C$2:$C$500=$I$3))>0)*--((($L$3="全部")+('出货退货'!$D$2:$D$500=$L$3))>0)*'出货退货'!$I$2:$I$500) | D10: =SUMPRODUCT(('出货退货'!$A$2:$A$500=$C$3)*--(('出货退货'!$B$2:$B$500=B10)>0)*--((($I$3="全部")+('出货退货'!$C$2:$C$500=$I$3))>0)*--((($L$3="全部")+('出货退货'!$D$2:$D$500=$L$3))>0)*'出货退货'!$J$2:$J$500) | E10: =SUMPRODUCT(('销售明细'!$A$2:$A$500=$C$3)*--(('销售明细'!$B$2:$B$500=B10)>0)*--((($I$3="全部")+('销售明细'!$C$2:$C$500=$I$3))>0)*--((($L$3="全部")+('销售明细'!$D$2:$D$500=$L$3))>0)*'销售明细'!$N$2:$N$500) | F10: =SUMPRODUCT(('销售明细'!$A$2:$A$500=$C$3)*--(('销售明细'!$B$2:$B$500=B10)>0)*--((($I$3="全部")+('销售明细'!$C$2:$C$500=$I$3))>0)*--((($L$3="全部")+('销售明细'!$D$2:$D$500=$L$3))>0)*'销售明细'!$O$2:$O$500) | G10: =IFERROR(D10/F10,0) | H10: =SUMPRODUCT(('出货退货'!$A$2:$A$500=$C$3)*--(('出货退货'!$B$2:$B$500=B10)>0)*--((($I$3="全部")+('出货退货'!$C$2:$C$500=$I$3))>0)*--((($L$3="全部")+('出货退货'!$D$2:$D$500=$L$3))>0)*'出货退货'!$K$2:$K$500) | I10: =SUMPRODUCT(('出货退货'!$A$2:$A$500=$C$3)*--(('出货退货'!$B$2:$B$500=B10)>0)*--((($I$3="全部")+('出货退货'!$C$2:$C$500=$I$3))>0)*--((($L$3="全部")+('出货退货'!$D$2:$D$500=$L$3))>0)*'出货退货'!$L$2:$L$500) | J10: =IF(D10=0,"缺出货金额",IF(C10=0,"缺出货数量","可用"))
B11: 永辉 | C11: =SUMPRODUCT(('出货退货'!$A$2:$A$500=$C$3)*--(('出货退货'!$B$2:$B$500=B11)>0)*--((($I$3="全部")+('出货退货'!$C$2:$C$500=$I$3))>0)*--((($L$3="全部")+('出货退货'!$D$2:$D$500=$L$3))>0)*'出货退货'!$I$2:$I$500) | D11: =SUMPRODUCT(('出货退货'!$A$2:$A$500=$C$3)*--(('出货退货'!$B$2:$B$500=B11)>0)*--((($I$3="全部")+('出货退货'!$C$2:$C$500=$I$3))>0)*--((($L$3="全部")+('出货退货'!$D$2:$D$500=$L$3))>0)*'出货退货'!$J$2:$J$500) | E11: =SUMPRODUCT(('销售明细'!$A$2:$A$500=$C$3)*--(('销售明细'!$B$2:$B$500=B11)>0)*--((($I$3="全部")+('销售明细'!$C$2:$C$500=$I$3))>0)*--((($L$3="全部")+('销售明细'!$D$2:$D$500=$L$3))>0)*'销售明细'!$N$2:$N$500) | F11: =SUMPRODUCT(('销售明细'!$A$2:$A$500=$C$3)*--(('销售明细'!$B$2:$B$500=B11)>0)*--((($I$3="全部")+('销售明细'!$C$2:$C$500=$I$3))>0)*--((($L$3="全部")+('销售明细'!$D$2:$D$500=$L$3))>0)*'销售明细'!$O$2:$O$500) | G11: =IFERROR(D11/F11,0) | H11: =SUMPRODUCT(('出货退货'!$A$2:$A$500=$C$3)*--(('出货退货'!$B$2:$B$500=B11)>0)*--((($I$3="全部")+('出货退货'!$C$2:$C$500=$I$3))>0)*--((($L$3="全部")+('出货退货'!$D$2:$D$500=$L$3))>0)*'出货退货'!$K$2:$K$500) | I11: =SUMPRODUCT(('出货退货'!$A$2:$A$500=$C$3)*--(('出货退货'!$B$2:$B$500=B11)>0)*--((($I$3="全部")+('出货退货'!$C$2:$C$500=$I$3))>0)*--((($L$3="全部")+('出货退货'!$D$2:$D$500=$L$3))>0)*'出货退货'!$L$2:$L$500) | J11: =IF(D11=0,"缺出货金额",IF(C11=0,"缺出货数量","可用"))
B12: 天虹 | C12: =SUMPRODUCT(('出货退货'!$A$2:$A$500=$C$3)*--(('出货退货'!$B$2:$B$500=B12)>0)*--((($I$3="全部")+('出货退货'!$C$2:$C$500=$I$3))>0)*--((($L$3="全部")+('出货退货'!$D$2:$D$500=$L$3))>0)*'出货退货'!$I$2:$I$500) | D12: =SUMPRODUCT(('出货退货'!$A$2:$A$500=$C$3)*--(('出货退货'!$B$2:$B$500=B12)>0)*--((($I$3="全部")+('出货退货'!$C$2:$C$500=$I$3))>0)*--((($L$3="全部")+('出货退货'!$D$2:$D$500=$L$3))>0)*'出货退货'!$J$2:$J$500) | E12: =SUMPRODUCT(('销售明细'!$A$2:$A$500=$C$3)*--(('销售明细'!$B$2:$B$500=B12)>0)*--((($I$3="全部")+('销售明细'!$C$2:$C$500=$I$3))>0)*--((($L$3="全部")+('销售明细'!$D$2:$D$500=$L$3))>0)*'销售明细'!$N$2:$N$500) | F12: =SUMPRODUCT(('销售明细'!$A$2:$A$500=$C$3)*--(('销售明细'!$B$2:$B$500=B12)>0)*--((($I$3="全部")+('销售明细'!$C$2:$C$500=$I$3))>0)*--((($L$3="全部")+('销售明细'!$D$2:$D$500=$L$3))>0)*'销售明细'!$O$2:$O$500) | G12: =IFERROR(D12/F12,0) | H12: =SUMPRODUCT(('出货退货'!$A$2:$A$500=$C$3)*--(('出货退货'!$B$2:$B$500=B12)>0)*--((($I$3="全部")+('出货退货'!$C$2:$C$500=$I$3))>0)*--((($L$3="全部")+('出货退货'!$D$2:$D$500=$L$3))>0)*'出货退货'!$K$2:$K$500) | I12: =SUMPRODUCT(('出货退货'!$A$2:$A$500=$C$3)*--(('出货退货'!$B$2:$B$500=B12)>0)*--((($I$3="全部")+('出货退货'!$C$2:$C$500=$I$3))>0)*--((($L$3="全部")+('出货退货'!$D$2:$D$500=$L$3))>0)*'出货退货'!$L$2:$L$500) | J12: =IF(D12=0,"缺出货金额",IF(C12=0,"缺出货数量","可用"))
B13: 比优特 | C13: =SUMPRODUCT(('出货退货'!$A$2:$A$500=$C$3)*--(('出货退货'!$B$2:$B$500=B13)>0)*--((($I$3="全部")+('出货退货'!$C$2:$C$500=$I$3))>0)*--((($L$3="全部")+('出货退货'!$D$2:$D$500=$L$3))>0)*'出货退货'!$I$2:$I$500) | D13: =SUMPRODUCT(('出货退货'!$A$2:$A$500=$C$3)*--(('出货退货'!$B$2:$B$500=B13)>0)*--((($I$3="全部")+('出货退货'!$C$2:$C$500=$I$3))>0)*--((($L$3="全部")+('出货退货'!$D$2:$D$500=$L$3))>0)*'出货退货'!$J$2:$J$500) | E13: =SUMPRODUCT(('销售明细'!$A$2:$A$500=$C$3)*--(('销售明细'!$B$2:$B$500=B13)>0)*--((($I$3="全部")+('销售明细'!$C$2:$C$500=$I$3))>0)*--((($L$3="全部")+('销售明细'!$D$2:$D$500=$L$3))>0)*'销售明细'!$N$2:$N$500) | F13: =SUMPRODUCT(('销售明细'!$A$2:$A$500=$C$3)*--(('销售明细'!$B$2:$B$500=B13)>0)*--((($I$3="全部")+('销售明细'!$C$2:$C$500=$I$3))>0)*--((($L$3="全部")+('销售明细'!$D$2:$D$500=$L$3))>0)*'销售明细'!$O$2:$O$500) | G13: =IFERROR(D13/F13,0) | H13: =SUMPRODUCT(('出货退货'!$A$2:$A$500=$C$3)*--(('出货退货'!$B$2:$B$500=B13)>0)*--((($I$3="全部")+('出货退货'!$C$2:$C$500=$I$3))>0)*--((($L$3="全部")+('出货退货'!$D$2:$D$500=$L$3))>0)*'出货退货'!$K$2:$K$500) | I13: =SUMPRODUCT(('出货退货'!$A$2:$A$500=$C$3)*--(('出货退货'!$B$2:$B$500=B13)>0)*--((($I$3="全部")+('出货退货'!$C$2:$C$500=$I$3))>0)*--((($L$3="全部")+('出货退货'!$D$2:$D$500=$L$3))>0)*'出货退货'!$L$2:$L$500) | J13: =IF(D13=0,"缺出货金额",IF(C13=0,"缺出货数量","可用"))
B14: 家得福 | C14: =SUMPRODUCT(('出货退货'!$A$2:$A$500=$C$3)*--(('出货退货'!$B$2:$B$500=B14)>0)*--((($I$3="全部")+('出货退货'!$C$2:$C$500=$I$3))>0)*--((($L$3="全部")+('出货退货'!$D$2:$D$500=$L$3))>0)*'出货退货'!$I$2:$I$500) | D14: =SUMPRODUCT(('出货退货'!$A$2:$A$500=$C$3)*--(('出货退货'!$B$2:$B$500=B14)>0)*--((($I$3="全部")+('出货退货'!$C$2:$C$500=$I$3))>0)*--((($L$3="全部")+('出货退货'!$D$2:$D$500=$L$3))>0)*'出货退货'!$J$2:$J$500) | E14: =SUMPRODUCT(('销售明细'!$A$2:$A$500=$C$3)*--(('销售明细'!$B$2:$B$500=B14)>0)*--((($I$3="全部")+('销售明细'!$C$2:$C$500=$I$3))>0)*--((($L$3="全部")+('销售明细'!$D$2:$D$500=$L$3))>0)*'销售明细'!$N$2:$N$500) | F14: =SUMPRODUCT(('销售明细'!$A$2:$A$500=$C$3)*--(('销售明细'!$B$2:$B$500=B14)>0)*--((($I$3="全部")+('销售明细'!$C$2:$C$500=$I$3))>0)*--((($L$3="全部")+('销售明细'!$D$2:$D$500=$L$3))>0)*'销售明细'!$O$2:$O$500) | G14: =IFERROR(D14/F14,0) | H14: =SUMPRODUCT(('出货退货'!$A$2:$A$500=$C$3)*--(('出货退货'!$B$2:$B$500=B14)>0)*--((($I$3="全部")+('出货退货'!$C$2:$C$500=$I$3))>0)*--((($L$3="全部")+('出货退货'!$D$2:$D$500=$L$3))>0)*'出货退货'!$K$2:$K$500) | I14: =SUMPRODUCT(('出货退货'!$A$2:$A$500=$C$3)*--(('出货退货'!$B$2:$B$500=B14)>0)*--((($I$3="全部")+('出货退货'!$C$2:$C$500=$I$3))>0)*--((($L$3="全部")+('出货退货'!$D$2:$D$500=$L$3))>0)*'出货退货'!$L$2:$L$500) | J14: =IF(D14=0,"缺出货金额",IF(C14=0,"缺出货数量","可用"))
B17: 汇总：by单品
B18: 商品编码 | C18: 商品名称 | D18: KA系统 | E18: 出货数量 | F18: 出货金额 | G18: POS销售数量 | H18: POS销售额 | I18: 出货/POS额 | J18: 备注
B19: 4354168 | C19: 脱骨侠无骨鸡爪(柠檬味) | D19: 大润发 | E19: =SUMPRODUCT(('出货退货'!$A$2:$A$500=$C$3)*--((($F$3="全部")+('出货退货'!$B$2:$B$500=$F$3))>0)*--((($I$3="全部")+('出货退货'!$C$2:$C$500=$I$3))>0)*--((($L$3="全部")+('出货退货'!$D$2:$D$500=$L$3))>0)*--(('出货退货'!$G$2:$G$500=B19)>0)*'出货退货'!$I$2:$I$500) | F19: =SUMPRODUCT(('出货退货'!$A$2:$A$500=$C$3)*--((($F$3="全部")+('出货退货'!$B$2:$B$500=$F$3))>0)*--((($I$3="全部")+('出货退货'!$C$2:$C$500=$I$3))>0)*--((($L$3="全部")+('出货退货'!$D$2:$D$500=$L$3))>0)*--(('出货退货'!$G$2:$G$500=B19)>0)*'出货退货'!$J$2:$J$500) | G19: =SUMPRODUCT(('销售明细'!$A$2:$A$500=$C$3)*--((($F$3="全部")+('销售明细'!$B$2:$B$500=$F$3))>0)*--((($I$3="全部")+('销售明细'!$C$2:$C$500=$I$3))>0)*--((($L$3="全部")+('销售明细'!$D$2:$D$500=$L$3))>0)*--(('销售明细'!$H$2:$H$500=B19)>0)*'销售明细'!$N$2:$N$500) | H19: =SUMPRODUCT(('销售明细'!$A$2:$A$500=$C$3)*--((($F$3="全部")+('销售明细'!$B$2:$B$500=$F$3))>0)*--((($I$3="全部")+('销售明细'!$C$2:$C$500=$I$3))>0)*--((($L$3="全部")+('销售明细'!$D$2:$D$500=$L$3))>0)*--(('销售明细'!$H$2:$H$500=B19)>0)*'销售明细'!$O$2:$O$500) | I19: =IFERROR(F19/H19,0) | J19: =IF(F19=0,"缺出货源","")
B20: 4502138 | C20: 脱骨侠虎皮凤爪(白松露味) | D20: 大润发 | E20: =SUMPRODUCT(('出货退货'!$A$2:$A$500=$C$3)*--((($F$3="全部")+('出货退货'!$B$2:$B$500=$F$3))>0)*--((($I$3="全部")+('出货退货'!$C$2:$C$500=$I$3))>0)*--((($L$3="全部")+('出货退货'!$D$2:$D$500=$L$3))>0)*--(('出货退货'!$G$2:$G$500=B20)>0)*'出货退货'!$I$2:$I$500) | F20: =SUMPRODUCT(('出货退货'!$A$2:$A$500=$C$3)*--((($F$3="全部")+('出货退货'!$B$2:$B$500=$F$3))>0)*--((($I$3="全部")+('出货退货'!$C$2:$C$500=$I$3))>0)*--((($L$3="全部")+('出货退货'!$D$2:$D$500=$L$3))>0)*--(('出货退货'!$G$2:$G$500=B20)>0)*'出货退货'!$J$2:$J$500) | G20: =SUMPRODUCT(('销售明细'!$A$2:$A$500=$C$3)*--((($F$3="全部")+('销售明细'!$B$2:$B$500=$F$3))>0)*--((($I$3="全部")+('销售明细'!$C$2:$C$500=$I$3))>0)*--((($L$3="全部")+('销售明细'!$D$2:$D$500=$L$3))>0)*--(('销售明细'!$H$2:$H$500=B20)>0)*'销售明细'!$N$2:$N$500) | H20: =SUMPRODUCT(('销售明细'!$A$2:$A$500=$C$3)*--((($F$3="全部")+('销售明细'!$B$2:$B$500=$F$3))>0)*--((($I$3="全部")+('销售明细'!$C$2:$C$500=$I$3))>0)*--((($L$3="全部")+('销售明细'!$D$2:$D$500=$L$3))>0)*--(('销售明细'!$H$2:$H$500=B20)>0)*'销售明细'!$O$2:$O$500) | I20: =IFERROR(F20/H20,0) | J20: =IF(F20=0,"缺出货源","")
B21: 25354863 | C21: 常温脱骨侠无骨鸡爪柠檬 | D21: 沃尔玛 | E21: =SUMPRODUCT(('出货退货'!$A$2:$A$500=$C$3)*--((($F$3="全部")+('出货退货'!$B$2:$B$500=$F$3))>0)*--((($I$3="全部")+('出货退货'!$C$2:$C$500=$I$3))>0)*--((($L$3="全部")+('出货退货'!$D$2:$D$500=$L$3))>0)*--(('出货退货'!$G$2:$G$500=B21)>0)*'出货退货'!$I$2:$I$500) | F21: =SUMPRODUCT(('出货退货'!$A$2:$A$500=$C$3)*--((($F$3="全部")+('出货退货'!$B$2:$B$500=$F$3))>0)*--((($I$3="全部")+('出货退货'!$C$2:$C$500=$I$3))>0)*--((($L$3="全部")+('出货退货'!$D$2:$D$500=$L$3))>0)*--(('出货退货'!$G$2:$G$500=B21)>0)*'出货退货'!$J$2:$J$500) | G21: =SUMPRODUCT(('销售明细'!$A$2:$A$500=$C$3)*--((($F$3="全部")+('销售明细'!$B$2:$B$500=$F$3))>0)*--((($I$3="全部")+('销售明细'!$C$2:$C$500=$I$3))>0)*--((($L$3="全部")+('销售明细'!$D$2:$D$500=$L$3))>0)*--(('销售明细'!$H$2:$H$500=B21)>0)*'销售明细'!$N$2:$N$500) | H21: =SUMPRODUCT(('销售明细'!$A$2:$A$500=$C$3)*--((($F$3="全部")+('销售明细'!$B$2:$B$500=$F$3))>0)*--((($I$3="全部")+('销售明细'!$C$2:$C$500=$I$3))>0)*--((($L$3="全部")+('销售明细'!$D$2:$D$500=$L$3))>0)*--(('销售明细'!$H$2:$H$500=B21)>0)*'销售明细'!$O$2:$O$500) | I21: =IFERROR(F21/H21,0) | J21: =IF(F21=0,"缺出货源","")
B22: 431448153 | C22: 盒马工坊 蒜香无骨鸡爪 230g | D22: 盒马 | E22: =SUMPRODUCT(('出货退货'!$A$2:$A$500=$C$3)*--((($F$3="全部")+('出货退货'!$B$2:$B$500=$F$3))>0)*--((($I$3="全部")+('出货退货'!$C$2:$C$500=$I$3))>0)*--((($L$3="全部")+('出货退货'!$D$2:$D$500=$L$3))>0)*--(('出货退货'!$G$2:$G$500=B22)>0)*'出货退货'!$I$2:$I$500) | F22: =SUMPRODUCT(('出货退货'!$A$2:$A$500=$C$3)*--((($F$3="全部")+('出货退货'!$B$2:$B$500=$F$3))>0)*--((($I$3="全部")+('出货退货'!$C$2:$C$500=$I$3))>0)*--((($L$3="全部")+('出货退货'!$D$2:$D$500=$L$3))>0)*--(('出货退货'!$G$2:$G$500=B22)>0)*'出货退货'!$J$2:$J$500) | G22: =SUMPRODUCT(('销售明细'!$A$2:$A$500=$C$3)*--((($F$3="全部")+('销售明细'!$B$2:$B$500=$F$3))>0)*--((($I$3="全部")+('销售明细'!$C$2:$C$500=$I$3))>0)*--((($L$3="全部")+('销售明细'!$D$2:$D$500=$L$3))>0)*--(('销售明细'!$H$2:$H$500=B22)>0)*'销售明细'!$N$2:$N$500) | H22: =SUMPRODUCT(('销售明细'!$A$2:$A$500=$C$3)*--((($F$3="全部")+('销售明细'!$B$2:$B$500=$F$3))>0)*--((($I$3="全部")+('销售明细'!$C$2:$C$500=$I$3))>0)*--((($L$3="全部")+('销售明细'!$D$2:$D$500=$L$3))>0)*--(('销售明细'!$H$2:$H$500=B22)>0)*'销售明细'!$O$2:$O$500) | I22: =IFERROR(F22/H22,0) | J22: =IF(F22=0,"缺出货源","")
B23: v000110869 | C23: 脱骨侠双椒无骨鸭掌 | D23: 天虹 | E23: =SUMPRODUCT(('出货退货'!$A$2:$A$500=$C$3)*--((($F$3="全部")+('出货退货'!$B$2:$B$500=$F$3))>0)*--((($I$3="全部")+('出货退货'!$C$2:$C$500=$I$3))>0)*--((($L$3="全部")+('出货退货'!$D$2:$D$500=$L$3))>0)*--(('出货退货'!$G$2:$G$500=B23)>0)*'出货退货'!$I$2:$I$500) | F23: =SUMPRODUCT(('出货退货'!$A$2:$A$500=$C$3)*--((($F$3="全部")+('出货退货'!$B$2:$B$500=$F$3))>0)*--((($I$3="全部")+('出货退货'!$C$2:$C$500=$I$3))>0)*--((($L$3="全部")+('出货退货'!$D$2:$D$500=$L$3))>0)*--(('出货退货'!$G$2:$G$500=B23)>0)*'出货退货'!$J$2:$J$500) | G23: =SUMPRODUCT(('销售明细'!$A$2:$A$500=$C$3)*--((($F$3="全部")+('销售明细'!$B$2:$B$500=$F$3))>0)*--((($I$3="全部")+('销售明细'!$C$2:$C$500=$I$3))>0)*--((($L$3="全部")+('销售明细'!$D$2:$D$500=$L$3))>0)*--(('销售明细'!$H$2:$H$500=B23)>0)*'销售明细'!$N$2:$N$500) | H23: =SUMPRODUCT(('销售明细'!$A$2:$A$500=$C$3)*--((($F$3="全部")+('销售明细'!$B$2:$B$500=$F$3))>0)*--((($I$3="全部")+('销售明细'!$C$2:$C$500=$I$3))>0)*--((($L$3="全部")+('销售明细'!$D$2:$D$500=$L$3))>0)*--(('销售明细'!$H$2:$H$500=B23)>0)*'销售明细'!$O$2:$O$500) | I23: =IFERROR(F23/H23,0) | J23: =IF(F23=0,"缺出货源","")
B24: 10081319 | C24: 脱骨侠酸辣柠檬无骨鸡爪780g | D24: 家得福 | E24: =SUMPRODUCT(('出货退货'!$A$2:$A$500=$C$3)*--((($F$3="全部")+('出货退货'!$B$2:$B$500=$F$3))>0)*--((($I$3="全部")+('出货退货'!$C$2:$C$500=$I$3))>0)*--((($L$3="全部")+('出货退货'!$D$2:$D$500=$L$3))>0)*--(('出货退货'!$G$2:$G$500=B24)>0)*'出货退货'!$I$2:$I$500) | F24: =SUMPRODUCT(('出货退货'!$A$2:$A$500=$C$3)*--((($F$3="全部")+('出货退货'!$B$2:$B$500=$F$3))>0)*--((($I$3="全部")+('出货退货'!$C$2:$C$500=$I$3))>0)*--((($L$3="全部")+('出货退货'!$D$2:$D$500=$L$3))>0)*--(('出货退货'!$G$2:$G$500=B24)>0)*'出货退货'!$J$2:$J$500) | G24: =SUMPRODUCT(('销售明细'!$A$2:$A$500=$C$3)*--((($F$3="全部")+('销售明细'!$B$2:$B$500=$F$3))>0)*--((($I$3="全部")+('销售明细'!$C$2:$C$500=$I$3))>0)*--((($L$3="全部")+('销售明细'!$D$2:$D$500=$L$3))>0)*--(('销售明细'!$H$2:$H$500=B24)>0)*'销售明细'!$N$2:$N$500) | H24: =SUMPRODUCT(('销售明细'!$A$2:$A$500=$C$3)*--((($F$3="全部")+('销售明细'!$B$2:$B$500=$F$3))>0)*--((($I$3="全部")+('销售明细'!$C$2:$C$500=$I$3))>0)*--((($L$3="全部")+('销售明细'!$D$2:$D$500=$L$3))>0)*--(('销售明细'!$H$2:$H$500=B24)>0)*'销售明细'!$O$2:$O$500) | I24: =IFERROR(F24/H24,0) | J24: =IF(F24=0,"缺出货源","")
B27: 汇总：by渠道
B28: 渠道 | C28: POS销售数量 | D28: POS销售额 | E28: 出货数量 | F28: 出货金额 | G28: 出货/POS额 | H28: 说明
B29: POS | C29: =SUMPRODUCT(('销售明细'!$A$2:$A$500=$C$3)*--((($F$3="全部")+('销售明细'!$B$2:$B$500=$F$3))>0)*--((($I$3="全部")+('销售明细'!$C$2:$C$500=$I$3))>0)*--((($L$3="全部")+('销售明细'!$D$2:$D$500=$L$3))>0)*--(('销售明细'!$M$2:$M$500=B29)>0)*'销售明细'!$N$2:$N$500) | D29: =SUMPRODUCT(('销售明细'!$A$2:$A$500=$C$3)*--((($F$3="全部")+('销售明细'!$B$2:$B$500=$F$3))>0)*--((($I$3="全部")+('销售明细'!$C$2:$C$500=$I$3))>0)*--((($L$3="全部")+('销售明细'!$D$2:$D$500=$L$3))>0)*--(('销售明细'!$M$2:$M$500=B29)>0)*'销售明细'!$O$2:$O$500) | E29: =SUMPRODUCT(('出货退货'!$A$2:$A$500=$C$3)*--((($F$3="全部")+('出货退货'!$B$2:$B$500=$F$3))>0)*--((($I$3="全部")+('出货退货'!$C$2:$C$500=$I$3))>0)*--((($L$3="全部")+('出货退货'!$D$2:$D$500=$L$3))>0)*'出货退货'!$I$2:$I$500) | F29: =SUMPRODUCT(('出货退货'!$A$2:$A$500=$C$3)*--((($F$3="全部")+('出货退货'!$B$2:$B$500=$F$3))>0)*--((($I$3="全部")+('出货退货'!$C$2:$C$500=$I$3))>0)*--((($L$3="全部")+('出货退货'!$D$2:$D$500=$L$3))>0)*'出货退货'!$J$2:$J$500) | G29: =IFERROR(F29/D29,0) | H29: 渠道出货需出货源提供渠道字段；当前出货按筛选总额展示
B30: 线下 | C30: =SUMPRODUCT(('销售明细'!$A$2:$A$500=$C$3)*--((($F$3="全部")+('销售明细'!$B$2:$B$500=$F$3))>0)*--((($I$3="全部")+('销售明细'!$C$2:$C$500=$I$3))>0)*--((($L$3="全部")+('销售明细'!$D$2:$D$500=$L$3))>0)*--(('销售明细'!$M$2:$M$500=B30)>0)*'销售明细'!$N$2:$N$500) | D30: =SUMPRODUCT(('销售明细'!$A$2:$A$500=$C$3)*--((($F$3="全部")+('销售明细'!$B$2:$B$500=$F$3))>0)*--((($I$3="全部")+('销售明细'!$C$2:$C$500=$I$3))>0)*--((($L$3="全部")+('销售明细'!$D$2:$D$500=$L$3))>0)*--(('销售明细'!$M$2:$M$500=B30)>0)*'销售明细'!$O$2:$O$500) | E30: =SUMPRODUCT(('出货退货'!$A$2:$A$500=$C$3)*--((($F$3="全部")+('出货退货'!$B$2:$B$500=$F$3))>0)*--((($I$3="全部")+('出货退货'!$C$2:$C$500=$I$3))>0)*--((($L$3="全部")+('出货退货'!$D$2:$D$500=$L$3))>0)*'出货退货'!$I$2:$I$500) | F30: =SUMPRODUCT(('出货退货'!$A$2:$A$500=$C$3)*--((($F$3="全部")+('出货退货'!$B$2:$B$500=$F$3))>0)*--((($I$3="全部")+('出货退货'!$C$2:$C$500=$I$3))>0)*--((($L$3="全部")+('出货退货'!$D$2:$D$500=$L$3))>0)*'出货退货'!$J$2:$J$500) | G30: =IFERROR(F30/D30,0) | H30: 渠道出货需出货源提供渠道字段；当前出货按筛选总额展示
B31: 京东到家 | C31: =SUMPRODUCT(('销售明细'!$A$2:$A$500=$C$3)*--((($F$3="全部")+('销售明细'!$B$2:$B$500=$F$3))>0)*--((($I$3="全部")+('销售明细'!$C$2:$C$500=$I$3))>0)*--((($L$3="全部")+('销售明细'!$D$2:$D$500=$L$3))>0)*--(('销售明细'!$M$2:$M$500=B31)>0)*'销售明细'!$N$2:$N$500) | D31: =SUMPRODUCT(('销售明细'!$A$2:$A$500=$C$3)*--((($F$3="全部")+('销售明细'!$B$2:$B$500=$F$3))>0)*--((($I$3="全部")+('销售明细'!$C$2:$C$500=$I$3))>0)*--((($L$3="全部")+('销售明细'!$D$2:$D$500=$L$3))>0)*--(('销售明细'!$M$2:$M$500=B31)>0)*'销售明细'!$O$2:$O$500) | E31: =SUMPRODUCT(('出货退货'!$A$2:$A$500=$C$3)*--((($F$3="全部")+('出货退货'!$B$2:$B$500=$F$3))>0)*--((($I$3="全部")+('出货退货'!$C$2:$C$500=$I$3))>0)*--((($L$3="全部")+('出货退货'!$D$2:$D$500=$L$3))>0)*'出货退货'!$I$2:$I$500) | F31: =SUMPRODUCT(('出货退货'!$A$2:$A$500=$C$3)*--((($F$3="全部")+('出货退货'!$B$2:$B$500=$F$3))>0)*--((($I$3="全部")+('出货退货'!$C$2:$C$500=$I$3))>0)*--((($L$3="全部")+('出货退货'!$D$2:$D$500=$L$3))>0)*'出货退货'!$J$2:$J$500) | G31: =IFERROR(F31/D31,0) | H31: 渠道出货需出货源提供渠道字段；当前出货按筛选总额展示
B32: 美团 | C32: =SUMPRODUCT(('销售明细'!$A$2:$A$500=$C$3)*--((($F$3="全部")+('销售明细'!$B$2:$B$500=$F$3))>0)*--((($I$3="全部")+('销售明细'!$C$2:$C$500=$I$3))>0)*--((($L$3="全部")+('销售明细'!$D$2:$D$500=$L$3))>0)*--(('销售明细'!$M$2:$M$500=B32)>0)*'销售明细'!$N$2:$N$500) | D32: =SUMPRODUCT(('销售明细'!$A$2:$A$500=$C$3)*--((($F$3="全部")+('销售明细'!$B$2:$B$500=$F$3))>0)*--((($I$3="全部")+('销售明细'!$C$2:$C$500=$I$3))>0)*--((($L$3="全部")+('销售明细'!$D$2:$D$500=$L$3))>0)*--(('销售明细'!$M$2:$M$500=B32)>0)*'销售明细'!$O$2:$O$500) | E32: =SUMPRODUCT(('出货退货'!$A$2:$A$500=$C$3)*--((($F$3="全部")+('出货退货'!$B$2:$B$500=$F$3))>0)*--((($I$3="全部")+('出货退货'!$C$2:$C$500=$I$3))>0)*--((($L$3="全部")+('出货退货'!$D$2:$D$500=$L$3))>0)*'出货退货'!$I$2:$I$500) | F32: =SUMPRODUCT(('出货退货'!$A$2:$A$500=$C$3)*--((($F$3="全部")+('出货退货'!$B$2:$B$500=$F$3))>0)*--((($I$3="全部")+('出货退货'!$C$2:$C$500=$I$3))>0)*--((($L$3="全部")+('出货退货'!$D$2:$D$500=$L$3))>0)*'出货退货'!$J$2:$J$500) | G32: =IFERROR(F32/D32,0) | H32: 渠道出货需出货源提供渠道字段；当前出货按筛选总额展示
B33: 天虹到家 | C33: =SUMPRODUCT(('销售明细'!$A$2:$A$500=$C$3)*--((($F$3="全部")+('销售明细'!$B$2:$B$500=$F$3))>0)*--((($I$3="全部")+('销售明细'!$C$2:$C$500=$I$3))>0)*--((($L$3="全部")+('销售明细'!$D$2:$D$500=$L$3))>0)*--(('销售明细'!$M$2:$M$500=B33)>0)*'销售明细'!$N$2:$N$500) | D33: =SUMPRODUCT(('销售明细'!$A$2:$A$500=$C$3)*--((($F$3="全部")+('销售明细'!$B$2:$B$500=$F$3))>0)*--((($I$3="全部")+('销售明细'!$C$2:$C$500=$I$3))>0)*--((($L$3="全部")+('销售明细'!$D$2:$D$500=$L$3))>0)*--(('销售明细'!$M$2:$M$500=B33)>0)*'销售明细'!$O$2:$O$500) | E33: =SUMPRODUCT(('出货退货'!$A$2:$A$500=$C$3)*--((($F$3="全部")+('出货退货'!$B$2:$B$500=$F$3))>0)*--((($I$3="全部")+('出货退货'!$C$2:$C$500=$I$3))>0)*--((($L$3="全部")+('出货退货'!$D$2:$D$500=$L$3))>0)*'出货退货'!$I$2:$I$500) | F33: =SUMPRODUCT(('出货退货'!$A$2:$A$500=$C$3)*--((($F$3="全部")+('出货退货'!$B$2:$B$500=$F$3))>0)*--((($I$3="全部")+('出货退货'!$C$2:$C$500=$I$3))>0)*--((($L$3="全部")+('出货退货'!$D$2:$D$500=$L$3))>0)*'出货退货'!$J$2:$J$500) | G33: =IFERROR(F33/D33,0) | H33: 渠道出货需出货源提供渠道字段；当前出货按筛选总额展示
B36: 原始数据：出货退货明细
B37: 数据日期 | C37: KA系统 | D37: 大区 | E37: 省份 | F37: 门店编码 | G37: 门店名称 | H37: 商品编码 | I37: 商品名称 | J37: 出货数量 | K37: 出货金额 | L37: 退货数量 | M37: 退货金额 | N37: 来源
B38: ='出货退货'!A2 | C38: ='出货退货'!B2 | D38: ='出货退货'!C2 | E38: ='出货退货'!D2 | F38: ='出货退货'!E2 | G38: ='出货退货'!F2 | H38: ='出货退货'!G2 | I38: ='出货退货'!H2 | ... N38: ='出货退货'!M2
B39: ='出货退货'!A3 | C39: ='出货退货'!B3 | D39: ='出货退货'!C3 | E39: ='出货退货'!D3 | F39: ='出货退货'!E3 | G39: ='出货退货'!F3 | H39: ='出货退货'!G3 | I39: ='出货退货'!H3 | ... N39: ='出货退货'!M3
B40: ='出货退货'!A4 | C40: ='出货退货'!B4 | D40: ='出货退货'!C4 | E40: ='出货退货'!D4 | F40: ='出货退货'!E4 | G40: ='出货退货'!F4 | H40: ='出货退货'!G4 | I40: ='出货退货'!H4 | ... N40: ='出货退货'!M4
B41: ='出货退货'!A5 | C41: ='出货退货'!B5 | D41: ='出货退货'!C5 | E41: ='出货退货'!D5 | F41: ='出货退货'!E5 | G41: ='出货退货'!F5 | H41: ='出货退货'!G5 | I41: ='出货退货'!H5 | ... N41: ='出货退货'!M5
B42: ='出货退货'!A6 | C42: ='出货退货'!B6 | D42: ='出货退货'!C6 | E42: ='出货退货'!D6 | F42: ='出货退货'!E6 | G42: ='出货退货'!F6 | H42: ='出货退货'!G6 | I42: ='出货退货'!H6 | ... N42: ='出货退货'!M6
B43: ='出货退货'!A7 | C43: ='出货退货'!B7 | D43: ='出货退货'!C7 | E43: ='出货退货'!D7 | F43: ='出货退货'!E7 | G43: ='出货退货'!F7 | H43: ='出货退货'!G7 | I43: ='出货退货'!H7 | ... N43: ='出货退货'!M7
B44: ='出货退货'!A8 | C44: ='出货退货'!B8 | D44: ='出货退货'!C8 | E44: ='出货退货'!D8 | F44: ='出货退货'!E8 | G44: ='出货退货'!F8 | H44: ='出货退货'!G8 | I44: ='出货退货'!H8 | ... N44: ='出货退货'!M8
B45: ='出货退货'!A9 | C45: ='出货退货'!B9 | D45: ='出货退货'!C9 | E45: ='出货退货'!D9 | F45: ='出货退货'!E9 | G45: ='出货退货'!F9 | H45: ='出货退货'!G9 | I45: ='出货退货'!H9 | ... N45: ='出货退货'!M9
B46: ='出货退货'!A10 | C46: ='出货退货'!B10 | D46: ='出货退货'!C10 | E46: ='出货退货'!D10 | F46: ='出货退货'!E10 | G46: ='出货退货'!F10 | H46: ='出货退货'!G10 | I46: ='出货退货'!H10 | ... N46: ='出货退货'!M10
B47: ='出货退货'!A11 | C47: ='出货退货'!B11 | D47: ='出货退货'!C11 | E47: ='出货退货'!D11 | F47: ='出货退货'!E11 | G47: ='出货退货'!F11 | H47: ='出货退货'!G11 | I47: ='出货退货'!H11 | ... N47: ='出货退货'!M11
...

Sheet 2-单品出货POS对比
A1: 系统单品出货额和POS额对比
A2: 关键词：系统、单品、出货额、POS额、差异、比例。
B3: 统计日期 | C3: =MAX('销售明细'!A2:A500) | E3: KA系统 | F3: 全部 | H3: 大区 | I3: 全部 | K3: 省份 | L3: 全部
B5: 汇总：系统单品出货额和POS额对比
B6: KA系统 | C6: 商品编码 | D6: 商品名称 | E6: 出货额 | F6: POS额 | G6: 差异 | H6: 出货/POS额 | I6: 出货数量 | J6: POS销量 | K6: 状态
B7: 大润发 | C7: 4354168 | D7: 脱骨侠无骨鸡爪(柠檬味) | E7: =SUMPRODUCT(('出货退货'!$A$2:$A$500=$C$3)*--((($F$3="全部")+('出货退货'!$B$2:$B$500=$F$3))>0)*--((($I$3="全部")+('出货退货'!$C$2:$C$500=$I$3))>0)*--((($L$3="全部")+('出货退货'!$D$2:$D$500=$L$3))>0)*--(('出货退货'!$B$2:$B$500=B7)>0)*--(('出货退货'!$G$2:$G$500=C7)>0)*'出货退货'!$J$2:$J$500) | F7: =SUMPRODUCT(('销售明细'!$A$2:$A$500=$C$3)*--((($F$3="全部")+('销售明细'!$B$2:$B$500=$F$3))>0)*--((($I$3="全部")+('销售明细'!$C$2:$C$500=$I$3))>0)*--((($L$3="全部")+('销售明细'!$D$2:$D$500=$L$3))>0)*--(('销售明细'!$B$2:$B$500=B7)>0)*--(('销售明细'!$H$2:$H$500=C7)>0)*'销售明细'!$O$2:$O$500) | G7: =E7-F7 | H7: =IFERROR(E7/F7,0) | I7: =SUMPRODUCT(('出货退货'!$A$2:$A$500=$C$3)*--((($F$3="全部")+('出货退货'!$B$2:$B$500=$F$3))>0)*--((($I$3="全部")+('出货退货'!$C$2:$C$500=$I$3))>0)*--((($L$3="全部")+('出货退货'!$D$2:$D$500=$L$3))>0)*--(('出货退货'!$B$2:$B$500=B7)>0)*--(('出货退货'!$G$2:$G$500=C7)>0)*'出货退货'!$I$2:$I$500) | J7: =SUMPRODUCT(('销售明细'!$A$2:$A$500=$C$3)*--((($F$3="全部")+('销售明细'!$B$2:$B$500=$F$3))>0)*--((($I$3="全部")+('销售明细'!$C$2:$C$500=$I$3))>0)*--((($L$3="全部")+('销售明细'!$D$2:$D$500=$L$3))>0)*--(('销售明细'!$B$2:$B$500=B7)>0)*--(('销售明细'!$H$2:$H$500=C7)>0)*'销售明细'!$N$2:$N$500) | K7: =IF(E7=0,"缺出货源",IF(H7<0.8,"出货低于POS",IF(H7>1.2,"出货高于POS","匹配")))
B8: 大润发 | C8: 4502138 | D8: 脱骨侠虎皮凤爪(白松露味) | E8: =SUMPRODUCT(('出货退货'!$A$2:$A$500=$C$3)*--((($F$3="全部")+('出货退货'!$B$2:$B$500=$F$3))>0)*--((($I$3="全部")+('出货退货'!$C$2:$C$500=$I$3))>0)*--((($L$3="全部")+('出货退货'!$D$2:$D$500=$L$3))>0)*--(('出货退货'!$B$2:$B$500=B8)>0)*--(('出货退货'!$G$2:$G$500=C8)>0)*'出货退货'!$J$2:$J$500) | F8: =SUMPRODUCT(('销售明细'!$A$2:$A$500=$C$3)*--((($F$3="全部")+('销售明细'!$B$2:$B$500=$F$3))>0)*--((($I$3="全部")+('销售明细'!$C$2:$C$500=$I$3))>0)*--((($L$3="全部")+('销售明细'!$D$2:$D$500=$L$3))>0)*--(('销售明细'!$B$2:$B$500=B8)>0)*--(('销售明细'!$H$2:$H$500=C8)>0)*'销售明细'!$O$2:$O$500) | G8: =E8-F8 | H8: =IFERROR(E8/F8,0) | I8: =SUMPRODUCT(('出货退货'!$A$2:$A$500=$C$3)*--((($F$3="全部")+('出货退货'!$B$2:$B$500=$F$3))>0)*--((($I$3="全部")+('出货退货'!$C$2:$C$500=$I$3))>0)*--((($L$3="全部")+('出货退货'!$D$2:$D$500=$L$3))>0)*--(('出货退货'!$B$2:$B$500=B8)>0)*--(('出货退货'!$G$2:$G$500=C8)>0)*'出货退货'!$I$2:$I$500) | J8: =SUMPRODUCT(('销售明细'!$A$2:$A$500=$C$3)*--((($F$3="全部")+('销售明细'!$B$2:$B$500=$F$3))>0)*--((($I$3="全部")+('销售明细'!$C$2:$C$500=$I$3))>0)*--((($L$3="全部")+('销售明细'!$D$2:$D$500=$L$3))>0)*--(('销售明细'!$B$2:$B$500=B8)>0)*--(('销售明细'!$H$2:$H$500=C8)>0)*'销售明细'!$N$2:$N$500) | K8: =IF(E8=0,"缺出货源",IF(H8<0.8,"出货低于POS",IF(H8>1.2,"出货高于POS","匹配")))
B9: 沃尔玛 | C9: 25354863 | D9: 常温脱骨侠无骨鸡爪柠檬 | E9: =SUMPRODUCT(('出货退货'!$A$2:$A$500=$C$3)*--((($F$3="全部")+('出货退货'!$B$2:$B$500=$F$3))>0)*--((($I$3="全部")+('出货退货'!$C$2:$C$500=$I$3))>0)*--((($L$3="全部")+('出货退货'!$D$2:$D$500=$L$3))>0)*--(('出货退货'!$B$2:$B$500=B9)>0)*--(('出货退货'!$G$2:$G$500=C9)>0)*'出货退货'!$J$2:$J$500) | F9: =SUMPRODUCT(('销售明细'!$A$2:$A$500=$C$3)*--((($F$3="全部")+('销售明细'!$B$2:$B$500=$F$3))>0)*--((($I$3="全部")+('销售明细'!$C$2:$C$500=$I$3))>0)*--((($L$3="全部")+('销售明细'!$D$2:$D$500=$L$3))>0)*--(('销售明细'!$B$2:$B$500=B9)>0)*--(('销售明细'!$H$2:$H$500=C9)>0)*'销售明细'!$O$2:$O$500) | G9: =E9-F9 | H9: =IFERROR(E9/F9,0) | I9: =SUMPRODUCT(('出货退货'!$A$2:$A$500=$C$3)*--((($F$3="全部")+('出货退货'!$B$2:$B$500=$F$3))>0)*--((($I$3="全部")+('出货退货'!$C$2:$C$500=$I$3))>0)*--((($L$3="全部")+('出货退货'!$D$2:$D$500=$L$3))>0)*--(('出货退货'!$B$2:$B$500=B9)>0)*--(('出货退货'!$G$2:$G$500=C9)>0)*'出货退货'!$I$2:$I$500) | J9: =SUMPRODUCT(('销售明细'!$A$2:$A$500=$C$3)*--((($F$3="全部")+('销售明细'!$B$2:$B$500=$F$3))>0)*--((($I$3="全部")+('销售明细'!$C$2:$C$500=$I$3))>0)*--((($L$3="全部")+('销售明细'!$D$2:$D$500=$L$3))>0)*--(('销售明细'!$B$2:$B$500=B9)>0)*--(('销售明细'!$H$2:$H$500=C9)>0)*'销售明细'!$N$2:$N$500) | K9: =IF(E9=0,"缺出货源",IF(H9<0.8,"出货低于POS",IF(H9>1.2,"出货高于POS","匹配")))
B10: 盒马 | C10: 431448153 | D10: 盒马工坊 蒜香无骨鸡爪 230g | E10: =SUMPRODUCT(('出货退货'!$A$2:$A$500=$C$3)*--((($F$3="全部")+('出货退货'!$B$2:$B$500=$F$3))>0)*--((($I$3="全部")+('出货退货'!$C$2:$C$500=$I$3))>0)*--((($L$3="全部")+('出货退货'!$D$2:$D$500=$L$3))>0)*--(('出货退货'!$B$2:$B$500=B10)>0)*--(('出货退货'!$G$2:$G$500=C10)>0)*'出货退货'!$J$2:$J$500) | F10: =SUMPRODUCT(('销售明细'!$A$2:$A$500=$C$3)*--((($F$3="全部")+('销售明细'!$B$2:$B$500=$F$3))>0)*--((($I$3="全部")+('销售明细'!$C$2:$C$500=$I$3))>0)*--((($L$3="全部")+('销售明细'!$D$2:$D$500=$L$3))>0)*--(('销售明细'!$B$2:$B$500=B10)>0)*--(('销售明细'!$H$2:$H$500=C10)>0)*'销售明细'!$O$2:$O$500) | G10: =E10-F10 | H10: =IFERROR(E10/F10,0) | I10: =SUMPRODUCT(('出货退货'!$A$2:$A$500=$C$3)*--((($F$3="全部")+('出货退货'!$B$2:$B$500=$F$3))>0)*--((($I$3="全部")+('出货退货'!$C$2:$C$500=$I$3))>0)*--((($L$3="全部")+('出货退货'!$D$2:$D$500=$L$3))>0)*--(('出货退货'!$B$2:$B$500=B10)>0)*--(('出货退货'!$G$2:$G$500=C10)>0)*'出货退货'!$I$2:$I$500) | J10: =SUMPRODUCT(('销售明细'!$A$2:$A$500=$C$3)*--((($F$3="全部")+('销售明细'!$B$2:$B$500=$F$3))>0)*--((($I$3="全部")+('销售明细'!$C$2:$C$500=$I$3))>0)*--((($L$3="全部")+('销售明细'!$D$2:$D$500=$L$3))>0)*--(('销售明细'!$B$2:$B$500=B10)>0)*--(('销售明细'!$H$2:$H$500=C10)>0)*'销售明细'!$N$2:$N$500) | K10: =IF(E10=0,"缺出货源",IF(H10<0.8,"出货低于POS",IF(H10>1.2,"出货高于POS","匹配")))
B11: 天虹 | C11: v000110869 | D11: 脱骨侠双椒无骨鸭掌 | E11: =SUMPRODUCT(('出货退货'!$A$2:$A$500=$C$3)*--((($F$3="全部")+('出货退货'!$B$2:$B$500=$F$3))>0)*--((($I$3="全部")+('出货退货'!$C$2:$C$500=$I$3))>0)*--((($L$3="全部")+('出货退货'!$D$2:$D$500=$L$3))>0)*--(('出货退货'!$B$2:$B$500=B11)>0)*--(('出货退货'!$G$2:$G$500=C11)>0)*'出货退货'!$J$2:$J$500) | F11: =SUMPRODUCT(('销售明细'!$A$2:$A$500=$C$3)*--((($F$3="全部")+('销售明细'!$B$2:$B$500=$F$3))>0)*--((($I$3="全部")+('销售明细'!$C$2:$C$500=$I$3))>0)*--((($L$3="全部")+('销售明细'!$D$2:$D$500=$L$3))>0)*--(('销售明细'!$B$2:$B$500=B11)>0)*--(('销售明细'!$H$2:$H$500=C11)>0)*'销售明细'!$O$2:$O$500) | G11: =E11-F11 | H11: =IFERROR(E11/F11,0) | I11: =SUMPRODUCT(('出货退货'!$A$2:$A$500=$C$3)*--((($F$3="全部")+('出货退货'!$B$2:$B$500=$F$3))>0)*--((($I$3="全部")+('出货退货'!$C$2:$C$500=$I$3))>0)*--((($L$3="全部")+('出货退货'!$D$2:$D$500=$L$3))>0)*--(('出货退货'!$B$2:$B$500=B11)>0)*--(('出货退货'!$G$2:$G$500=C11)>0)*'出货退货'!$I$2:$I$500) | J11: =SUMPRODUCT(('销售明细'!$A$2:$A$500=$C$3)*--((($F$3="全部")+('销售明细'!$B$2:$B$500=$F$3))>0)*--((($I$3="全部")+('销售明细'!$C$2:$C$500=$I$3))>0)*--((($L$3="全部")+('销售明细'!$D$2:$D$500=$L$3))>0)*--(('销售明细'!$B$2:$B$500=B11)>0)*--(('销售明细'!$H$2:$H$500=C11)>0)*'销售明细'!$N$2:$N$500) | K11: =IF(E11=0,"缺出货源",IF(H11<0.8,"出货低于POS",IF(H11>1.2,"出货高于POS","匹配")))
B12: 家得福 | C12: 10081319 | D12: 脱骨侠酸辣柠檬无骨鸡爪780g | E12: =SUMPRODUCT(('出货退货'!$A$2:$A$500=$C$3)*--((($F$3="全部")+('出货退货'!$B$2:$B$500=$F$3))>0)*--((($I$3="全部")+('出货退货'!$C$2:$C$500=$I$3))>0)*--((($L$3="全部")+('出货退货'!$D$2:$D$500=$L$3))>0)*--(('出货退货'!$B$2:$B$500=B12)>0)*--(('出货退货'!$G$2:$G$500=C12)>0)*'出货退货'!$J$2:$J$500) | F12: =SUMPRODUCT(('销售明细'!$A$2:$A$500=$C$3)*--((($F$3="全部")+('销售明细'!$B$2:$B$500=$F$3))>0)*--((($I$3="全部")+('销售明细'!$C$2:$C$500=$I$3))>0)*--((($L$3="全部")+('销售明细'!$D$2:$D$500=$L$3))>0)*--(('销售明细'!$B$2:$B$500=B12)>0)*--(('销售明细'!$H$2:$H$500=C12)>0)*'销售明细'!$O$2:$O$500) | G12: =E12-F12 | H12: =IFERROR(E12/F12,0) | I12: =SUMPRODUCT(('出货退货'!$A$2:$A$500=$C$3)*--((($F$3="全部")+('出货退货'!$B$2:$B$500=$F$3))>0)*--((($I$3="全部")+('出货退货'!$C$2:$C$500=$I$3))>0)*--((($L$3="全部")+('出货退货'!$D$2:$D$500=$L$3))>0)*--(('出货退货'!$B$2:$B$500=B12)>0)*--(('出货退货'!$G$2:$G$500=C12)>0)*'出货退货'!$I$2:$I$500) | J12: =SUMPRODUCT(('销售明细'!$A$2:$A$500=$C$3)*--((($F$3="全部")+('销售明细'!$B$2:$B$500=$F$3))>0)*--((($I$3="全部")+('销售明细'!$C$2:$C$500=$I$3))>0)*--((($L$3="全部")+('销售明细'!$D$2:$D$500=$L$3))>0)*--(('销售明细'!$B$2:$B$500=B12)>0)*--(('销售明细'!$H$2:$H$500=C12)>0)*'销售明细'!$N$2:$N$500) | K12: =IF(E12=0,"缺出货源",IF(H12<0.8,"出货低于POS",IF(H12>1.2,"出货高于POS","匹配")))
B15: 原始数据：POS销售明细与出货明细
B16: 来源 | C16: 数据日期 | D16: KA系统 | E16: 商品编码 | F16: 商品名称 | G16: 门店名称 | H16: 数量 | I16: 金额 | J16: 渠道/来源字段
B18: POS | C18: ='销售明细'!A2 | D18: ='销售明细'!B2 | E18: ='销售明细'!H2 | F18: ='销售明细'!J2 | G18: ='销售明细'!F2 | H18: ='销售明细'!N2 | I18: ='销售明细'!O2 | J18: ='销售明细'!M2
B19: POS | C19: ='销售明细'!A3 | D19: ='销售明细'!B3 | E19: ='销售明细'!H3 | F19: ='销售明细'!J3 | G19: ='销售明细'!F3 | H19: ='销售明细'!N3 | I19: ='销售明细'!O3 | J19: ='销售明细'!M3
B20: POS | C20: ='销售明细'!A4 | D20: ='销售明细'!B4 | E20: ='销售明细'!H4 | F20: ='销售明细'!J4 | G20: ='销售明细'!F4 | H20: ='销售明细'!N4 | I20: ='销售明细'!O4 | J20: ='销售明细'!M4
B21: POS | C21: ='销售明细'!A5 | D21: ='销售明细'!B5 | E21: ='销售明细'!H5 | F21: ='销售明细'!J5 | G21: ='销售明细'!F5 | H21: ='销售明细'!N5 | I21: ='销售明细'!O5 | J21: ='销售明细'!M5
B22: POS | C22: ='销售明细'!A6 | D22: ='销售明细'!B6 | E22: ='销售明细'!H6 | F22: ='销售明细'!J6 | G22: ='销售明细'!F6 | H22: ='销售明细'!N6 | I22: ='销售明细'!O6 | J22: ='销售明细'!M6
B23: POS | C23: ='销售明细'!A7 | D23: ='销售明细'!B7 | E23: ='销售明细'!H7 | F23: ='销售明细'!J7 | G23: ='销售明细'!F7 | H23: ='销售明细'!N7 | I23: ='销售明细'!O7 | J23: ='销售明细'!M7
B24: POS | C24: ='销售明细'!A8 | D24: ='销售明细'!B8 | E24: ='销售明细'!H8 | F24: ='销售明细'!J8 | G24: ='销售明细'!F8 | H24: ='销售明细'!N8 | I24: ='销售明细'!O8 | J24: ='销售明细'!M8
B25: POS | C25: ='销售明细'!A9 | D25: ='销售明细'!B9 | E25: ='销售明细'!H9 | F25: ='销售明细'!J9 | G25: ='销售明细'!F9 | H25: ='销售明细'!N9 | I25: ='销售明细'!O9 | J25: ='销售明细'!M9
B26: POS | C26: ='销售明细'!A10 | D26: ='销售明细'!B10 | E26: ='销售明细'!H10 | F26: ='销售明细'!J10 | G26: ='销售明细'!F10 | H26: ='销售明细'!N10 | I26: ='销售明细'!O10 | J26: ='销售明细'!M10
B27: POS | C27: ='销售明细'!A11 | D27: ='销售明细'!B11 | E27: ='销售明细'!H11 | F27: ='销售明细'!J11 | G27: ='销售明细'!F11 | H27: ='销售明细'!N11 | I27: ='销售明细'!O11 | J27: ='销售明细'!M11
B28: POS | C28: ='销售明细'!A12 | D28: ='销售明细'!B12 | E28: ='销售明细'!H12 | F28: ='销售明细'!J12 | G28: ='销售明细'!F12 | H28: ='销售明细'!N12 | I28: ='销售明细'!O12 | J28: ='销售明细'!M12
B29: POS | C29: ='销售明细'!A13 | D29: ='销售明细'!B13 | E29: ='销售明细'!H13 | F29: ='销售明细'!J13 | G29: ='销售明细'!F13 | H29: ='销售明细'!N13 | I29: ='销售明细'!O13 | J29: ='销售明细'!M13
... B32: POS | C32: ='销售明细'!A16 | D32: ='销售明细'!B16 | E32: ='销售明细'!H16 | F32: ='销售明细'!J16 | G32: ='销售明细'!F16 | H32: ='销售明细'!N16 | I32: ='销售明细'!O16 | J32: ='销售明细'!M16
B35: 出货 | C35: ='出货退货'!A2 | D35: ='出货退货'!B2 | E35: ='出货退货'!G2 | F35: ='出货退货'!H2 | G35: ='出货退货'!F2 | H35: ='出货退货'!I2 | I35: ='出货退货'!J2 | J35: ='出货退货'!M2
B36: 出货 | C36: ='出货退货'!A3 | D36: ='出货退货'!B3 | E36: ='出货退货'!G3 | F36: ='出货退货'!H3 | G36: ='出货退货'!F3 | H36: ='出货退货'!I3 | I36: ='出货退货'!J3 | J36: ='出货退货'!M3
B37: 出货 | C37: ='出货退货'!A4 | D37: ='出货退货'!B4 | E37: ='出货退货'!G4 | F37: ='出货退货'!H4 | G37: ='出货退货'!F4 | H37: ='出货退货'!I4 | I37: ='出货退货'!J4 | J37: ='出货退货'!M4
B38: 出货 | C38: ='出货退货'!A5 | D38: ='出货退货'!B5 | E38: ='出货退货'!G5 | F38: ='出货退货'!H5 | G38: ='出货退货'!F5 | H38: ='出货退货'!I5 | I38: ='出货退货'!J5 | J38: ='出货退货'!M5
B39: 出货 | C39: ='出货退货'!A6 | D39: ='出货退货'!B6 | E39: ='出货退货'!G6 | F39: ='出货退货'!H6 | G39: ='出货退货'!F6 | H39: ='出货退货'!I6 | I39: ='出货退货'!J6 | J39: ='出货退货'!M6

Sheet 3-门店库存周转天数
A1: 门店端库存周转天数
A2: 关键词：POS数据、门店端库存、各大区、各单品、数据日前7天平均。
B3: 统计日期 | C3: =MAX('销售明细'!A2:A500) | E3: KA系统 | F3: 全部 | H3: 大区 | I3: 全部 | K3: 省份 | L3: 全部
B5: 汇总：各大区区分各单品库存周转天数
B6: 大区 | C6: 商品编码 | D6: 商品名称 | E6: 门店库存 | F6: 近7日平均销量 | G6: 库存周转天数 | H6: 有库存门店数 | I6: 动销门店数 | J6: 风险
B7: 华东 | C7: 4354168 | D7: 脱骨侠无骨鸡爪(柠檬味) | E7: =SUMPRODUCT(('库存明细'!$A$2:$A$500=$C$3)*--((($F$3="全部")+('库存明细'!$B$2:$B$500=$F$3))>0)*--((($I$3="全部")+('库存明细'!$C$2:$C$500=$I$3))>0)*--((($L$3="全部")+('库存明细'!$D$2:$D$500=$L$3))>0)*--(('库存明细'!$C$2:$C$500=B7)>0)*--(('库存明细'!$H$2:$H$500=C7)>0)*'库存明细'!$J$2:$J$500) | F7: =SUMPRODUCT(('库存明细'!$A$2:$A$500=$C$3)*--((($F$3="全部")+('库存明细'!$B$2:$B$500=$F$3))>0)*--((($I$3="全部")+('库存明细'!$C$2:$C$500=$I$3))>0)*--((($L$3="全部")+('库存明细'!$D$2:$D$500=$L$3))>0)*--(('库存明细'!$C$2:$C$500=B7)>0)*--(('库存明细'!$H$2:$H$500=C7)>0)*'库存明细'!$M$2:$M$500) | G7: =IFERROR(E7/F7,"") | H7: =COUNTIFS('库存明细'!$A$2:$A$500,$C$3,'库存明细'!$C$2:$C$500,B7,'库存明细'!$H$2:$H$500,C7,'库存明细'!$J$2:$J$500,">0") | I7: =COUNTIFS('销售明细'!$A$2:$A$500,$C$3,'销售明细'!$C$2:$C$500,B7,'销售明细'!$H$2:$H$500,C7,'销售明细'!$N$2:$N$500,">0") | J7: =IF(G7="","无动销",IF(G7>60,"高风险","正常"))
B8: 华南 | C8: 4502138 | D8: 脱骨侠虎皮凤爪(白松露味) | E8: =SUMPRODUCT(('库存明细'!$A$2:$A$500=$C$3)*--((($F$3="全部")+('库存明细'!$B$2:$B$500=$F$3))>0)*--((($I$3="全部")+('库存明细'!$C$2:$C$500=$I$3))>0)*--((($L$3="全部")+('库存明细'!$D$2:$D$500=$L$3))>0)*--(('库存明细'!$C$2:$C$500=B8)>0)*--(('库存明细'!$H$2:$H$500=C8)>0)*'库存明细'!$J$2:$J$500) | F8: =SUMPRODUCT(('库存明细'!$A$2:$A$500=$C$3)*--((($F$3="全部")+('库存明细'!$B$2:$B$500=$F$3))>0)*--((($I$3="全部")+('库存明细'!$C$2:$C$500=$I$3))>0)*--((($L$3="全部")+('库存明细'!$D$2:$D$500=$L$3))>0)*--(('库存明细'!$C$2:$C$500=B8)>0)*--(('库存明细'!$H$2:$H$500=C8)>0)*'库存明细'!$M$2:$M$500) | G8: =IFERROR(E8/F8,"") | H8: =COUNTIFS('库存明细'!$A$2:$A$500,$C$3,'库存明细'!$C$2:$C$500,B8,'库存明细'!$H$2:$H$500,C8,'库存明细'!$J$2:$J$500,">0") | I8: =COUNTIFS('销售明细'!$A$2:$A$500,$C$3,'销售明细'!$C$2:$C$500,B8,'销售明细'!$H$2:$H$500,C8,'销售明细'!$N$2:$N$500,">0") | J8: =IF(G8="","无动销",IF(G8>60,"高风险","正常"))
B9: 华南 | C9: 25354863 | D9: 常温脱骨侠无骨鸡爪柠檬 | E9: =SUMPRODUCT(('库存明细'!$A$2:$A$500=$C$3)*--((($F$3="全部")+('库存明细'!$B$2:$B$500=$F$3))>0)*--((($I$3="全部")+('库存明细'!$C$2:$C$500=$I$3))>0)*--((($L$3="全部")+('库存明细'!$D$2:$D$500=$L$3))>0)*--(('库存明细'!$C$2:$C$500=B9)>0)*--(('库存明细'!$H$2:$H$500=C9)>0)*'库存明细'!$J$2:$J$500) | F9: =SUMPRODUCT(('库存明细'!$A$2:$A$500=$C$3)*--((($F$3="全部")+('库存明细'!$B$2:$B$500=$F$3))>0)*--((($I$3="全部")+('库存明细'!$C$2:$C$500=$I$3))>0)*--((($L$3="全部")+('库存明细'!$D$2:$D$500=$L$3))>0)*--(('库存明细'!$C$2:$C$500=B9)>0)*--(('库存明细'!$H$2:$H$500=C9)>0)*'库存明细'!$M$2:$M$500) | G9: =IFERROR(E9/F9,"") | H9: =COUNTIFS('库存明细'!$A$2:$A$500,$C$3,'库存明细'!$C$2:$C$500,B9,'库存明细'!$H$2:$H$500,C9,'库存明细'!$J$2:$J$500,">0") | I9: =COUNTIFS('销售明细'!$A$2:$A$500,$C$3,'销售明细'!$C$2:$C$500,B9,'销售明细'!$H$2:$H$500,C9,'销售明细'!$N$2:$N$500,">0") | J9: =IF(G9="","无动销",IF(G9>60,"高风险","正常"))
B10: 华北 | C10: 5150673 | D10: 脱骨侠无骨鸡爪(柠檬味)158g | E10: =SUMPRODUCT(('库存明细'!$A$2:$A$500=$C$3)*--((($F$3="全部")+('库存明细'!$B$2:$B$500=$F$3))>0)*--((($I$3="全部")+('库存明细'!$C$2:$C$500=$I$3))>0)*--((($L$3="全部")+('库存明细'!$D$2:$D$500=$L$3))>0)*--(('库存明细'!$C$2:$C$500=B10)>0)*--(('库存明细'!$H$2:$H$500=C10)>0)*'库存明细'!$J$2:$J$500) | F10: =SUMPRODUCT(('库存明细'!$A$2:$A$500=$C$3)*--((($F$3="全部")+('库存明细'!$B$2:$B$500=$F$3))>0)*--((($I$3="全部")+('库存明细'!$C$2:$C$500=$I$3))>0)*--((($L$3="全部")+('库存明细'!$D$2:$D$500=$L$3))>0)*--(('库存明细'!$C$2:$C$500=B10)>0)*--(('库存明细'!$H$2:$H$500=C10)>0)*'库存明细'!$M$2:$M$500) | G10: =IFERROR(E10/F10,"") | H10: =COUNTIFS('库存明细'!$A$2:$A$500,$C$3,'库存明细'!$C$2:$C$500,B10,'库存明细'!$H$2:$H$500,C10,'库存明细'!$J$2:$J$500,">0") | I10: =COUNTIFS('销售明细'!$A$2:$A$500,$C$3,'销售明细'!$C$2:$C$500,B10,'销售明细'!$H$2:$H$500,C10,'销售明细'!$N$2:$N$500,">0") | J10: =IF(G10="","无动销",IF(G10>60,"高风险","正常"))
B11: 华中 | C11: 431448153 | D11: 盒马工坊 蒜香无骨鸡爪 230g | E11: =SUMPRODUCT(('库存明细'!$A$2:$A$500=$C$3)*--((($F$3="全部")+('库存明细'!$B$2:$B$500=$F$3))>0)*--((($I$3="全部")+('库存明细'!$C$2:$C$500=$I$3))>0)*--((($L$3="全部")+('库存明细'!$D$2:$D$500=$L$3))>0)*--(('库存明细'!$C$2:$C$500=B11)>0)*--(('库存明细'!$H$2:$H$500=C11)>0)*'库存明细'!$J$2:$J$500) | F11: =SUMPRODUCT(('库存明细'!$A$2:$A$500=$C$3)*--((($F$3="全部")+('库存明细'!$B$2:$B$500=$F$3))>0)*--((($I$3="全部")+('库存明细'!$C$2:$C$500=$I$3))>0)*--((($L$3="全部")+('库存明细'!$D$2:$D$500=$L$3))>0)*--(('库存明细'!$C$2:$C$500=B11)>0)*--(('库存明细'!$H$2:$H$500=C11)>0)*'库存明细'!$M$2:$M$500) | G11: =IFERROR(E11/F11,"") | H11: =COUNTIFS('库存明细'!$A$2:$A$500,$C$3,'库存明细'!$C$2:$C$500,B11,'库存明细'!$H$2:$H$500,C11,'库存明细'!$J$2:$J$500,">0") | I11: =COUNTIFS('销售明细'!$A$2:$A$500,$C$3,'销售明细'!$C$2:$C$500,B11,'销售明细'!$H$2:$H$500,C11,'销售明细'!$N$2:$N$500,">0") | J11: =IF(G11="","无动销",IF(G11>60,"高风险","正常"))
B12: 华东 | C12: 10081319 | D12: 脱骨侠酸辣柠檬无骨鸡爪780g | E12: =SUMPRODUCT(('库存明细'!$A$2:$A$500=$C$3)*--((($F$3="全部")+('库存明细'!$B$2:$B$500=$F$3))>0)*--((($I$3="全部")+('库存明细'!$C$2:$C$500=$I$3))>0)*--((($L$3="全部")+('库存明细'!$D$2:$D$500=$L$3))>0)*--(('库存明细'!$C$2:$C$500=B12)>0)*--(('库存明细'!$H$2:$H$500=C12)>0)*'库存明细'!$J$2:$J$500) | F12: =SUMPRODUCT(('库存明细'!$A$2:$A$500=$C$3)*--((($F$3="全部")+('库存明细'!$B$2:$B$500=$F$3))>0)*--((($I$3="全部")+('库存明细'!$C$2:$C$500=$I$3))>0)*--((($L$3="全部")+('库存明细'!$D$2:$D$500=$L$3))>0)*--(('库存明细'!$C$2:$C$500=B12)>0)*--(('库存明细'!$H$2:$H$500=C12)>0)*'库存明细'!$M$2:$M$500) | G12: =IFERROR(E12/F12,"") | H12: =COUNTIFS('库存明细'!$A$2:$A$500,$C$3,'库存明细'!$C$2:$C$500,B12,'库存明细'!$H$2:$H$500,C12,'库存明细'!$J$2:$J$500,">0") | I12: =COUNTIFS('销售明细'!$A$2:$A$500,$C$3,'销售明细'!$C$2:$C$500,B12,'销售明细'!$H$2:$H$500,C12,'销售明细'!$N$2:$N$500,">0") | J12: =IF(G12="","无动销",IF(G12>60,"高风险","正常"))
B15: 原始数据：库存明细
B16: 数据日期 | C16: KA系统 | D16: 大区 | E16: 省份 | F16: 门店编码 | G16: 门店名称 | H16: 商品编码 | I16: 商品名称 | J16: 门店库存 | K16: 近7日平均销量 | L16: 周转天数 | M16: 是否超60天
B18: ='库存明细'!A2 | C18: ='库存明细'!B2 | D18: ='库存明细'!C2 | E18: ='库存明细'!D2 | F18: ='库存明细'!E2 | G18: ='库存明细'!F2 | H18: ='库存明细'!H2 | I18: ='库存明细'!I2 | J18: ='库存明细'!J2 | K18: ='库存明细'!M2 | L18: ='库存明细'!N2 | M18: ='库存明细'!O2
B19: ='库存明细'!A3 | C19: ='库存明细'!B3 | D19: ='库存明细'!C3 | E19: ='库存明细'!D3 | F19: ='库存明细'!E3 | G19: ='库存明细'!F3 | H19: ='库存明细'!H3 | I19: ='库存明细'!I3 | J19: ='库存明细'!J3 | K19: ='库存明细'!M3 | L19: ='库存明细'!N3 | M19: ='库存明细'!O3
B20: ='库存明细'!A4 | C20: ='库存明细'!B4 | D20: ='库存明细'!C4 | E20: ='库存明细'!D4 | F20: ='库存明细'!E4 | G20: ='库存明细'!F4 | H20: ='库存明细'!H4 | I20: ='库存明细'!I4 | J20: ='库存明细'!J4 | K20: ='库存明细'!M4 | L20: ='库存明细'!N4 | M20: ='库存明细'!O4
B21: ='库存明细'!A5 | C21: ='库存明细'!B5 | D21: ='库存明细'!C5 | E21: ='库存明细'!D5 | F21: ='库存明细'!E5 | G21: ='库存明细'!F5 | H21: ='库存明细'!H5 | I21: ='库存明细'!I5 | J21: ='库存明细'!J5 | K21: ='库存明细'!M5 | L21: ='库存明细'!N5 | M21: ='库存明细'!O5
B22: ='库存明细'!A6 | C22: ='库存明细'!B6 | D22: ='库存明细'!C6 | E22: ='库存明细'!D6 | F22: ='库存明细'!E6 | G22: ='库存明细'!F6 | H22: ='库存明细'!H6 | I22: ='库存明细'!I6 | J22: ='库存明细'!J6 | K22: ='库存明细'!M6 | L22: ='库存明细'!N6 | M22: ='库存明细'!O6
B23: ='库存明细'!A7 | C23: ='库存明细'!B7 | D23: ='库存明细'!C7 | E23: ='库存明细'!D7 | F23: ='库存明细'!E7 | G23: ='库存明细'!F7 | H23: ='库存明细'!H7 | I23: ='库存明细'!I7 | J23: ='库存明细'!J7 | K23: ='库存明细'!M7 | L23: ='库存明细'!N7 | M23: ='库存明细'!O7
B24: ='库存明细'!A8 | C24: ='库存明细'!B8 | D24: ='库存明细'!C8 | E24: ='库存明细'!D8 | F24: ='库存明细'!E8 | G24: ='库存明细'!F8 | H24: ='库存明细'!H8 | I24: ='库存明细'!I8 | J24: ='库存明细'!J8 | K24: ='库存明细'!M8 | L24: ='库存明细'!N8 | M24: ='库存明细'!O8
B25: ='库存明细'!A9 | C25: ='库存明细'!B9 | D25: ='库存明细'!C9 | E25: ='库存明细'!D9 | F25: ='库存明细'!E9 | G25: ='库存明细'!F9 | H25: ='库存明细'!H9 | I25: ='库存明细'!I9 | J25: ='库存明细'!J9 | K25: ='库存明细'!M9 | L25: ='库存明细'!N9 | M25: ='库存明细'!O9
B26: ='库存明细'!A10 | C26: ='库存明细'!B10 | D26: ='库存明细'!C10 | E26: ='库存明细'!D10 | F26: ='库存明细'!E10 | G26: ='库存明细'!F10 | H26: ='库存明细'!H10 | I26: ='库存明细'!I10 | J26: ='库存明细'!J10 | K26: ='库存明细'!M10 | L26: ='库存明细'!N10 | M26: ='库存明细'!O10
B27: ='库存明细'!A11 | C27: ='库存明细'!B11 | D27: ='库存明细'!C11 | E27: ='库存明细'!D11 | F27: ='库存明细'!E11 | G27: ='库存明细'!F11 | H27: ='库存明细'!H11 | I27: ='库存明细'!I11 | J27: ='库存明细'!J11 | K27: ='库存明细'!M11 | L27: ='库存明细'!N11 | M27: ='库存明细'!O11
B28: ='库存明细'!A12 | C28: ='库存明细'!B12 | D28: ='库存明细'!C12 | E28: ='库存明细'!D12 | F28: ='库存明细'!E12 | G28: ='库存明细'!F12 | H28: ='库存明细'!H12 | I28: ='库存明细'!I12 | J28: ='库存明细'!J12 | K28: ='库存明细'!M12 | L28: ='库存明细'!N12 | M28: ='库存明细'!O12
B29: ='库存明细'!A13 | C29: ='库存明细'!B13 | D29: ='库存明细'!C13 | E29: ='库存明细'!D13 | F29: ='库存明细'!E13 | G29: ='库存明细'!F13 | H29: ='库存明细'!H13 | I29: ='库存明细'!I13 | J29: ='库存明细'!J13 | K29: ='库存明细'!M13 | L29: ='库存明细'!N13 | M29: ='库存明细'!O13
... B46: ='库存明细'!A30 | C46: ='库存明细'!B30 | D46: ='库存明细'!C30 | E46: ='库存明细'!D30 | F46: ='库存明细'!E30 | G46: ='库存明细'!F30 | H46: ='库存明细'!H30 | I46: ='库存明细'!I30 | J46: ='库存明细'!J30 | K46: ='库存明细'!M30 | L46: ='库存明细'!N30 | M46: ='库存明细'!O30

Sheet 4-超60天门店排名
A1: 超60天门店排名
A2: 关键词：各大区、库存周转天数超60天、门店数排名。
B3: 统计日期 | C3: =MAX('销售明细'!A2:A500) | E3: KA系统 | F3: 全部 | H3: 大区 | I3: 全部 | K3: 省份 | L3: 全部
B5: 汇总：各大区库存周转天数超60天门店数排名
B6: 排名 | C6: 大区 | D6: 超60天门店数 | E6: 门店库存 | F6: 近7日平均销量 | G6: 平均周转天数 | H6: 主要风险单品 | I6: 处理建议
B7: 1 | C7: =IFERROR(INDEX($L$20:$L$24,MATCH(LARGE($M$20:$M$24,B7),$M$20:$M$24,0)),"") | D7: =IFERROR(INDEX($M$20:$M$24,MATCH(C7,$L$20:$L$24,0)),0) | E7: =IFERROR(INDEX($N$20:$N$24,MATCH(C7,$L$20:$L$24,0)),0) | F7: =IFERROR(INDEX($O$20:$O$24,MATCH(C7,$L$20:$L$24,0)),0) | G7: =IFERROR(INDEX($P$20:$P$24,MATCH(C7,$L$20:$L$24,0)),"") | H7: =IFERROR(INDEX('库存明细'!$I$2:$I$500,MATCH(MAXIFS('库存明细'!$N$2:$N$500,'库存明细'!$C$2:$C$500,C7),'库存明细'!$N$2:$N$500,0)),"") | I7: =IF(D7>0,"优先清理无动销库存/调拨/促销","正常跟踪")
B8: 2 | C8: =IFERROR(INDEX($L$20:$L$24,MATCH(LARGE($M$20:$M$24,B8),$M$20:$M$24,0)),"") | D8: =IFERROR(INDEX($M$20:$M$24,MATCH(C8,$L$20:$L$24,0)),0) | E8: =IFERROR(INDEX($N$20:$N$24,MATCH(C8,$L$20:$L$24,0)),0) | F8: =IFERROR(INDEX($O$20:$O$24,MATCH(C8,$L$20:$L$24,0)),0) | G8: =IFERROR(INDEX($P$20:$P$24,MATCH(C8,$L$20:$L$24,0)),"") | H8: =IFERROR(INDEX('库存明细'!$I$2:$I$500,MATCH(MAXIFS('库存明细'!$N$2:$N$500,'库存明细'!$C$2:$C$500,C8),'库存明细'!$N$2:$N$500,0)),"") | I8: =IF(D8>0,"优先清理无动销库存/调拨/促销","正常跟踪")
B9: 3 | C9: =IFERROR(INDEX($L$20:$L$24,MATCH(LARGE($M$20:$M$24,B9),$M$20:$M$24,0)),"") | D9: =IFERROR(INDEX($M$20:$M$24,MATCH(C9,$L$20:$L$24,0)),0) | E9: =IFERROR(INDEX($N$20:$N$24,MATCH(C9,$L$20:$L$24,0)),0) | F9: =IFERROR(INDEX($O$20:$O$24,MATCH(C9,$L$20:$L$24,0)),0) | G9: =IFERROR(INDEX($P$20:$P$24,MATCH(C9,$L$20:$L$24,0)),"") | H9: =IFERROR(INDEX('库存明细'!$I$2:$I$500,MATCH(MAXIFS('库存明细'!$N$2:$N$500,'库存明细'!$C$2:$C$500,C9),'库存明细'!$N$2:$N$500,0)),"") | I9: =IF(D9>0,"优先清理无动销库存/调拨/促销","正常跟踪")
B10: 4 | C10: =IFERROR(INDEX($L$20:$L$24,MATCH(LARGE($M$20:$M$24,B10),$M$20:$M$24,0)),"") | D10: =IFERROR(INDEX($M$20:$M$24,MATCH(C10,$L$20:$L$24,0)),0) | E10: =IFERROR(INDEX($N$20:$N$24,MATCH(C10,$L$20:$L$24,0)),0) | F10: =IFERROR(INDEX($O$20:$O$24,MATCH(C10,$L$20:$L$24,0)),0) | G10: =IFERROR(INDEX($P$20:$P$24,MATCH(C10,$L$20:$L$24,0)),"") | H10: =IFERROR(INDEX('库存明细'!$I$2:$I$500,MATCH(MAXIFS('库存明细'!$N$2:$N$500,'库存明细'!$C$2:$C$500,C10),'库存明细'!$N$2:$N$500,0)),"") | I10: =IF(D10>0,"优先清理无动销库存/调拨/促销","正常跟踪")
B11: 5 | C11: =IFERROR(INDEX($L$20:$L$24,MATCH(LARGE($M$20:$M$24,B11),$M$20:$M$24,0)),"") | D11: =IFERROR(INDEX($M$20:$M$24,MATCH(C11,$L$20:$L$24,0)),0) | E11: =IFERROR(INDEX($N$20:$N$24,MATCH(C11,$L$20:$L$24,0)),0) | F11: =IFERROR(INDEX($O$20:$O$24,MATCH(C11,$L$20:$L$24,0)),0) | G11: =IFERROR(INDEX($P$20:$P$24,MATCH(C11,$L$20:$L$24,0)),"") | H11: =IFERROR(INDEX('库存明细'!$I$2:$I$500,MATCH(MAXIFS('库存明细'!$N$2:$N$500,'库存明细'!$C$2:$C$500,C11),'库存明细'!$N$2:$N$500,0)),"") | I11: =IF(D11>0,"优先清理无动销库存/调拨/促销","正常跟踪")
B15: 原始数据：超60天门店明细
B16: 数据日期 | C16: KA系统 | D16: 大区 | E16: 省份 | F16: 门店编码 | G16: 门店名称 | H16: 商品编码 | I16: 商品名称 | J16: 门店库存 | K16: 近7日平均销量 | L16: 周转天数 | M16: 是否超60天
B18: ='库存明细'!A2 | C18: ='库存明细'!B2 | D18: ='库存明细'!C2 | E18: ='库存明细'!D2 | F18: ='库存明细'!E2 | G18: ='库存明细'!F2 | H18: ='库存明细'!H2 | I18: ='库存明细'!I2 | J18: ='库存明细'!J2 | K18: ='库存明细'!M2 | L18: ='库存明细'!N2 | M18: ='库存明细'!O2
B19: ='库存明细'!A3 | C19: ='库存明细'!B3 | D19: ='库存明细'!C3 | E19: ='库存明细'!D3 | F19: ='库存明细'!E3 | G19: ='库存明细'!F3 | H19: ='库存明细'!H3 | I19: ='库存明细'!I3 | J19: ='库存明细'!J3 | K19: ='库存明细'!M3 | L19: ='库存明细'!N3 | M19: ='库存明细'!O3
B20: ='库存明细'!A4 | C20: ='库存明细'!B4 | D20: ='库存明细'!C4 | E20: ='库存明细'!D4 | F20: ='库存明细'!E4 | G20: ='库存明细'!F4 | H20: ='库存明细'!H4 | I20: ='库存明细'!I4 | J20: ='库存明细'!J4 | K20: ='库存明细'!M4 | L20: ='库存明细'!N4 | M20: ='库存明细'!O4 | N20: =SUMPRODUCT(('库存明细'!$A$2:$A$500=$C$3)*--((($F$3="全部")+('库存明细'!$B$2:$B$500=$F$3))>0)*--((($I$3="全部")+('库存明细'!$C$2:$C$500=$I$3))>0)*--((($L$3="全部")+('库存明细'!$D$2:$D$500=$L$3))>0)*--(('库存明细'!$C$2:$C$500=L20)>0)*'库存明细'!$J$2:$J$500) | O20: =SUMPRODUCT(('库存明细'!$A$2:$A$500=$C$3)*--((($F$3="全部")+('库存明细'!$B$2:$B$500=$F$3))>0)*--((($I$3="全部")+('库存明细'!$C$2:$C$500=$I$3))>0)*--((($L$3="全部")+('库存明细'!$D$2:$D$500=$L$3))>0)*--(('库存明细'!$C$2:$C$500=L20)>0)*'库存明细'!$M$2:$M$500) | P20: =IFERROR(N20/O20,"")
B21: ='库存明细'!A5 | C21: ='库存明细'!B5 | D21: ='库存明细'!C5 | E21: ='库存明细'!D5 | F21: ='库存明细'!E5 | G21: ='库存明细'!F5 | H21: ='库存明细'!H5 | I21: ='库存明细'!I5 | J21: ='库存明细'!J5 | K21: ='库存明细'!M5 | L21: ='库存明细'!N5 | M21: ='库存明细'!O5 | N21: =SUMPRODUCT(('库存明细'!$A$2:$A$500=$C$3)*--((($F$3="全部")+('库存明细'!$B$2:$B$500=$F$3))>0)*--((($I$3="全部")+('库存明细'!$C$2:$C$500=$I$3))>0)*--((($L$3="全部")+('库存明细'!$D$2:$D$500=$L$3))>0)*--(('库存明细'!$C$2:$C$500=L21)>0)*'库存明细'!$J$2:$J$500) | O21: =SUMPRODUCT(('库存明细'!$A$2:$A$500=$C$3)*--((($F$3="全部")+('库存明细'!$B$2:$B$500=$F$3))>0)*--((($I$3="全部")+('库存明细'!$C$2:$C$500=$I$3))>0)*--((($L$3="全部")+('库存明细'!$D$2:$D$500=$L$3))>0)*--(('库存明细'!$C$2:$C$500=L21)>0)*'库存明细'!$M$2:$M$500) | P21: =IFERROR(N21/O21,"")
B22: ='库存明细'!A6 | C22: ='库存明细'!B6 | D22: ='库存明细'!C6 | E22: ='库存明细'!D6 | F22: ='库存明细'!E6 | G22: ='库存明细'!F6 | H22: ='库存明细'!H6 | I22: ='库存明细'!I6 | J22: ='库存明细'!J6 | K22: ='库存明细'!M6 | L22: ='库存明细'!N6 | M22: ='库存明细'!O6 | N22: =SUMPRODUCT(('库存明细'!$A$2:$A$500=$C$3)*--((($F$3="全部")+('库存明细'!$B$2:$B$500=$F$3))>0)*--((($I$3="全部")+('库存明细'!$C$2:$C$500=$I$3))>0)*--((($L$3="全部")+('库存明细'!$D$2:$D$500=$L$3))>0)*--(('库存明细'!$C$2:$C$500=L22)>0)*'库存明细'!$J$2:$J$500) | O22: =SUMPRODUCT(('库存明细'!$A$2:$A$500=$C$3)*--((($F$3="全部")+('库存明细'!$B$2:$B$500=$F$3))>0)*--((($I$3="全部")+('库存明细'!$C$2:$C$500=$I$3))>0)*--((($L$3="全部")+('库存明细'!$D$2:$D$500=$L$3))>0)*--(('库存明细'!$C$2:$C$500=L22)>0)*'库存明细'!$M$2:$M$500) | P22: =IFERROR(N22/O22,"")
B23: ='库存明细'!A7 | C23: ='库存明细'!B7 | D23: ='库存明细'!C7 | E23: ='库存明细'!D7 | F23: ='库存明细'!E7 | G23: ='库存明细'!F7 | H23: ='库存明细'!H7 | I23: ='库存明细'!I7 | J23: ='库存明细'!J7 | K23: ='库存明细'!M7 | L23: ='库存明细'!N7 | M23: ='库存明细'!O7 | N23: =SUMPRODUCT(('库存明细'!$A$2:$A$500=$C$3)*--((($F$3="全部")+('库存明细'!$B$2:$B$500=$F$3))>0)*--((($I$3="全部")+('库存明细'!$C$2:$C$500=$I$3))>0)*--((($L$3="全部")+('库存明细'!$D$2:$D$500=$L$3))>0)*--(('库存明细'!$C$2:$C$500=L23)>0)*'库存明细'!$J$2:$J$500) | O23: =SUMPRODUCT(('库存明细'!$A$2:$A$500=$C$3)*--((($F$3="全部")+('库存明细'!$B$2:$B$500=$F$3))>0)*--((($I$3="全部")+('库存明细'!$C$2:$C$500=$I$3))>0)*--((($L$3="全部")+('库存明细'!$D$2:$D$500=$L$3))>0)*--(('库存明细'!$C$2:$C$500=L23)>0)*'库存明细'!$M$2:$M$500) | P23: =IFERROR(N23/O23,"")
B24: ='库存明细'!A8 | C24: ='库存明细'!B8 | D24: ='库存明细'!C8 | E24: ='库存明细'!D8 | F24: ='库存明细'!E8 | G24: ='库存明细'!F8 | H24: ='库存明细'!H8 | I24: ='库存明细'!I8 | J24: ='库存明细'!J8 | K24: ='库存明细'!M8 | L24: ='库存明细'!N8 | M24: ='库存明细'!O8 | N24: =SUMPRODUCT(('库存明细'!$A$2:$A$500=$C$3)*--((($F$3="全部")+('库存明细'!$B$2:$B$500=$F$3))>0)*--((($I$3="全部")+('库存明细'!$C$2:$C$500=$I$3))>0)*--((($L$3="全部")+('库存明细'!$D$2:$D$500=$L$3))>0)*--(('库存明细'!$C$2:$C$500=L24)>0)*'库存明细'!$J$2:$J$500) | O24: =SUMPRODUCT(('库存明细'!$A$2:$A$500=$C$3)*--((($F$3="全部")+('库存明细'!$B$2:$B$500=$F$3))>0)*--((($I$3="全部")+('库存明细'!$C$2:$C$500=$I$3))>0)*--((($L$3="全部")+('库存明细'!$D$2:$D$500=$L$3))>0)*--(('库存明细'!$C$2:$C$500=L24)>0)*'库存明细'!$M$2:$M$500) | P24: =IFERROR(N24/O24,"")
B25: ='库存明细'!A9 | C25: ='库存明细'!B9 | D25: ='库存明细'!C9 | E25: ='库存明细'!D9 | F25: ='库存明细'!E9 | G25: ='库存明细'!F9 | H25: ='库存明细'!H9 | I25: ='库存明细'!I9 | J25: ='库存明细'!J9 | K25: ='库存明细'!M9 | L25: ='库存明细'!N9 | M25: ='库存明细'!O9
B26: ='库存明细'!A10 | C26: ='库存明细'!B10 | D26: ='库存明细'!C10 | E26: ='库存明细'!D10 | F26: ='库存明细'!E10 | G26: ='库存明细'!F10 | H26: ='库存明细'!H10 | I26: ='库存明细'!I10 | J26: ='库存明细'!J10 | K26: ='库存明细'!M10 | L26: ='库存明细'!N10 | M26: ='库存明细'!O10
B27: ='库存明细'!A11 | C27: ='库存明细'!B11 | D27: ='库存明细'!C11 | E27: ='库存明细'!D11 | F27: ='库存明细'!E11 | G27: ='库存明细'!F11 | H27: ='库存明细'!H11 | I27: ='库存明细'!I11 | J27: ='库存明细'!J11 | K27: ='库存明细'!M11 | L27: ='库存明细'!N11 | M27: ='库存明细'!O11
B28: ='库存明细'!A12 | C28: ='库存明细'!B12 | D28: ='库存明细'!C12 | E28: ='库存明细'!D12 | F28: ='库存明细'!E12 | G28: ='库存明细'!F12 | H28: ='库存明细'!H12 | I28: ='库存明细'!I12 | J28: ='库存明细'!J12 | K28: ='库存明细'!M12 | L28: ='库存明细'!N12 | M28: ='库存明细'!O12
B29: ='库存明细'!A13 | C29: ='库存明细'!B13 | D29: ='库存明细'!C13 | E29: ='库存明细'!D13 | F29: ='库存明细'!E13 | G29: ='库存明细'!F13 | H29: ='库存明细'!H13 | I29: ='库存明细'!I13 | J29: ='库存明细'!J13 | K29: ='库存明细'!M13 | L29: ='库存明细'!N13 | M29: ='库存明细'!O13
B30: ='库存明细'!A14 | C30: ='库存明细'!B14 | D30: ='库存明细'!C14 | E30: ='库存明细'!D14 | F30: ='库存明细'!E14 | G30: ='库存明细'!F14 | H30: ='库存明细'!H14 | I30: ='库存明细'!I14 | J30: ='库存明细'!J14 | K30: ='库存明细'!M14 | L30: ='库存明细'!N14 | M30: ='库存明细'!O14
B31: ='库存明细'!A15 | C31: ='库存明细'!B15 | D31: ='库存明细'!C15 | E31: ='库存明细'!D15 | F31: ='库存明细'!E15 | G31: ='库存明细'!F15 | H31: ='库存明细'!H15 | I31: ='库存明细'!I15 | J31: ='库存明细'!J15 | K31: ='库存明细'!M15 | L31: ='库存明细'!N15 | M31: ='库存明细'!O15
B32: ='库存明细'!A16 | C32: ='库存明细'!B16 | D32: ='库存明细'!C16 | E32: ='库存明细'!D16 | F32: ='库存明细'!E16 | G32: ='库存明细'!F16 | H32: ='库存明细'!H16 | I32: ='库存明细'!I16 | J32: ='库存明细'!J16 | K32: ='库存明细'!M16 | L32: ='库存明细'!N16 | M32: ='库存明细'!O16
B33: ='库存明细'!A17 | C33: ='库存明细'!B17 | D33: ='库存明细'!C17 | E33: ='库存明细'!D17 | F33: ='库存明细'!E17 | G33: ='库存明细'!F17 | H33: ='库存明细'!H17 | I33: ='库存明细'!I17 | J33: ='库存明细'!J17 | K33: ='库存明细'!M17 | L33: ='库存明细'!N17 | M33: ='库存明细'!O17
B34: ='库存明细'!A18 | C34: ='库存明细'!B18 | D34: ='库存明细'!C18 | E34: ='库存明细'!D18 | F34: ='库存明细'!E18 | G34: ='库存明细'!F18 | H34: ='库存明细'!H18 | I34: ='库存明细'!I18 | J34: ='库存明细'!J18 | K34: ='库存明细'!M18 | L34: ='库存明细'!N18 | M34: ='库存明细'!O18
B35: ='库存明细'!A19 | C35: ='库存明细'!B19 | D35: ='库存明细'!C19 | E35: ='库存明细'!D19 | F35: ='库存明细'!E19 | G35: ='库存明细'!F19 | H35: ='库存明细'!H19 | I35: ='库存明细'!I19 | J35: ='库存明细'!J19 | K35: ='库存明细'!M19 | L35: ='库存明细'!N19 | M35: ='库存明细'!O19
B36: ='库存明细'!A20 | C36: ='库存明细'!B20 | D36: ='库存明细'!C20 | E36: ='库存明细'!D20 | F36: ='库存明细'!E20 | G36: ='库存明细'!F20 | H36: ='库存明细'!H20 | I36: ='库存明细'!I20 | J36: ='库存明细'!J20 | K36: ='库存明细'!M20 | L36: ='库存明细'!N20 | M36: ='库存明细'!O20
... B46: ='库存明细'!A30 | C46: ='库存明细'!B30 | D46: ='库存明细'!C30 | E46: ='库存明细'!D30 | F46: ='库存明细'!E30 | G46: ='库存明细'!F30 | H46: ='库存明细'!H30 | I46: ='库存明细'!I30 | J46: ='库存明细'!J30 | K46: ='库存明细'!M30 | L46: ='库存明细'!N30 | M46: ='库存明细'!O30

Sheet 销售明细
A1: 数据日期 | B1: KA系统 | C1: 大区 | D1: 省份 | E1: 门店编码 | F1: 门店名称 | G1: 是否DC | H1: 商品编码 | I1: 商品条码 | J1: 商品名称 | K1: 规格 | L1: 温层 | M1: 渠道 | N1: 销售数量 | O1: 销售金额 | P1: 含税口径 | Q1: 动销标记 | R1: 备注
A2: 46166 | B2: 大润发 | C2: 华东 | D2: 上海 | E2: 1001 | F2: 闸北店 | G2: 否 | H2: 4354168 | I2: 697000000001 | J2: 脱骨侠无骨鸡爪(柠檬味) | K2: 158g/袋 | L2: 常温 | M2: 线下 | N2: 210 | O2: 4675 | P2: 含税 | Q2: Y
A3: 46166 | B3: 大润发 | C3: 华东 | D3: 江苏 | E3: 1002 | F3: 杨浦店 | G3: 否 | H3: 4354169 | I3: 697000000002 | J3: 脱骨侠无骨鸡爪(泡椒味) | K3: 158g/袋 | L3: 常温 | M3: 京东到家 | N3: 86 | O3: 1978 | P3: 含税 | Q3: Y
A4: 46167 | B4: 大润发 | C4: 华南 | D4: 广东 | E4: 5001 | F4: 广州天河店 | G4: 否 | H4: 4502138 | I4: 697000000003 | J4: 脱骨侠虎皮凤爪(白松露味) | K4: 220g/盒 | L4: 冷藏 | M4: 美团 | N4: 134 | O4: 3350 | P4: 含税 | Q4: Y
A5: 46167 | B5: 沃尔玛 | C5: 华南 | D5: 广东 | E5: 101 | F5: 沃尔玛广州天河店 | G5: 否 | H5: 25354863 | I5: 0697765695110 | J5: 常温脱骨侠无骨鸡爪柠檬 | K5: 158g/袋 | L5: 常温 | M5: POS | N5: 190 | O5: 3800 | P5: 未税 | Q5: Y
A6: 46168 | B6: 华润 | C6: 华北 | D6: 北京 | E6: 204392 | F6: 皇姑店 | G6: 否 | H6: 5150673 | I6: 6973883075622 | J6: 脱骨侠无骨鸡爪(柠檬味)158g | K6: 158g/袋 | L6: 常温 | M6: 线下 | N6: 150 | O6: 2895 | P6: 含税 | Q6: Y
A7: 46168 | B7: 盒马 | C7: 华中 | D7: 湖北 | E7: HM001 | F7: 武汉珞狮路店 | G7: 否 | H7: 431448153 | I7: 6973883075387 | J7: 盒马工坊 蒜香无骨鸡爪 230g | K7: 230g/盒 | L7: 冷藏 | M7: POS | N7: 980 | O7: 12740 | P7: 含税 | Q7: Y
A8: 46169 | B8: 永辉 | C8: 华东 | D8: 浙江 | E8: 9626 | F8: 滨江区龙湖天街店 | G8: 否 | H8: 1830795 | I8: 6973883073277 | J8: 脱骨侠蒜香酸甜辣无骨鸡爪780g | K8: 780g/罐 | L8: 冷藏 | M8: POS | N8: 52 | O8: 2225 | P8: 含税 | Q8: Y
A9: 46169 | B9: 天虹 | C9: 华南 | D9: 广东 | E9: 104 | F9: 深圳创业天虹 | G9: 否 | H9: v000110869 | I9: 6977656954114 | J9: 脱骨侠双椒无骨鸭掌 | K9: 320g/袋 | L9: 冷藏 | M9: 天虹到家 | N9: 72 | O9: 2729 | P9: 含税 | Q9: Y
A10: 46170 | B10: 比优特 | C10: 东北 | D10: 黑龙江 | E10: 2201 | F10: 麓林山店 | G10: 否 | H10: 1156752 | I10: 6973883073277 | J10: 脱骨侠无骨鸡爪蒜香酸甜辣780g | K10: 780g/罐 | L10: 冷藏 | M10: POS | N10: 18 | O10: 629 | P10: 含税 | Q10: Y
A11: 46170 | B11: 家得福 | C11: 华东 | D11: 江苏 | E11: 1001 | F11: 家得福海棠店 | G11: 否 | H11: 10081319 | I11: 6973883073284 | J11: 脱骨侠酸辣柠檬无骨鸡爪780g | K11: 780g/罐 | L11: 冷藏 | M11: POS | N11: 35 | O11: 1033 | P11: 含税 | Q11: Y
A12: 46171 | B12: 大润发 | C12: 华北 | D12: 天津 | E12: 6001 | F12: 天津南开店 | G12: 否 | H12: 4354172 | I12: 697000000004 | J12: 脱骨侠盐焗鸡爪 | K12: 138g/袋 | L12: 常温 | M12: 线下 | N12: 98 | O12: 1421 | P12: 含税 | Q12: Y
A13: 46171 | B13: 沃尔玛 | C13: 华东 | D13: 浙江 | E13: 2470 | F13: 沃尔玛赤峰玉龙大街店 | G13: 否 | H13: 25325573 | I13: 0697388307468 | J13: 冷藏蒜香凤爪 | K13: 230g/盒 | L13: 冷藏 | M13: POS | N13: 79 | O13: 2500 | P13: 未税 | Q13: Y
... A16: 46172 | B16: 天虹 | C16: 华南 | D16: 广东 | E16: 104 | F16: 深圳创业天虹 | G16: 否 | H16: v000110869 | I16: 6977656954114 | J16: 脱骨侠双椒无骨鸭掌 | K16: 320g/袋 | L16: 冷藏 | M16: 京东到家 | N16: 88 | O16: 3335 | P16: 含税 | Q16: Y

Sheet 库存明细
A1: 数据日期 | B1: KA系统 | C1: 大区 | D1: 省份 | E1: 门店编码 | F1: 门店名称 | G1: 是否DC | H1: 商品编码 | I1: 商品名称 | J1: 门店库存 | K1: DC库存 | L1: 在途/待收 | M1: 近7日平均销量 | N1: 周转天数 | O1: 是否超60天 | P1: 备注
A2: 46172 | B2: 大润发 | C2: 华东 | D2: 上海 | E2: 1001 | F2: 闸北店 | G2: 否 | H2: 4354168 | I2: 脱骨侠无骨鸡爪(柠檬味) | J2: 15089 | K2: 1950 | L2: 725 | M2: 620 | N2: =IFERROR(J2/M2,"") | O2: =IF(N2="","",IF(N2>60,"Y","N"))
A3: 46172 | B3: 大润发 | C3: 华南 | D3: 广东 | E3: 5001 | F3: 广州天河店 | G3: 否 | H3: 4502138 | I3: 脱骨侠虎皮凤爪(白松露味) | J3: 13619 | K3: 1250 | L3: 550 | M3: 210 | N3: =IFERROR(J3/M3,"") | O3: =IF(N3="","",IF(N3>60,"Y","N"))
A4: 46172 | B4: 沃尔玛 | C4: 华南 | D4: 广东 | E4: 101 | F4: 沃尔玛广州天河店 | G4: 否 | H4: 25354863 | I4: 常温脱骨侠无骨鸡爪柠檬 | J4: 30943 | K4: 0 | L4: 840 | M4: 1408 | N4: =IFERROR(J4/M4,"") | O4: =IF(N4="","",IF(N4>60,"Y","N"))
A5: 46172 | B5: 华润 | C5: 华北 | D5: 北京 | E5: 204392 | F5: 皇姑店 | G5: 否 | H5: 5150673 | I5: 脱骨侠无骨鸡爪(柠檬味)158g | J5: 5233 | K5: 0 | L5: 0 | M5: 245 | N5: =IFERROR(J5/M5,"") | O5: =IF(N5="","",IF(N5>60,"Y","N"))
A6: 46172 | B6: 盒马 | C6: 华中 | D6: 湖北 | E6: HM001 | F6: 武汉珞狮路店 | G6: 否 | H6: 431448153 | I6: 盒马工坊 蒜香无骨鸡爪 230g | J6: 94942 | K6: 0 | L6: 21250 | M6: 20146 | N6: =IFERROR(J6/M6,"") | O6: =IF(N6="","",IF(N6>60,"Y","N"))
A7: 46172 | B7: 永辉 | C7: 华东 | D7: 浙江 | E7: 9626 | F7: 滨江区龙湖天街店 | G7: 否 | H7: 1830795 | I7: 脱骨侠蒜香酸甜辣无骨鸡爪780g | J7: 74 | K7: 0 | L7: 0 | M7: 7 | N7: =IFERROR(J7/M7,"") | O7: =IF(N7="","",IF(N7>60,"Y","N"))
A8: 46172 | B8: 天虹 | C8: 华南 | D8: 广东 | E8: 104 | F8: 深圳创业天虹 | G8: 否 | H8: v000110869 | I8: 脱骨侠双椒无骨鸭掌 | J8: 5444 | K8: 0 | L8: 0 | M8: 129 | N8: =IFERROR(J8/M8,"") | O8: =IF(N8="","",IF(N8>60,"Y","N"))
A9: 46172 | B9: 比优特 | C9: 东北 | D9: 黑龙江 | E9: 2201 | F9: 麓林山店 | G9: 否 | H9: 1156752 | I9: 脱骨侠无骨鸡爪蒜香酸甜辣780g | J9: 15925 | K9: 0 | L9: 0 | M9: 31 | N9: =IFERROR(J9/M9,"") | O9: =IF(N9="","",IF(N9>60,"Y","N"))
A10: 46172 | B10: 家得福 | C10: 华东 | D10: 江苏 | E10: 1001 | F10: 家得福海棠店 | G10: 否 | H10: 10081319 | I10: 脱骨侠酸辣柠檬无骨鸡爪780g | J10: 315 | K10: 0 | L10: 0 | M10: 6 | N10: =IFERROR(J10/M10,"") | O10: =IF(N10="","",IF(N10>60,"Y","N"))

Sheet 出货退货
A1: 数据日期 | B1: KA系统 | C1: 大区 | D1: 省份 | E1: 门店编码 | F1: 门店名称 | G1: 商品编码 | H1: 商品名称 | I1: 出货数量 | J1: 出货金额 | K1: 退货数量 | L1: 退货金额 | M1: 出货字段来源 | N1: 退货字段来源 | O1: 备注
A2: 46172 | B2: 盒马 | C2: 华中 | D2: 湖北 | E2: HM001 | F2: 武汉珞狮路店 | G2: 431448153 | H2: 盒马工坊 蒜香无骨鸡爪 230g | I2: 24043 | K2: 120 | M2: 当天入库采购件数数量 | N2: 退货数量
A3: 46172 | B3: 家得福 | C3: 华东 | D3: 江苏 | E3: 1001 | F3: 家得福海棠店 | G3: 10081319 | H3: 脱骨侠酸辣柠檬无骨鸡爪780g | I3: 315 | J3: 9050 | K3: 0 | L3: 0 | M3: 进货数量/含税进货金额 | N3: 含税退补金额
A4: 46172 | B4: 大润发 | C4: 华东 | D4: 上海 | E4: 1001 | F4: 闸北店 | G4: 4354168 | H4: 脱骨侠无骨鸡爪(柠檬味) | I4: 725 | M4: 待收 | N4: 源表无退货发生 | O4: 待收不等于真实出货，需业务确认
A5: 46172 | B5: 沃尔玛 | C5: 华南 | D5: 广东 | E5: 101 | F5: 沃尔玛广州天河店 | G5: 25354863 | H5: 常温脱骨侠无骨鸡爪柠檬 | M5: 缺进货源 | N5: 缺退货源 | O5: 需补退货/进货明细
