Workbook

Sheet 总览仪表盘
A1: KA销售新增统计字段模板
A2: 可替换明细页示例数据；总览页公式会自动汇总销售、库存、出货退货与周转风险。
B4: 销售金额 | D4: 销售数量 | H4: 门店库存 | J4: 超60天门店 | L4: ●
B5: =SUM('销售明细'!O2:O500) | D5: =SUM('销售明细'!N2:N500) | H5: =SUM('库存明细'!J2:J500) | J5: =COUNTIF('库存明细'!O2:O500,"Y")
B8: 按系统销售汇总 | H8: 按日期销售趋势
B9: KA系统 | C9: 销售金额 | D9: 销售数量 | E9: 占比 | H9: 日期 | I9: 销售金额 | J9: 销售数量 | K9: 动销门店
B10: 大润发 | C10: =SUMIF('销售明细'!B$2:B$500,B10,'销售明细'!O$2:O$500) | D10: =SUMIF('销售明细'!B$2:B$500,B10,'销售明细'!N$2:N$500) | E10: =IFERROR(C10/SUM($C$10:$C$17),0) | H10: 46166 | I10: =SUMIF('销售明细'!A$2:A$500,H10,'销售明细'!O$2:O$500) | J10: =SUMIF('销售明细'!A$2:A$500,H10,'销售明细'!N$2:N$500) | K10: =COUNTIFS('销售明细'!A$2:A$500,H10,'销售明细'!N$2:N$500,">0")
B11: 盒马 | C11: =SUMIF('销售明细'!B$2:B$500,B11,'销售明细'!O$2:O$500) | D11: =SUMIF('销售明细'!B$2:B$500,B11,'销售明细'!N$2:N$500) | E11: =IFERROR(C11/SUM($C$10:$C$17),0) | H11: 46167 | I11: =SUMIF('销售明细'!A$2:A$500,H11,'销售明细'!O$2:O$500) | J11: =SUMIF('销售明细'!A$2:A$500,H11,'销售明细'!N$2:N$500) | K11: =COUNTIFS('销售明细'!A$2:A$500,H11,'销售明细'!N$2:N$500,">0")
B12: 华润 | C12: =SUMIF('销售明细'!B$2:B$500,B12,'销售明细'!O$2:O$500) | D12: =SUMIF('销售明细'!B$2:B$500,B12,'销售明细'!N$2:N$500) | E12: =IFERROR(C12/SUM($C$10:$C$17),0) | H12: 46168 | I12: =SUMIF('销售明细'!A$2:A$500,H12,'销售明细'!O$2:O$500) | J12: =SUMIF('销售明细'!A$2:A$500,H12,'销售明细'!N$2:N$500) | K12: =COUNTIFS('销售明细'!A$2:A$500,H12,'销售明细'!N$2:N$500,">0")
B13: 沃尔玛 | C13: =SUMIF('销售明细'!B$2:B$500,B13,'销售明细'!O$2:O$500) | D13: =SUMIF('销售明细'!B$2:B$500,B13,'销售明细'!N$2:N$500) | E13: =IFERROR(C13/SUM($C$10:$C$17),0) | H13: 46169 | I13: =SUMIF('销售明细'!A$2:A$500,H13,'销售明细'!O$2:O$500) | J13: =SUMIF('销售明细'!A$2:A$500,H13,'销售明细'!N$2:N$500) | K13: =COUNTIFS('销售明细'!A$2:A$500,H13,'销售明细'!N$2:N$500,">0")
B14: 永辉 | C14: =SUMIF('销售明细'!B$2:B$500,B14,'销售明细'!O$2:O$500) | D14: =SUMIF('销售明细'!B$2:B$500,B14,'销售明细'!N$2:N$500) | E14: =IFERROR(C14/SUM($C$10:$C$17),0) | H14: 46170 | I14: =SUMIF('销售明细'!A$2:A$500,H14,'销售明细'!O$2:O$500) | J14: =SUMIF('销售明细'!A$2:A$500,H14,'销售明细'!N$2:N$500) | K14: =COUNTIFS('销售明细'!A$2:A$500,H14,'销售明细'!N$2:N$500,">0")
B15: 天虹 | C15: =SUMIF('销售明细'!B$2:B$500,B15,'销售明细'!O$2:O$500) | D15: =SUMIF('销售明细'!B$2:B$500,B15,'销售明细'!N$2:N$500) | E15: =IFERROR(C15/SUM($C$10:$C$17),0) | H15: 46171 | I15: =SUMIF('销售明细'!A$2:A$500,H15,'销售明细'!O$2:O$500) | J15: =SUMIF('销售明细'!A$2:A$500,H15,'销售明细'!N$2:N$500) | K15: =COUNTIFS('销售明细'!A$2:A$500,H15,'销售明细'!N$2:N$500,">0")
B16: 比优特 | C16: =SUMIF('销售明细'!B$2:B$500,B16,'销售明细'!O$2:O$500) | D16: =SUMIF('销售明细'!B$2:B$500,B16,'销售明细'!N$2:N$500) | E16: =IFERROR(C16/SUM($C$10:$C$17),0) | H16: 46172 | I16: =SUMIF('销售明细'!A$2:A$500,H16,'销售明细'!O$2:O$500) | J16: =SUMIF('销售明细'!A$2:A$500,H16,'销售明细'!N$2:N$500) | K16: =COUNTIFS('销售明细'!A$2:A$500,H16,'销售明细'!N$2:N$500,">0")
B17: 家得福 | C17: =SUMIF('销售明细'!B$2:B$500,B17,'销售明细'!O$2:O$500) | D17: =SUMIF('销售明细'!B$2:B$500,B17,'销售明细'!N$2:N$500) | E17: =IFERROR(C17/SUM($C$10:$C$17),0)
B20: 大区库存周转风险 | H20: 出货 / POS 对比
B21: 大区 | C21: 门店库存 | D21: 近7日均销 | E21: 周转天数 | F21: 超60天门店 | H21: KA系统 | I21: POS销售额 | J21: 出货金额 | K21: 差额 | L21: 出货/POS
B22: 华东 | C22: =SUMIF('库存明细'!C$2:C$500,B22,'库存明细'!J$2:J$500) | D22: =SUMIF('库存明细'!C$2:C$500,B22,'库存明细'!M$2:M$500) | E22: =IFERROR(C22/D22,"") | F22: =COUNTIFS('库存明细'!C$2:C$500,B22,'库存明细'!O$2:O$500,"Y") | H22: 大润发 | I22: =SUMIF('销售明细'!B$2:B$500,H22,'销售明细'!O$2:O$500) | J22: =SUMIF('出货退货'!B$2:B$500,H22,'出货退货'!J$2:J$500) | K22: =J22-I22 | L22: =IFERROR(J22/I22,0)
B23: 华南 | C23: =SUMIF('库存明细'!C$2:C$500,B23,'库存明细'!J$2:J$500) | D23: =SUMIF('库存明细'!C$2:C$500,B23,'库存明细'!M$2:M$500) | E23: =IFERROR(C23/D23,"") | F23: =COUNTIFS('库存明细'!C$2:C$500,B23,'库存明细'!O$2:O$500,"Y") | H23: 盒马 | I23: =SUMIF('销售明细'!B$2:B$500,H23,'销售明细'!O$2:O$500) | J23: =SUMIF('出货退货'!B$2:B$500,H23,'出货退货'!J$2:J$500) | K23: =J23-I23 | L23: =IFERROR(J23/I23,0)
B24: 华北 | C24: =SUMIF('库存明细'!C$2:C$500,B24,'库存明细'!J$2:J$500) | D24: =SUMIF('库存明细'!C$2:C$500,B24,'库存明细'!M$2:M$500) | E24: =IFERROR(C24/D24,"") | F24: =COUNTIFS('库存明细'!C$2:C$500,B24,'库存明细'!O$2:O$500,"Y") | H24: 华润 | I24: =SUMIF('销售明细'!B$2:B$500,H24,'销售明细'!O$2:O$500) | J24: =SUMIF('出货退货'!B$2:B$500,H24,'出货退货'!J$2:J$500) | K24: =J24-I24 | L24: =IFERROR(J24/I24,0)
B25: 华中 | C25: =SUMIF('库存明细'!C$2:C$500,B25,'库存明细'!J$2:J$500) | D25: =SUMIF('库存明细'!C$2:C$500,B25,'库存明细'!M$2:M$500) | E25: =IFERROR(C25/D25,"") | F25: =COUNTIFS('库存明细'!C$2:C$500,B25,'库存明细'!O$2:O$500,"Y") | H25: 沃尔玛 | I25: =SUMIF('销售明细'!B$2:B$500,H25,'销售明细'!O$2:O$500) | J25: =SUMIF('出货退货'!B$2:B$500,H25,'出货退货'!J$2:J$500) | K25: =J25-I25 | L25: =IFERROR(J25/I25,0)
B26: 东北 | C26: =SUMIF('库存明细'!C$2:C$500,B26,'库存明细'!J$2:J$500) | D26: =SUMIF('库存明细'!C$2:C$500,B26,'库存明细'!M$2:M$500) | E26: =IFERROR(C26/D26,"") | F26: =COUNTIFS('库存明细'!C$2:C$500,B26,'库存明细'!O$2:O$500,"Y") | H26: 永辉 | I26: =SUMIF('销售明细'!B$2:B$500,H26,'销售明细'!O$2:O$500) | J26: =SUMIF('出货退货'!B$2:B$500,H26,'出货退货'!J$2:J$500) | K26: =J26-I26 | L26: =IFERROR(J26/I26,0)
H27: 天虹 | I27: =SUMIF('销售明细'!B$2:B$500,H27,'销售明细'!O$2:O$500) | J27: =SUMIF('出货退货'!B$2:B$500,H27,'出货退货'!J$2:J$500) | K27: =J27-I27 | L27: =IFERROR(J27/I27,0)
H28: 比优特 | I28: =SUMIF('销售明细'!B$2:B$500,H28,'销售明细'!O$2:O$500) | J28: =SUMIF('出货退货'!B$2:B$500,H28,'出货退货'!J$2:J$500) | K28: =J28-I28 | L28: =IFERROR(J28/I28,0)
H29: 家得福 | I29: =SUMIF('销售明细'!B$2:B$500,H29,'销售明细'!O$2:O$500) | J29: =SUMIF('出货退货'!B$2:B$500,H29,'出货退货'!J$2:J$500) | K29: =J29-I29 | L29: =IFERROR(J29/I29,0)

Sheet 日报看板-图片版
N1: 统计时间： 2026-05-31
B2: 销售额 | F2: 销量 | K2: 当月日均销量 | Q2: 品项 | R2: 销售额 | S2: 销量 | T2: PSD | U2: 库存 | V2: 周转天数 | W2: 日期 | X2: 蒜香 780g | Y2: 藤椒 780g | Z2: 柠檬 780g
B3: 0元 | F3: 0罐 | K3: 790罐 | Q3: 蒜香 780g | R3: 0 | S3: 0 | T3: 0 | U3: 0 | V3: 0 | W3: 46167 | X3: 0 | Y3: 0 | Z3: 0
Q4: 藤椒 780g | R4: 0 | S4: 0 | T4: 0 | U4: 0 | V4: 0 | W4: 46168 | X4: 0 | Y4: 0 | Z4: 0
B5: 环比昨日↓100.0% | F5: 环比昨日↓100.0% | Q5: 柠檬 780g | R5: 0 | S5: 0 | T5: 0 | U5: 0 | V5: 0 | W5: 46169 | X5: 0 | Y5: 0 | Z5: 0
W6: 46170 | X6: 0 | Y6: 0 | Z6: 0
B7: 库存 | F7: 有库存门店数 | K7: 动销门店数 | W7: 46171 | X7: 0 | Y7: 0 | Z7: 0
B8: 0罐 | F8: 1家 | K8: 1家 | W8: 46172 | X8: 0 | Y8: 0 | Z8: 0
W9: 46173 | X9: 0 | Y9: 0 | Z9: 0
B10: 环比昨日↓100.0%
A56: 门店明细-动销TOP5
A57: 门店名称 | B57: 销售数量 | C57: 销售金额 | D57: 库存数量 | E57: 库存金额 | F57: 库存天数 | G57: 排名
A58: 保定定州万达店 | B58: 50 | C58: 1344.9 | D58: 315 | E58: 5156.5 | F58: 6.3 | G58: 1
A59: 天津SM店 | B59: 47 | C59: 1259.9 | D59: 333 | E59: 5451.1 | F59: 7.1 | G59: 2
A60: 广州海珠丽影广场店 | B60: 38 | C60: 1022.2 | D60: 286 | E60: 4681.8 | F60: 7.5 | G60: 3
A61: 兰州城关万达店 | B61: 37 | C61: 993.8 | D61: 206 | E61: 3372.1 | F61: 5.6 | G61: 4
A62: 沈阳浑南龙湖店 | B62: 36 | C62: 962.4 | D62: 310 | E62: 5074.7 | F62: 8.6 | G62: 5
A64: 广州花都融创茂店 | B64: 12 | C64: 322.8 | D64: 201 | E64: 3290.3 | F64: 16.8 | G64: 4
A65: 深圳光明大仟里店 | B65: 12 | C65: 322.8 | E65: 2782.8 | F65: 14.2
A66: 深圳南山京东酒馆店 | B66: 7 | C66: 188.3 | E66: 2226.3 | F66: 19.4
A67: 深圳罗湖金光华店 | B67: 7 | C67: 188.3 | E67: 2029.9 | F67: 17.7
A68: 重庆云阳滨江大道店 | B68: 8 | C68: 215.2 | E68: 1718.8 | F68: 13.1
A69: 杭州滨江宝龙店 | B69: 2 | C69: 53.8 | E69: 376.5 | F69: 11.5
A70: 西安阳光天地店 | B70: 2 | C70: 53.8 | E70: 1195 | F70: 36.5
A71: 合肥瑶海万达店 | B71: 0 | C71: 0 | E71: 409.3 | F71: #NUM!
A72: 合肥旺东风大道店 | B72: 0 | C72: 0 | E72: 409.3 | F72: #NUM!
A73: 合肥肥东吾悦店 | B73: 0 | C73: 0 | E73: 409.3 | F73: #NUM!
A74: 合肥宝文店 | B74: 0 | C74: 0 | E74: 409.3 | F74: #NUM!
A75: 合肥瑶海n7店 | B75: 0 | C75: 0 | E75: 409.3 | F75: #NUM!
A76: 巢湖万达店 | B76: 0 | C76: 0 | E76: 409.3 | F76: #NUM!
A77: 惠州大亚湾万达店 | B77: 0 | C77: 0 | E77: 30.8 | F77: #NUM!
A78: 成都锦江交华店 | B78: 0 | C78: 0 | E78: 123.2 | F78: #NUM!
A79: 深圳光明大仟里店 | B79: 0 | C79: 0 | E79: 1971.2 | F79: #NUM!
A80: 深圳宝安大仟里店 | B80: 0 | C80: 0 | E80: 277.2 | F80: #NUM!
A81: 深圳罗湖益田假日店 | B81: 0 | C81: 0 | E81: 30.8 | F81: #NUM!
A82: 盐城中南城店 | B82: 0 | C82: 0 | E82: 409.3 | F82: #NUM!
... A85: 阜阳颍州万达店 | B85: 0 | C85: 0 | E85: 409.3 | F85: #NUM!
A87: 门店名称 | B87: 销量 | D87: 门店名称 | E87: 销量
A88: 成都锦江城市花园店 | B88: 30 | D88: 深圳罗湖金光华店 | E88: 11
A89: 重庆市-华福大道站 | B89: 29 | D89: 昆明五华吾悦店 | E89: 9
...

Sheet 销售明细
A1: 数据日期 | B1: KA系统 | C1: 大区 | D1: 省份 | E1: 门店编码 | F1: 门店名称 | G1: 是否DC | H1: 商品编码 | I1: 商品条码 | J1: 商品名称 | K1: 规格 | L1: 温层 | M1: 渠道 | N1: 销售数量 | O1: 销售金额 | P1: 含税口径 | Q1: 动销标记 | R1: 备注
A2: 46166 | B2: 大润发 | C2: 华东 | D2: 上海 | E2: 1001 | F2: 闸北店 | G2: 否 | H2: 4354168 | I2: 697000000001 | J2: 脱骨侠无骨鸡爪(柠檬味) | K2: 158g/袋 | L2: 常温 | M2: 线下 | N2: 210 | O2: 4675 | P2: 含税 | Q2: Y
A3: 46166 | B3: 大润发 | C3: 华东 | D3: 江苏 | E3: 1002 | F3: 杨浦店 | G3: 否 | H3: 4354169 | I3: 697000000002 | J3: 脱骨侠无骨鸡爪(泡椒味) | K3: 158g/袋 | L3: 常温 | M3: 京东到家 | N3: 86 | O3: 1978 | P3: 含税 | Q3: Y
A4: 46167 | B4: 大润发 | C4: 华南 | D4: 广东 | E4: 5001 | F4: 广州天河店 | G4: 否 | H4: 4502138 | I4: 697000000003 | J4: 脱骨侠虎皮凤爪(白松露味) | K4: 220g/盒 | L4: 冷藏 | M4: 美团 | N4: 134 | O4: 3350 | P4: 含税 | Q4: Y
A5: 46167 | B5: 沃尔玛 | C5: 华南 | D5: 广东 | E5: 101 | F5: 沃尔玛广州天河店 | G5: 否 | H5: 25354863 | I5: 0697765695110 | J5: 常温脱骨侠无骨鸡爪柠檬 | K5: 158g/袋 | L5: 常温 | M5: POS | N5: 190 | O5: 3800 | P5: 未税 | Q5: Y
A6: 46168 | B6: 华润 | C6: 华北 | D6: 北京 | E6: 204392 | F6: 皇姑店 | G6: 否 | H6: 5150673 | I6: 6973883075622 | J6: 脱骨侠无骨鸡爪(柠檬味)158g | K6: 158g/袋 | L6: 常温 | M6: 线下 | N6: 150 | O6: 2895 | P6: 含税 | Q6: Y
A7: 46168 | B7: 盒马 | C7: 华中 | D7: 湖北 | E7: HM001 | F7: 武汉珞狮路店 | G7: 否 | H7: 431448153 | I7: 6973883075387 | J7: 盒马工坊 蒜香无骨鸡爪 230g | K7: 230g/盒 | L7: 冷藏 | M7: POS | N7: 980 | O7: 12740 | P7: 含税 | Q7: Y
A8: 46169 | B8: 永辉 | C8: 华东 | D8: 浙江 | E8: 9626 | F8: 滨江区龙湖天街店 | G8: 否 | H8: 1830795 | I8: 6973883073277 | J8: 脱骨侠蒜香酸甜辣无骨鸡爪780g | K8: 780g/罐 | L8: 冷藏 | M8: POS | N8: 52 | O8: 2225 | P8: 含税 | Q8: Y
A9: 46169 | B9: 天虹 | C9: 华南 | D9: 广东 | E9: 104 | F9: 深圳创业天虹 | G9: 否 | H9: v000110869 | I9: 6977656954114 | J9: 脱骨侠双椒无骨鸭掌 | K9: 320g/袋 | L9: 冷藏 | M9: 天虹到家 | N9: 72 | O9: 2729 | P9: 含税 | Q9: Y
A10: 46170 | B10: 比优特 | C10: 东北 | D10: 黑龙江 | E10: 2201 | F10: 麓林山店 | G10: 否 | H10: 1156752 | I10: 6973883073277 | J10: 脱骨侠无骨鸡爪蒜香酸甜辣780g | K10: 780g/罐 | L10: 冷藏 | M10: POS | N10: 18 | O10: 629 | P10: 含税 | Q10: Y
A11: 46170 | B11: 家得福 | C11: 华东 | D11: 江苏 | E11: 1001 | F11: 家得福海棠店 | G11: 否 | H11: 10081319 | I11: 6973883073284 | J11: 脱骨侠酸辣柠檬无骨鸡爪780g | K11: 780g/罐 | L11: 冷藏 | M11: POS | N11: 35 | O11: 1033 | P11: 含税 | Q11: Y
A12: 46171 | B12: 大润发 | C12: 华北 | D12: 天津 | E12: 6001 | F12: 天津南开店 | G12: 否 | H12: 4354172 | I12: 697000000004 | J12: 脱骨侠盐焗鸡爪 | K12: 138g/袋 | L12: 常温 | M12: 线下 | N12: 98 | O12: 1421 | P12: 含税 | Q12: Y
A13: 46171 | B13: 沃尔玛 | C13: 华东 | D13: 浙江 | E13: 2470 | F13: 沃尔玛赤峰玉龙大街店 | G13: 否 | H13: 25325573 | I13: 0697388307468 | J13: 冷藏蒜香凤爪 | K13: 230g/盒 | L13: 冷藏 | M13: POS | N13: 79 | O13: 2500 | P13: 未税 | Q13: Y
... A16: 46172 | B16: 天虹 | C16: 华南 | D16: 广东 | E16: 104 | F16: 深圳创业天虹 | G16: 否 | H16: v000110869 | I16: 6977656954114 | J16: 脱骨侠双椒无骨鸭掌 | K16: 320g/袋 | L16: 冷藏 | M16: 京东到家 | N16: 88 | O16: 3335 | P16: 含税 | Q16: Y

Sheet 库存明细
A1: 数据日期 | B1: KA系统 | C1: 大区 | D1: 省份 | E1: 门店编码 | F1: 门店名称 | G1: 是否DC | H1: 商品编码 | I1: 商品名称 | J1: 门店库存 | K1: DC库存 | L1: 在途/待收 | M1: 近7日平均销量 | N1: 周转天数 | O1: 是否超60天 | P1: 备注
A2: 46172 | B2: 大润发 | C2: 华东 | D2: 上海 | E2: 1001 | F2: 闸北店 | G2: 否 | H2: 4354168 | I2: 脱骨侠无骨鸡爪(柠檬味) | J2: 15089 | K2: 1950 | L2: 725 | M2: 620 | N2: =IFERROR(J2/M2,"") | O2: =IF(N2="","",IF(N2>60,"Y","N"))
A3: 46172 | B3: 大润发 | C3: 华南 | D3: 广东 | E3: 5001 | F3: 广州天河店 | G3: 否 | H3: 4502138 | I3: 脱骨侠虎皮凤爪(白松露味) | J3: 13619 | K3: 1250 | L3: 550 | M3: 210 | N3: =IFERROR(J3/M3,"") | O3: =IF(N3="","",IF(N3>60,"Y","N"))
A4: 46172 | B4: 沃尔玛 | C4: 华南 | D4: 广东 | E4: 101 | F4: 沃尔玛广州天河店 | G4: 否 | H4: 25354863 | I4: 常温脱骨侠无骨鸡爪柠檬 | J4: 30943 | K4: 0 | L4: 840 | M4: 1408 | N4: =IFERROR(J4/M4,"") | O4: =IF(N4="","",IF(N4>60,"Y","N"))
A5: 46172 | B5: 华润 | C5: 华北 | D5: 北京 | E5: 204392 | F5: 皇姑店 | G5: 否 | H5: 5150673 | I5: 脱骨侠无骨鸡爪(柠檬味)158g | J5: 5233 | K5: 0 | L5: 0 | M5: 245 | N5: =IFERROR(J5/M5,"") | O5: =IF(N5="","",IF(N5>60,"Y","N"))
A6: 46172 | B6: 盒马 | C6: 华中 | D6: 湖北 | E6: HM001 | F6: 武汉珞狮路店 | G6: 否 | H6: 431448153 | I6: 盒马工坊 蒜香无骨鸡爪 230g | J6: 94942 | K6: 0 | L6: 21250 | M6: 20146 | N6: =IFERROR(J6/M6,"") | O6: =IF(N6="","",IF(N6>60,"Y","N"))
A7: 46172 | B7: 永辉 | C7: 华东 | D7: 浙江 | E7: 9626 | F7: 滨江区龙湖天街店 | G7: 否 | H7: 1830795 | I7: 脱骨侠蒜香酸甜辣无骨鸡爪780g | J7: 74 | K7: 0 | L7: 0 | M7: 7 | N7: =IFERROR(J7/M7,"") | O7: =IF(N7="","",IF(N7>60,"Y","N"))
A8: 46172 | B8: 天虹 | C8: 华南 | D8: 广东 | E8: 104 | F8: 深圳创业天虹 | G8: 否 | H8: v000110869 | I8: 脱骨侠双椒无骨鸭掌 | J8: 5444 | K8: 0 | L8: 0 | M8: 129 | N8: =IFERROR(J8/M8,"") | O8: =IF(N8="","",IF(N8>60,"Y","N"))
A9: 46172 | B9: 比优特 | C9: 东北 | D9: 黑龙江 | E9: 2201 | F9: 麓林山店 | G9: 否 | H9: 1156752 | I9: 脱骨侠无骨鸡爪蒜香酸甜辣780g | J9: 15925 | K9: 0 | L9: 0 | M9: 31 | N9: =IFERROR(J9/M9,"") | O9: =IF(N9="","",IF(N9>60,"Y","N"))
A10: 46172 | B10: 家得福 | C10: 华东 | D10: 江苏 | E10: 1001 | F10: 家得福海棠店 | G10: 否 | H10: 10081319 | I10: 脱骨侠酸辣柠檬无骨鸡爪780g | J10: 315 | K10: 0 | L10: 0 | M10: 6 | N10: =IFERROR(J10/M10,"") | O10: =IF(N10="","",IF(N10>60,"Y","N"))

Sheet 出货退货
A1: 数据日期 | B1: KA系统 | C1: 大区 | D1: 省份 | E1: 门店编码 | F1: 门店名称 | G1: 商品编码 | H1: 商品名称 | I1: 出货数量 | J1: 出货金额 | K1: 退货数量 | L1: 退货金额 | M1: 出货字段来源 | N1: 退货字段来源 | O1: 备注
A2: 46172 | B2: 盒马 | C2: 华中 | D2: 湖北 | E2: HM001 | F2: 武汉珞狮路店 | G2: 431448153 | H2: 盒马工坊 蒜香无骨鸡爪 230g | I2: 24043 | K2: 120 | M2: 当天入库采购件数数量 | N2: 退货数量
A3: 46172 | B3: 家得福 | C3: 华东 | D3: 江苏 | E3: 1001 | F3: 家得福海棠店 | G3: 10081319 | H3: 脱骨侠酸辣柠檬无骨鸡爪780g | I3: 315 | J3: 9050 | K3: 0 | L3: 0 | M3: 进货数量/含税进货金额 | N3: 含税退补金额
A4: 46172 | B4: 大润发 | C4: 华东 | D4: 上海 | E4: 1001 | F4: 闸北店 | G4: 4354168 | H4: 脱骨侠无骨鸡爪(柠檬味) | I4: 725 | M4: 待收 | N4: 源表无退货发生 | O4: 待收不等于真实出货，需业务确认
A5: 46172 | B5: 沃尔玛 | C5: 华南 | D5: 广东 | E5: 101 | F5: 沃尔玛广州天河店 | G5: 25354863 | H5: 常温脱骨侠无骨鸡爪柠檬 | M5: 缺进货源 | N5: 缺退货源 | O5: 需补退货/进货明细

Sheet 门店维表
A1: KA系统 | B1: 门店编码 | C1: 门店名称 | D1: 是否DC | E1: 大区 | F1: 省份 | G1: 城市 | H1: 内外区 | I1: 门店状态
A2: 大润发 | B2: 1001 | C2: 闸北店 | D2: 否 | E2: 华东 | F2: 上海 | G2: 上海 | H2: 内区 | I2: 开业
A3: 大润发 | B3: 1002 | C3: 杨浦店 | D3: 否 | E3: 华东 | F3: 上海 | G3: 上海 | H3: 内区 | I3: 开业
A4: 大润发 | B4: 5001 | C4: 广州天河店 | D4: 否 | E4: 华南 | F4: 广东 | G4: 广州 | H4: 外区 | I4: 开业
A5: 沃尔玛 | B5: 101 | C5: 沃尔玛广州天河店 | D5: 否 | E5: 华南 | F5: 广东 | G5: 广州 | H5: 外区 | I5: 开业
A6: 华润 | B6: 204392 | C6: 皇姑店 | D6: 否 | E6: 华北 | F6: 北京 | G6: 北京 | H6: 外区 | I6: 开业
A7: 盒马 | B7: HM001 | C7: 武汉珞狮路店 | D7: 否 | E7: 华中 | F7: 湖北 | G7: 武汉 | H7: 外区 | I7: 开业
A8: 永辉 | B8: 9626 | C8: 滨江区龙湖天街店 | D8: 否 | E8: 华东 | F8: 浙江 | G8: 杭州 | H8: 内区 | I8: 开业
A9: 天虹 | B9: 104 | C9: 深圳创业天虹 | D9: 否 | E9: 华南 | F9: 广东 | G9: 深圳 | H9: 外区 | I9: 开业
A10: 比优特 | B10: 2201 | C10: 麓林山店 | D10: 否 | E10: 东北 | F10: 黑龙江 | G10: 鹤岗 | H10: 外区 | I10: 开业
A11: 家得福 | B11: 1001 | C11: 家得福海棠店 | D11: 否 | E11: 华东 | F11: 江苏 | G11: 连云港 | H11: 内区 | I11: 开业

Sheet 商品维表
A1: KA系统 | B1: 商品编码 | C1: 商品条码 | D1: 统一商品名 | E1: 系统商品名 | F1: 规格 | G1: 温层 | H1: 口味 | I1: 产品线 | J1: 是否核心品
A2: 大润发 | B2: 4354168 | C2: 697000000001 | D2: 无骨鸡爪 柠檬味 158g | E2: 脱骨侠无骨鸡爪(柠檬味) | F2: 158g/袋 | G2: 常温 | H2: 柠檬 | I2: 无骨鸡爪 | J2: Y
A3: 大润发 | B3: 4502138 | C3: 697000000003 | D3: 虎皮凤爪 白松露味 | E3: 脱骨侠虎皮凤爪(白松露味) | F3: 220g/盒 | G3: 冷藏 | H3: 白松露 | I3: 虎皮凤爪 | J3: Y
A4: 沃尔玛 | B4: 25354863 | C4: 0697765695110 | D4: 无骨鸡爪 柠檬味 158g | E4: 常温脱骨侠无骨鸡爪柠檬 | F4: 158g/袋 | G4: 常温 | H4: 柠檬 | I4: 无骨鸡爪 | J4: Y
A5: 盒马 | B5: 431448153 | C5: 6973883075387 | D5: 蒜香无骨鸡爪 230g | E5: 盒马工坊 蒜香无骨鸡爪 230g | F5: 230g/盒 | G5: 冷藏 | H5: 蒜香 | I5: 无骨鸡爪 | J5: Y
A6: 天虹 | B6: v000110869 | C6: 6977656954114 | D6: 双椒无骨鸭掌 320g | E6: 脱骨侠双椒无骨鸭掌 | F6: 320g/袋 | G6: 冷藏 | H6: 双椒 | I6: 鸭掌 | J6: Y

Sheet 指标口径
A1: 指标 | B1: 计算口径 | C1: 建议字段/公式 | D1: 注意事项
A2: 销售数量 | B2: 按日期、系统、门店、商品、渠道汇总 POS 销售数量 | C2: SUMIFS(销售明细[销售数量], ...) | D2: 不同系统最小单位需统一
A3: 销售金额 | B3: 按同维度汇总 POS 销售金额，优先含税口径 | C3: SUMIFS(销售明细[销售金额], ...) | D3: 沃尔玛部分为未税，需保留标签或换算
A4: 出货数量 | B4: 优先取进货/入库/日收/月收/待收等字段 | C4: 出货退货[出货数量] | D4: 待收不一定等于真实出货
A5: 近7日平均销量 | B5: 建议 D-7 至 D-1 销售数量合计 / 7 | C5: SUMIFS(...)/7 | D5: 不建议包含数据日
A6: 门店库存周转天数 | B6: 门店库存 / 近7日平均销量 | C6: '=IFERROR(门店库存/近7日平均销量,"") | D6: 均销为0且有库存时标记无动销库存
A7: PSD | B7: 销售数量 / 有库存门店数 | C7: 销售数量/有库存门店数 | D7: 需确认分母沿用现有日报口径
A8: 超60天门店数 | B8: 周转天数>60 且门店库存>0 的门店数 | C8: COUNTIFS(...) | D8: 排除 DC、闭店、小店需依赖门店维表
A9: 退货率 | B9: 当月退货数量 / 当月进货数量 | C9: 退货数量/进货数量 | D9: 沃尔玛当前缺退货/进货源
