Workbook

Sheet 总览仪表盘
A1: KA销售新增统计字段模板
A2: 可替换明细页示例数据；总览页公式会自动汇总销售、库存、出货退货与周转风险。
B4: 销售金额 | D4: 销售数量 | H4: 门店库存 | J4: 超60天门店 | L4: ●
B5: =SUM(销售明细!O2:O500) -> 62845 | D5: =SUM(销售明细!N2:N500) -> 3527 | H5: =SUM(库存明细!J2:J500) -> 181584 | J5: =COUNTIF(库存明细!O2:O500,"Y") -> 2
B8: 按系统销售汇总 | H8: 按日期销售趋势
B9: KA系统 | C9: 销售金额 | D9: 销售数量 | E9: 占比 | H9: 日期 | I9: 销售金额 | J9: 销售数量 | K9: 动销门店
B10: 大润发 | C10: =SUMIF(销售明细!B$2:B$500,B10,销售明细!O$2:O$500) -> 16659 | D10: =SUMIF(销售明细!B$2:B$500,B10,销售明细!N$2:N$500) -> 763 | E10: =IFERROR(C10/SUM($C$10:$C$17),0) -> 0.26508075 | H10: 46166 | I10: =SUMIF(销售明细!A$2:A$500,H10,销售明细!O$2:O$500) -> 6653 | J10: =SUMIF(销售明细!A$2:A$500,H10,销售明细!N$2:N$500) -> 296 | K10: =COUNTIFS(销售明细!A$2:A$500,H10,销售明细!N$2:N$500,">0") -> 2
B11: 盒马 | C11: =SUMIF(销售明细!B$2:B$500,B11,销售明细!O$2:O$500) -> 27040 | D11: =SUMIF(销售明细!B$2:B$500,B11,销售明细!N$2:N$500) -> 2080 | E11: =IFERROR(C11/SUM($C$10:$C$17),0) -> 0.43026494 | H11: 46167 | I11: =SUMIF(销售明细!A$2:A$500,H11,销售明细!O$2:O$500) -> 7150 | J11: =SUMIF(销售明细!A$2:A$500,H11,销售明细!N$2:N$500) -> 324 | K11: =COUNTIFS(销售明细!A$2:A$500,H11,销售明细!N$2:N$500,">0") -> 2
B12: 华润 | C12: =SUMIF(销售明细!B$2:B$500,B12,销售明细!O$2:O$500) -> 2895 | D12: =SUMIF(销售明细!B$2:B$500,B12,销售明细!N$2:N$500) -> 150 | E12: =IFERROR(C12/SUM($C$10:$C$17),0) -> 0.046065717 | H12: 46168 | I12: =SUMIF(销售明细!A$2:A$500,H12,销售明细!O$2:O$500) -> 15635 | J12: =SUMIF(销售明细!A$2:A$500,H12,销售明细!N$2:N$500) -> 1130 | K12: =COUNTIFS(销售明细!A$2:A$500,H12,销售明细!N$2:N$500,">0") -> 2
B13: 沃尔玛 | C13: =SUMIF(销售明细!B$2:B$500,B13,销售明细!O$2:O$500) -> 6300 | D13: =SUMIF(销售明细!B$2:B$500,B13,销售明细!N$2:N$500) -> 269 | E13: =IFERROR(C13/SUM($C$10:$C$17),0) -> 0.10024664 | H13: 46169 | I13: =SUMIF(销售明细!A$2:A$500,H13,销售明细!O$2:O$500) -> 4954 | J13: =SUMIF(销售明细!A$2:A$500,H13,销售明细!N$2:N$500) -> 124 | K13: =COUNTIFS(销售明细!A$2:A$500,H13,销售明细!N$2:N$500,">0") -> 2
B14: 永辉 | C14: =SUMIF(销售明细!B$2:B$500,B14,销售明细!O$2:O$500) -> 2225 | D14: =SUMIF(销售明细!B$2:B$500,B14,销售明细!N$2:N$500) -> 52 | E14: =IFERROR(C14/SUM($C$10:$C$17),0) -> 0.035404567 | H14: 46170 | I14: =SUMIF(销售明细!A$2:A$500,H14,销售明细!O$2:O$500) -> 1662 | J14: =SUMIF(销售明细!A$2:A$500,H14,销售明细!N$2:N$500) -> 53 | K14: =COUNTIFS(销售明细!A$2:A$500,H14,销售明细!N$2:N$500,">0") -> 2
B15: 天虹 | C15: =SUMIF(销售明细!B$2:B$500,B15,销售明细!O$2:O$500) -> 6064 | D15: =SUMIF(销售明细!B$2:B$500,B15,销售明细!N$2:N$500) -> 160 | E15: =IFERROR(C15/SUM($C$10:$C$17),0) -> 0.096491368 | H15: 46171 | I15: =SUMIF(销售明细!A$2:A$500,H15,销售明细!O$2:O$500) -> 3921 | J15: =SUMIF(销售明细!A$2:A$500,H15,销售明细!N$2:N$500) -> 177 | K15: =COUNTIFS(销售明细!A$2:A$500,H15,销售明细!N$2:N$500,">0") -> 2
B16: 比优特 | C16: =SUMIF(销售明细!B$2:B$500,B16,销售明细!O$2:O$500) -> 629 | D16: =SUMIF(销售明细!B$2:B$500,B16,销售明细!N$2:N$500) -> 18 | E16: =IFERROR(C16/SUM($C$10:$C$17),0) -> 0.010008752 | H16: 46172 | I16: =SUMIF(销售明细!A$2:A$500,H16,销售明细!O$2:O$500) -> 22870 | J16: =SUMIF(销售明细!A$2:A$500,H16,销售明细!N$2:N$500) -> 1423 | K16: =COUNTIFS(销售明细!A$2:A$500,H16,销售明细!N$2:N$500,">0") -> 3
B17: 家得福 | C17: =SUMIF(销售明细!B$2:B$500,B17,销售明细!O$2:O$500) -> 1033 | D17: =SUMIF(销售明细!B$2:B$500,B17,销售明细!N$2:N$500) -> 35 | E17: =IFERROR(C17/SUM($C$10:$C$17),0) -> 0.016437266
B20: 大区库存周转风险 | H20: 出货 / POS 对比
B21: 大区 | C21: 门店库存 | D21: 近7日均销 | E21: 周转天数 | F21: 超60天门店 | H21: KA系统 | I21: POS销售额 | J21: 出货金额 | K21: 差额 | L21: 出货/POS
B22: 华东 | C22: =SUMIF(库存明细!C$2:C$500,B22,库存明细!J$2:J$500) -> 15478 | D22: =SUMIF(库存明细!C$2:C$500,B22,库存明细!M$2:M$500) -> 633 | E22: =IFERROR(C22/D22,"") -> 24.451817 | F22: =COUNTIFS(库存明细!C$2:C$500,B22,库存明细!O$2:O$500,"Y") -> 0 | H22: 大润发 | I22: =SUMIF(销售明细!B$2:B$500,H22,销售明细!O$2:O$500) -> 16659 | J22: =SUMIF(出货退货!B$2:B$500,H22,出货退货!J$2:J$500) -> 0 | K22: =J22-I22 -> -16659 | L22: =IFERROR(J22/I22,0) -> 0
B23: 华南 | C23: =SUMIF(库存明细!C$2:C$500,B23,库存明细!J$2:J$500) -> 50006 | D23: =SUMIF(库存明细!C$2:C$500,B23,库存明细!M$2:M$500) -> 1747 | E23: =IFERROR(C23/D23,"") -> 28.623927 | F23: =COUNTIFS(库存明细!C$2:C$500,B23,库存明细!O$2:O$500,"Y") -> 1 | H23: 盒马 | I23: =SUMIF(销售明细!B$2:B$500,H23,销售明细!O$2:O$500) -> 27040 | J23: =SUMIF(出货退货!B$2:B$500,H23,出货退货!J$2:J$500) -> 0 | K23: =J23-I23 -> -27040 | L23: =IFERROR(J23/I23,0) -> 0
B24: 华北 | C24: =SUMIF(库存明细!C$2:C$500,B24,库存明细!J$2:J$500) -> 5233 | D24: =SUMIF(库存明细!C$2:C$500,B24,库存明细!M$2:M$500) -> 245 | E24: =IFERROR(C24/D24,"") -> 21.359184 | F24: =COUNTIFS(库存明细!C$2:C$500,B24,库存明细!O$2:O$500,"Y") -> 0 | H24: 华润 | I24: =SUMIF(销售明细!B$2:B$500,H24,销售明细!O$2:O$500) -> 2895 | J24: =SUMIF(出货退货!B$2:B$500,H24,出货退货!J$2:J$500) -> 0 | K24: =J24-I24 -> -2895 | L24: =IFERROR(J24/I24,0) -> 0
B25: 华中 | C25: =SUMIF(库存明细!C$2:C$500,B25,库存明细!J$2:J$500) -> 94942 | D25: =SUMIF(库存明细!C$2:C$500,B25,库存明细!M$2:M$500) -> 20146 | E25: =IFERROR(C25/D25,"") -> 4.7126973 | F25: =COUNTIFS(库存明细!C$2:C$500,B25,库存明细!O$2:O$500,"Y") -> 0 | H25: 沃尔玛 | I25: =SUMIF(销售明细!B$2:B$500,H25,销售明细!O$2:O$500) -> 6300 | J25: =SUMIF(出货退货!B$2:B$500,H25,出货退货!J$2:J$500) -> 0 | K25: =J25-I25 -> -6300 | L25: =IFERROR(J25/I25,0) -> 0
B26: 东北 | C26: =SUMIF(库存明细!C$2:C$500,B26,库存明细!J$2:J$500) -> 15925 | D26: =SUMIF(库存明细!C$2:C$500,B26,库存明细!M$2:M$500) -> 31 | E26: =IFERROR(C26/D26,"") -> 513.70968 | F26: =COUNTIFS(库存明细!C$2:C$500,B26,库存明细!O$2:O$500,"Y") -> 1 | H26: 永辉 | I26: =SUMIF(销售明细!B$2:B$500,H26,销售明细!O$2:O$500) -> 2225 | J26: =SUMIF(出货退货!B$2:B$500,H26,出货退货!J$2:J$500) -> 0 | K26: =J26-I26 -> -2225 | L26: =IFERROR(J26/I26,0) -> 0
H27: 天虹 | I27: =SUMIF(销售明细!B$2:B$500,H27,销售明细!O$2:O$500) -> 6064 | J27: =SUMIF(出货退货!B$2:B$500,H27,出货退货!J$2:J$500) -> 0 | K27: =J27-I27 -> -6064 | L27: =IFERROR(J27/I27,0) -> 0
H28: 比优特 | I28: =SUMIF(销售明细!B$2:B$500,H28,销售明细!O$2:O$500) -> 629 | J28: =SUMIF(出货退货!B$2:B$500,H28,出货退货!J$2:J$500) -> 0 | K28: =J28-I28 -> -629 | L28: =IFERROR(J28/I28,0) -> 0
H29: 家得福 | I29: =SUMIF(销售明细!B$2:B$500,H29,销售明细!O$2:O$500) -> 1033 | J29: =SUMIF(出货退货!B$2:B$500,H29,出货退货!J$2:J$500) -> 9050 | K29: =J29-I29 -> 8017 | L29: =IFERROR(J29/I29,0) -> 8.7608906

Sheet 智能日报看板
A1: KA智能日报看板 | O1: 图表/明细计算区
A2: 筛选参数 | B2: 统计日期 | D2: KA系统 | F2: 大区 | H2: 省份 | J2: 温层 | L2: 渠道
B3: =MAX(销售明细!A2:A500) -> 46172 | D3: 全部 | F3: 全部 | H3: 全部 | J3: 全部 | L3: 全部 | P3: 日期 | Q3: 销售额 | R3: 销量
A4: 说明：销售、品项、渠道、门店TOP按销售明细汇总；库存与周转按库存明细汇总；出货/退货按出货退货页汇总。库存页暂不受温层、渠道筛选影响。 | P4: =$B$3-6 -> 46166 | Q4: =SUMPRODUCT((销售明细!$A$2:$A$500=$P$4)*--((($D$3="全部")+(销售明细!$B$2:$B$500=$D$3))>0)*--((($F$3="全部")+(销售明细!$C$2:$C$500=$F$3))>0)*--((($H$3="全部")+(销售明细!$D$2:$D$500=$H$3))>0)*--((($J$3="全部")+(销售明细!$L$2:$L$500=$J$3))>0)*--((($L$3="全部")+(销售明细!$M$2:$M$500=$L$3))>0)*销售明细!$O$2:$O$500) -> 6653 | R4: =SUMPRODUCT((销售明细!$A$2:$A$500=$P$4)*--((($D$3="全部")+(销售明细!$B$2:$B$500=$D$3))>0)*--((($F$3="全部")+(销售明细!$C$2:$C$500=$F$3))>0)*--((($H$3="全部")+(销售明细!$D$2:$D$500=$H$3))>0)*--((($J$3="全部")+(销售明细!$L$2:$L$500=$J$3))>0)*--((($L$3="全部")+(销售明细!$M$2:$M$500=$L$3))>0)*销售明细!$N$2:$N$500) -> 296
P5: =$B$3-5 -> 46167 | Q5: =SUMPRODUCT((销售明细!$A$2:$A$500=$P$5)*--((($D$3="全部")+(销售明细!$B$2:$B$500=$D$3))>0)*--((($F$3="全部")+(销售明细!$C$2:$C$500=$F$3))>0)*--((($H$3="全部")+(销售明细!$D$2:$D$500=$H$3))>0)*--((($J$3="全部")+(销售明细!$L$2:$L$500=$J$3))>0)*--((($L$3="全部")+(销售明细!$M$2:$M$500=$L$3))>0)*销售明细!$O$2:$O$500) -> 7150 | R5: =SUMPRODUCT((销售明细!$A$2:$A$500=$P$5)*--((($D$3="全部")+(销售明细!$B$2:$B$500=$D$3))>0)*--((($F$3="全部")+(销售明细!$C$2:$C$500=$F$3))>0)*--((($H$3="全部")+(销售明细!$D$2:$D$500=$H$3))>0)*--((($J$3="全部")+(销售明细!$L$2:$L$500=$J$3))>0)*--((($L$3="全部")+(销售明细!$M$2:$M$500=$L$3))>0)*销售明细!$N$2:$N$500) -> 324
B6: 销售额 | D6: 销量 | F6: 当月日均销量 | H6: 库存 | J6: 有库存门店数 | L6: 动销门店数 | P6: =$B$3-4 -> 46168 | Q6: =SUMPRODUCT((销售明细!$A$2:$A$500=$P$6)*--((($D$3="全部")+(销售明细!$B$2:$B$500=$D$3))>0)*--((($F$3="全部")+(销售明细!$C$2:$C$500=$F$3))>0)*--((($H$3="全部")+(销售明细!$D$2:$D$500=$H$3))>0)*--((($J$3="全部")+(销售明细!$L$2:$L$500=$J$3))>0)*--((($L$3="全部")+(销售明细!$M$2:$M$500=$L$3))>0)*销售明细!$O$2:$O$500) -> 15635 | R6: =SUMPRODUCT((销售明细!$A$2:$A$500=$P$6)*--((($D$3="全部")+(销售明细!$B$2:$B$500=$D$3))>0)*--((($F$3="全部")+(销售明细!$C$2:$C$500=$F$3))>0)*--((($H$3="全部")+(销售明细!$D$2:$D$500=$H$3))>0)*--((($J$3="全部")+(销售明细!$L$2:$L$500=$J$3))>0)*--((($L$3="全部")+(销售明细!$M$2:$M$500=$L$3))>0)*销售明细!$N$2:$N$500) -> 1130
B7: =SUMPRODUCT((销售明细!$A$2:$A$500=$B$3)*--((($D$3="全部")+(销售明细!$B$2:$B$500=$D$3))>0)*--((($F$3="全部")+(销售明细!$C$2:$C$500=$F$3))>0)*--((($H$3="全部")+(销售明细!$D$2:$D$500=$H$3))>0)*--((($J$3="全部")+(销售明细!$L$2:$L$500=$J$3))>0)*--((($L$3="全部")+(销售明细!$M$2:$M$500=$L$3))>0)*销售明细!$O$2:$O$500) -> 22870 | D7: =SUMPRODUCT((销售明细!$A$2:$A$500=$B$3)*--((($D$3="全部")+(销售明细!$B$2:$B$500=$D$3))>0)*--((($F$3="全部")+(销售明细!$C$2:$C$500=$F$3))>0)*--((($H$3="全部")+(销售明细!$D$2:$D$500=$H$3))>0)*--((($J$3="全部")+(销售明细!$L$2:$L$500=$J$3))>0)*--((($L$3="全部")+(销售明细!$M$2:$M$500=$L$3))>0)*销售明细!$N$2:$N$500) -> 1423 | F7: =IFERROR(SUMPRODUCT((TEXT(销售明细!$A$2:$A$500,"yyyymm")=TEXT($B$3,"yyyymm"))*--((($D$3="全部")+(销售明细!$B$2:$B$500=$D$3))>0)*--((($F$3="全部")+(销售明细!$C$2:$C$500=$F$3))>0)*--((($H$3="全部")+(销售明细!$D$2:$D$500=$H$3))>0)*--((($J$3="全部")+(销售明细!$L$2:$L$500=$J$3))>0)*--((($L$3="全部")+(销售明细!$M$2:$M$500=$L$3))>0)*销售明细!$N$2:$N$500)/DAY($B$3),0) -> 117.56667 | H7: =SUMPRODUCT((库存明细!$A$2:$A$500=$B$3)*--((($D$3="全部")+(库存明细!$B$2:$B$500=$D$3))>0)*--((($F$3="全部")+(库存明细!$C$2:$C$500=$F$3))>0)*--((($H$3="全部")+(库存明细!$D$2:$D$500=$H$3))>0)*库存明细!$J$2:$J$500) -> 181584 | J7: =IFERROR(ROWS(_xlfn.UNIQUE(_xlfn._xlws.FILTER(库存明细!$E$2:$E$500,((库存明细!$A$2:$A$500=$B$3)*--((($D$3="全部")+(库存明细!$B$2:$B$500=$D$3))>0)*--((($F$3="全部")+(库存明细!$C$2:$C$500=$F$3))>0)*--((($H$3="全部")+(库存明细!$D$2:$D$500=$H$3))>0))*(库存明细!$J$2:$J$500>0)))),0) -> 8 | L7: =IFERROR(ROWS(_xlfn.UNIQUE(_xlfn._xlws.FILTER(销售明细!$E$2:$E$500,((销售明细!$A$2:$A$500=$B$3)*--((($D$3="全部")+(销售明细!$B$2:$B$500=$D$3))>0)*--((($F$3="全部")+(销售明细!$C$2:$C$500=$F$3))>0)*--((($H$3="全部")+(销售明细!$D$2:$D$500=$H$3))>0)*--((($J$3="全部")+(销售明细!$L$2:$L$500=$J$3))>0)*--((($L$3="全部")+(销售明细!$M$2:$M$500=$L$3))>0))*(销售明细!$N$2:$N$500>0)))),0) -> 3 | P7: =$B$3-3 -> 46169 | Q7: =SUMPRODUCT((销售明细!$A$2:$A$500=$P$7)*--((($D$3="全部")+(销售明细!$B$2:$B$500=$D$3))>0)*--((($F$3="全部")+(销售明细!$C$2:$C$500=$F$3))>0)*--((($H$3="全部")+(销售明细!$D$2:$D$500=$H$3))>0)*--((($J$3="全部")+(销售明细!$L$2:$L$500=$J$3))>0)*--((($L$3="全部")+(销售明细!$M$2:$M$500=$L$3))>0)*销售明细!$O$2:$O$500) -> 4954 | R7: =SUMPRODUCT((销售明细!$A$2:$A$500=$P$7)*--((($D$3="全部")+(销售明细!$B$2:$B$500=$D$3))>0)*--((($F$3="全部")+(销售明细!$C$2:$C$500=$F$3))>0)*--((($H$3="全部")+(销售明细!$D$2:$D$500=$H$3))>0)*--((($J$3="全部")+(销售明细!$L$2:$L$500=$J$3))>0)*--((($L$3="全部")+(销售明细!$M$2:$M$500=$L$3))>0)*销售明细!$N$2:$N$500) -> 124
P8: =$B$3-2 -> 46170 | Q8: =SUMPRODUCT((销售明细!$A$2:$A$500=$P$8)*--((($D$3="全部")+(销售明细!$B$2:$B$500=$D$3))>0)*--((($F$3="全部")+(销售明细!$C$2:$C$500=$F$3))>0)*--((($H$3="全部")+(销售明细!$D$2:$D$500=$H$3))>0)*--((($J$3="全部")+(销售明细!$L$2:$L$500=$J$3))>0)*--((($L$3="全部")+(销售明细!$M$2:$M$500=$L$3))>0)*销售明细!$O$2:$O$500) -> 1662 | R8: =SUMPRODUCT((销售明细!$A$2:$A$500=$P$8)*--((($D$3="全部")+(销售明细!$B$2:$B$500=$D$3))>0)*--((($F$3="全部")+(销售明细!$C$2:$C$500=$F$3))>0)*--((($H$3="全部")+(销售明细!$D$2:$D$500=$H$3))>0)*--((($J$3="全部")+(销售明细!$L$2:$L$500=$J$3))>0)*--((($L$3="全部")+(销售明细!$M$2:$M$500=$L$3))>0)*销售明细!$N$2:$N$500) -> 53
B9: =IFERROR("环比昨日"&IF(B7/SUMPRODUCT((销售明细!$A$2:$A$500=$B$3-1)*--((($D$3="全部")+(销售明细!$B$2:$B$500=$D$3))>0)*--((($F$3="全部")+(销售明细!$C$2:$C$500=$F$3))>0)*--((($H$3="全部")+(销售明细!$D$2:$D$500=$H$3))>0)*--((($J$3="全部")+(销售明细!$L$2:$L$500=$J$3))>0)*--((($L$3="全部")+(销售明细!$M$2:$M$500=$L$3))>0)*销售明细!$O$2:$O$500)-1>=0,"↑","↓")&TEXT(ABS(B7/SUMPRODUCT((销售明细!$A$2:$A$500=$B$3-1)*--((($D$3="全部")+(销售明细!$B$2:$B$500=$D$3))>0)*--((($F$3="全部")+(销售明细!$C$2:$C$500=$F$3))>0)*--((($H$3="全部")+(销售明细!$D$2:$D$500=$H$3))>0)*--((($J$3="全部")+(销售明细!$L$2:$L$500=$J$3))>0)*--((($L$3="全部")+(销售明细!$M$2:$M$500=$L$3))>0)*销售明细!$O$2:$O$500)-1),"0.0%"),"环比昨日-") -> 环比昨日↑483.3% | D9: =IFERROR("环比昨日"&IF(D7/SUMPRODUCT((销售明细!$A$2:$A$500=$B$3-1)*--((($D$3="全部")+(销售明细!$B$2:$B$500=$D$3))>0)*--((($F$3="全部")+(销售明细!$C$2:$C$500=$F$3))>0)*--((($H$3="全部")+(销售明细!$D$2:$D$500=$H$3))>0)*--((($J$3="全部")+(销售明细!$L$2:$L$500=$J$3))>0)*--((($L$3="全部")+(销售明细!$M$2:$M$500=$L$3))>0)*销售明细!$N$2:$N$500)-1>=0,"↑","↓")&TEXT(ABS(D7/SUMPRODUCT((销售明细!$A$2:$A$500=$B$3-1)*--((($D$3="全部")+(销售明细!$B$2:$B$500=$D$3))>0)*--((($F$3="全部")+(销售明细!$C$2:$C$500=$F$3))>0)*--((($H$3="全部")+(销售明细!$D$2:$D$500=$H$3))>0)*--((($J$3="全部")+(销售明细!$L$2:$L$500=$J$3))>0)*--((($L$3="全部")+(销售明细!$M$2:$M$500=$L$3))>0)*销售明细!$N$2:$N$500)-1),"0.0%"),"环比昨日-") -> 环比昨日↑704.0% | H9: =IFERROR("环比昨日"&IF(H7/SUMPRODUCT((库存明细!$A$2:$A$500=$B$3-1)*--((($D$3="全部")+(库存明细!$B$2:$B$500=$D$3))>0)*--((($F$3="全部")+(库存明细!$C$2:$C$500=$F$3))>0)*--((($H$3="全部")+(库存明细!$D$2:$D$500=$H$3))>0)*库存明细!$J$2:$J$500)-1>=0,"↑","↓")&TEXT(ABS(H7/SUMPRODUCT((库存明细!$A$2:$A$500=$B$3-1)*--((($D$3="全部")+(库存明细!$B$2:$B$500=$D$3))>0)*--((($F$3="全部")+(库存明细!$C$2:$C$500=$F$3))>0)*--((($H$3="全部")+(库存明细!$D$2:$D$500=$H$3))>0)*库存明细!$J$2:$J$500)-1),"0.0%"),"环比昨日-") -> 环比昨日- | P9: =$B$3-1 -> 46171 | Q9: =SUMPRODUCT((销售明细!$A$2:$A$500=$P$9)*--((($D$3="全部")+(销售明细!$B$2:$B$500=$D$3))>0)*--((($F$3="全部")+(销售明细!$C$2:$C$500=$F$3))>0)*--((($H$3="全部")+(销售明细!$D$2:$D$500=$H$3))>0)*--((($J$3="全部")+(销售明细!$L$2:$L$500=$J$3))>0)*--((($L$3="全部")+(销售明细!$M$2:$M$500=$L$3))>0)*销售明细!$O$2:$O$500) -> 3921 | R9: =SUMPRODUCT((销售明细!$A$2:$A$500=$P$9)*--((($D$3="全部")+(销售明细!$B$2:$B$500=$D$3))>0)*--((($F$3="全部")+(销售明细!$C$2:$C$500=$F$3))>0)*--((($H$3="全部")+(销售明细!$D$2:$D$500=$H$3))>0)*--((($J$3="全部")+(销售明细!$L$2:$L$500=$J$3))>0)*--((($L$3="全部")+(销售明细!$M$2:$M$500=$L$3))>0)*销售明细!$N$2:$N$500) -> 177
P10: =$B$3-0 -> 46172 | Q10: =SUMPRODUCT((销售明细!$A$2:$A$500=$P$10)*--((($D$3="全部")+(销售明细!$B$2:$B$500=$D$3))>0)*--((($F$3="全部")+(销售明细!$C$2:$C$500=$F$3))>0)*--((($H$3="全部")+(销售明细!$D$2:$D$500=$H$3))>0)*--((($J$3="全部")+(销售明细!$L$2:$L$500=$J$3))>0)*--((($L$3="全部")+(销售明细!$M$2:$M$500=$L$3))>0)*销售明细!$O$2:$O$500) -> 22870 | R10: =SUMPRODUCT((销售明细!$A$2:$A$500=$P$10)*--((($D$3="全部")+(销售明细!$B$2:$B$500=$D$3))>0)*--((($F$3="全部")+(销售明细!$C$2:$C$500=$F$3))>0)*--((($H$3="全部")+(销售明细!$D$2:$D$500=$H$3))>0)*--((($J$3="全部")+(销售明细!$L$2:$L$500=$J$3))>0)*--((($L$3="全部")+(销售明细!$M$2:$M$500=$L$3))>0)*销售明细!$N$2:$N$500) -> 1423
B11: 门店明细-动销TOP5 | H11: 经营提醒
B12: 门店名称 | C12: 销售数量 | D12: 销售金额 | E12: 库存数量 | F12: 周转天数 | H12: 提醒项 | I12: 结果 | J12: 建议动作
B13: =IFERROR(INDEX($Y$44:$Y$53,MATCH(LARGE($AA$44:$AA$53,ROWS($B$13:B13)),$AA$44:$AA$53,0)),"") -> 武汉珞狮路店 | C13: =IFERROR(INDEX($Z$44:$Z$53,MATCH(B13,$Y$44:$Y$53,0)),0) -> 1100 | D13: =IFERROR(INDEX($AA$44:$AA$53,MATCH(B13,$Y$44:$Y$53,0)),0) -> 14300 | E13: =IFERROR(INDEX($AB$44:$AB$53,MATCH(B13,$Y$44:$Y$53,0)),0) -> 94942 | F13: =IFERROR(INDEX($AC$44:$AC$53,MATCH(B13,$Y$44:$Y$53,0)),"") -> 86.310909 | H13: 出货/POS | I13: =IFERROR(IF($J$24/$I$24<0.8,"偏低","正常"),"缺数据") -> 缺数据 | J13: 低于80%时检查补货或出货源 | P13: KA系统 | Q13: 销售额 | R13: 销量
B14: =IFERROR(INDEX($Y$44:$Y$53,MATCH(LARGE($AA$44:$AA$53,ROWS($B$13:B14)),$AA$44:$AA$53,0)),"") -> 闸北店 | C14: =IFERROR(INDEX($Z$44:$Z$53,MATCH(B14,$Y$44:$Y$53,0)),0) -> 235 | D14: =IFERROR(INDEX($AA$44:$AA$53,MATCH(B14,$Y$44:$Y$53,0)),0) -> 5235 | E14: =IFERROR(INDEX($AB$44:$AB$53,MATCH(B14,$Y$44:$Y$53,0)),0) -> 15089 | F14: =IFERROR(INDEX($AC$44:$AC$53,MATCH(B14,$Y$44:$Y$53,0)),"") -> 64.208511 | H14: 退货率 | I14: =IFERROR(IF($L$24>0.05,"偏高","正常"),"缺数据") -> 正常 | J14: 高于5%时按单品追踪原因 | P14: 大润发 | Q14: =SUMPRODUCT((销售明细!$A$2:$A$500=$B$3)*--((销售明细!$B$2:$B$500=P14)>0)*--((($F$3="全部")+(销售明细!$C$2:$C$500=$F$3))>0)*--((($H$3="全部")+(销售明细!$D$2:$D$500=$H$3))>0)*--((($J$3="全部")+(销售明细!$L$2:$L$500=$J$3))>0)*--((($L$3="全部")+(销售明细!$M$2:$M$500=$L$3))>0)*销售明细!$O$2:$O$500) -> 22870 | R14: =SUMPRODUCT((销售明细!$A$2:$A$500=$B$3)*--((销售明细!$B$2:$B$500=P14)>0)*--((($F$3="全部")+(销售明细!$C$2:$C$500=$F$3))>0)*--((($H$3="全部")+(销售明细!$D$2:$D$500=$H$3))>0)*--((($J$3="全部")+(销售明细!$L$2:$L$500=$J$3))>0)*--((($L$3="全部")+(销售明细!$M$2:$M$500=$L$3))>0)*销售明细!$N$2:$N$500) -> 1423
B15: =IFERROR(INDEX($Y$44:$Y$53,MATCH(LARGE($AA$44:$AA$53,ROWS($B$13:B15)),$AA$44:$AA$53,0)),"") -> 深圳创业天虹 | C15: =IFERROR(INDEX($Z$44:$Z$53,MATCH(B15,$Y$44:$Y$53,0)),0) -> 88 | D15: =IFERROR(INDEX($AA$44:$AA$53,MATCH(B15,$Y$44:$Y$53,0)),0) -> 3335 | E15: =IFERROR(INDEX($AB$44:$AB$53,MATCH(B15,$Y$44:$Y$53,0)),0) -> 5444 | F15: =IFERROR(INDEX($AC$44:$AC$53,MATCH(B15,$Y$44:$Y$53,0)),"") -> 61.863636 | H15: 周转风险 | I15: =IF($K$7>0,"存在超60天门店","正常") -> 正常 | J15: 优先处理库存大且无动销门店 | P15: 盒马 | Q15: =SUMPRODUCT((销售明细!$A$2:$A$500=$B$3)*--((销售明细!$B$2:$B$500=P15)>0)*--((($F$3="全部")+(销售明细!$C$2:$C$500=$F$3))>0)*--((($H$3="全部")+(销售明细!$D$2:$D$500=$H$3))>0)*--((($J$3="全部")+(销售明细!$L$2:$L$500=$J$3))>0)*--((($L$3="全部")+(销售明细!$M$2:$M$500=$L$3))>0)*销售明细!$O$2:$O$500) -> 22870 | R15: =SUMPRODUCT((销售明细!$A$2:$A$500=$B$3)*--((销售明细!$B$2:$B$500=P15)>0)*--((($F$3="全部")+(销售明细!$C$2:$C$500=$F$3))>0)*--((($H$3="全部")+(销售明细!$D$2:$D$500=$H$3))>0)*--((($J$3="全部")+(销售明细!$L$2:$L$500=$J$3))>0)*--((($L$3="全部")+(销售明细!$M$2:$M$500=$L$3))>0)*销售明细!$N$2:$N$500) -> 1423
B16: =IFERROR(INDEX($Y$44:$Y$53,MATCH(LARGE($AA$44:$AA$53,ROWS($B$13:B16)),$AA$44:$AA$53,0)),"") -> 杨浦店 | C16: =IFERROR(INDEX($Z$44:$Z$53,MATCH(B16,$Y$44:$Y$53,0)),0) -> 0 | D16: =IFERROR(INDEX($AA$44:$AA$53,MATCH(B16,$Y$44:$Y$53,0)),0) -> 0 | E16: =IFERROR(INDEX($AB$44:$AB$53,MATCH(B16,$Y$44:$Y$53,0)),0) -> 0 | F16: =IFERROR(INDEX($AC$44:$AC$53,MATCH(B16,$Y$44:$Y$53,0)),"") | H16: 数据质量 | I16: =IF(COUNTBLANK(销售明细!A2:O500)>200,"待补字段","可用") -> 待补字段 | J16: 补齐日期、门店、商品、金额字段 | P16: 华润 | Q16: =SUMPRODUCT((销售明细!$A$2:$A$500=$B$3)*--((销售明细!$B$2:$B$500=P16)>0)*--((($F$3="全部")+(销售明细!$C$2:$C$500=$F$3))>0)*--((($H$3="全部")+(销售明细!$D$2:$D$500=$H$3))>0)*--((($J$3="全部")+(销售明细!$L$2:$L$500=$J$3))>0)*--((($L$3="全部")+(销售明细!$M$2:$M$500=$L$3))>0)*销售明细!$O$2:$O$500) -> 22870 | R16: =SUMPRODUCT((销售明细!$A$2:$A$500=$B$3)*--((销售明细!$B$2:$B$500=P16)>0)*--((($F$3="全部")+(销售明细!$C$2:$C$500=$F$3))>0)*--((($H$3="全部")+(销售明细!$D$2:$D$500=$H$3))>0)*--((($J$3="全部")+(销售明细!$L$2:$L$500=$J$3))>0)*--((($L$3="全部")+(销售明细!$M$2:$M$500=$L$3))>0)*销售明细!$N$2:$N$500) -> 1423
B17: =IFERROR(INDEX($Y$44:$Y$53,MATCH(LARGE($AA$44:$AA$53,ROWS($B$13:B17)),$AA$44:$AA$53,0)),"") -> 杨浦店 | C17: =IFERROR(INDEX($Z$44:$Z$53,MATCH(B17,$Y$44:$Y$53,0)),0) -> 0 | D17: =IFERROR(INDEX($AA$44:$AA$53,MATCH(B17,$Y$44:$Y$53,0)),0) -> 0 | E17: =IFERROR(INDEX($AB$44:$AB$53,MATCH(B17,$Y$44:$Y$53,0)),0) -> 0 | F17: =IFERROR(INDEX($AC$44:$AC$53,MATCH(B17,$Y$44:$Y$53,0)),"") | P17: 沃尔玛 | Q17: =SUMPRODUCT((销售明细!$A$2:$A$500=$B$3)*--((销售明细!$B$2:$B$500=P17)>0)*--((($F$3="全部")+(销售明细!$C$2:$C$500=$F$3))>0)*--((($H$3="全部")+(销售明细!$D$2:$D$500=$H$3))>0)*--((($J$3="全部")+(销售明细!$L$2:$L$500=$J$3))>0)*--((($L$3="全部")+(销售明细!$M$2:$M$500=$L$3))>0)*销售明细!$O$2:$O$500) -> 22870 | R17: =SUMPRODUCT((销售明细!$A$2:$A$500=$B$3)*--((销售明细!$B$2:$B$500=P17)>0)*--((($F$3="全部")+(销售明细!$C$2:$C$500=$F$3))>0)*--((($H$3="全部")+(销售明细!$D$2:$D$500=$H$3))>0)*--((($J$3="全部")+(销售明细!$L$2:$L$500=$J$3))>0)*--((($L$3="全部")+(销售明细!$M$2:$M$500=$L$3))>0)*销售明细!$N$2:$N$500) -> 1423
P18: 永辉 | Q18: =SUMPRODUCT((销售明细!$A$2:$A$500=$B$3)*--((销售明细!$B$2:$B$500=P18)>0)*--((($F$3="全部")+(销售明细!$C$2:$C$500=$F$3))>0)*--((($H$3="全部")+(销售明细!$D$2:$D$500=$H$3))>0)*--((($J$3="全部")+(销售明细!$L$2:$L$500=$J$3))>0)*--((($L$3="全部")+(销售明细!$M$2:$M$500=$L$3))>0)*销售明细!$O$2:$O$500) -> 22870 | R18: =SUMPRODUCT((销售明细!$A$2:$A$500=$B$3)*--((销售明细!$B$2:$B$500=P18)>0)*--((($F$3="全部")+(销售明细!$C$2:$C$500=$F$3))>0)*--((($H$3="全部")+(销售明细!$D$2:$D$500=$H$3))>0)*--((($J$3="全部")+(销售明细!$L$2:$L$500=$J$3))>0)*--((($L$3="全部")+(销售明细!$M$2:$M$500=$L$3))>0)*销售明细!$N$2:$N$500) -> 1423
P19: 天虹 | Q19: =SUMPRODUCT((销售明细!$A$2:$A$500=$B$3)*--((销售明细!$B$2:$B$500=P19)>0)*--((($F$3="全部")+(销售明细!$C$2:$C$500=$F$3))>0)*--((($H$3="全部")+(销售明细!$D$2:$D$500=$H$3))>0)*--((($J$3="全部")+(销售明细!$L$2:$L$500=$J$3))>0)*--((($L$3="全部")+(销售明细!$M$2:$M$500=$L$3))>0)*销售明细!$O$2:$O$500) -> 22870 | R19: =SUMPRODUCT((销售明细!$A$2:$A$500=$B$3)*--((销售明细!$B$2:$B$500=P19)>0)*--((($F$3="全部")+(销售明细!$C$2:$C$500=$F$3))>0)*--((($H$3="全部")+(销售明细!$D$2:$D$500=$H$3))>0)*--((($J$3="全部")+(销售明细!$L$2:$L$500=$J$3))>0)*--((($L$3="全部")+(销售明细!$M$2:$M$500=$L$3))>0)*销售明细!$N$2:$N$500) -> 1423
P20: 比优特 | Q20: =SUMPRODUCT((销售明细!$A$2:$A$500=$B$3)*--((销售明细!$B$2:$B$500=P20)>0)*--((($F$3="全部")+(销售明细!$C$2:$C$500=$F$3))>0)*--((($H$3="全部")+(销售明细!$D$2:$D$500=$H$3))>0)*--((($J$3="全部")+(销售明细!$L$2:$L$500=$J$3))>0)*--((($L$3="全部")+(销售明细!$M$2:$M$500=$L$3))>0)*销售明细!$O$2:$O$500) -> 22870 | R20: =SUMPRODUCT((销售明细!$A$2:$A$500=$B$3)*--((销售明细!$B$2:$B$500=P20)>0)*--((($F$3="全部")+(销售明细!$C$2:$C$500=$F$3))>0)*--((($H$3="全部")+(销售明细!$D$2:$D$500=$H$3))>0)*--((($J$3="全部")+(销售明细!$L$2:$L$500=$J$3))>0)*--((($L$3="全部")+(销售明细!$M$2:$M$500=$L$3))>0)*销售明细!$N$2:$N$500) -> 1423
P21: 家得福 | Q21: =SUMPRODUCT((销售明细!$A$2:$A$500=$B$3)*--((销售明细!$B$2:$B$500=P21)>0)*--((($F$3="全部")+(销售明细!$C$2:$C$500=$F$3))>0)*--((($H$3="全部")+(销售明细!$D$2:$D$500=$H$3))>0)*--((($J$3="全部")+(销售明细!$L$2:$L$500=$J$3))>0)*--((($L$3="全部")+(销售明细!$M$2:$M$500=$L$3))>0)*销售明细!$O$2:$O$500) -> 22870 | R21: =SUMPRODUCT((销售明细!$A$2:$A$500=$B$3)*--((销售明细!$B$2:$B$500=P21)>0)*--((($F$3="全部")+(销售明细!$C$2:$C$500=$F$3))>0)*--((($H$3="全部")+(销售明细!$D$2:$D$500=$H$3))>0)*--((($J$3="全部")+(销售明细!$L$2:$L$500=$J$3))>0)*--((($L$3="全部")+(销售明细!$M$2:$M$500=$L$3))>0)*销售明细!$N$2:$N$500) -> 1423
H23: POS销售额 | I23: 出货金额 | J23: 退货金额 | K23: 退货率
H24: 汇总 | I24: =SUMPRODUCT((销售明细!$A$2:$A$500=$B$3)*--((($D$3="全部")+(销售明细!$B$2:$B$500=$D$3))>0)*--((($F$3="全部")+(销售明细!$C$2:$C$500=$F$3))>0)*--((($H$3="全部")+(销售明细!$D$2:$D$500=$H$3))>0)*--((($J$3="全部")+(销售明细!$L$2:$L$500=$J$3))>0)*--((($L$3="全部")+(销售明细!$M$2:$M$500=$L$3))>0)*销售明细!$O$2:$O$500) -> 22870 | J24: =SUMPRODUCT((出货退货!$A$2:$A$500=$B$3)*--((($D$3="全部")+(出货退货!$B$2:$B$500=$D$3))>0)*--((($F$3="全部")+(出货退货!$C$2:$C$500=$F$3))>0)*--((($H$3="全部")+(出货退货!$D$2:$D$500=$H$3))>0)*出货退货!$J$2:$J$500) -> #VALUE! | K24: =SUMPRODUCT((出货退货!$A$2:$A$500=$B$3)*--((($D$3="全部")+(出货退货!$B$2:$B$500=$D$3))>0)*--((($F$3="全部")+(出货退货!$C$2:$C$500=$F$3))>0)*--((($H$3="全部")+(出货退货!$D$2:$D$500=$H$3))>0)*出货退货!$L$2:$L$500) -> #VALUE! | L24: =IFERROR(K24/J24,0) -> 0
P25: 渠道 | Q25: 销售额 | R25: 占比
P26: POS | Q26: =SUMPRODUCT((销售明细!$A$2:$A$500=$B$3)*--((($D$3="全部")+(销售明细!$B$2:$B$500=$D$3))>0)*--((($F$3="全部")+(销售明细!$C$2:$C$500=$F$3))>0)*--((($H$3="全部")+(销售明细!$D$2:$D$500=$H$3))>0)*--((($J$3="全部")+(销售明细!$L$2:$L$500=$J$3))>0)*--((销售明细!$M$2:$M$500=P26)>0)*销售明细!$O$2:$O$500) -> 22870 | R26: =IFERROR(Q26/SUM($Q$26:$Q$32),0) -> 0.16666667
P27: 线下 | Q27: =SUMPRODUCT((销售明细!$A$2:$A$500=$B$3)*--((($D$3="全部")+(销售明细!$B$2:$B$500=$D$3))>0)*--((($F$3="全部")+(销售明细!$C$2:$C$500=$F$3))>0)*--((($H$3="全部")+(销售明细!$D$2:$D$500=$H$3))>0)*--((($J$3="全部")+(销售明细!$L$2:$L$500=$J$3))>0)*--((销售明细!$M$2:$M$500=P27)>0)*销售明细!$O$2:$O$500) -> 22870 | R27: =IFERROR(Q27/SUM($Q$26:$Q$32),0) -> 0.16666667
P28: 线上 | Q28: =SUMPRODUCT((销售明细!$A$2:$A$500=$B$3)*--((($D$3="全部")+(销售明细!$B$2:$B$500=$D$3))>0)*--((($F$3="全部")+(销售明细!$C$2:$C$500=$F$3))>0)*--((($H$3="全部")+(销售明细!$D$2:$D$500=$H$3))>0)*--((($J$3="全部")+(销售明细!$L$2:$L$500=$J$3))>0)*--((销售明细!$M$2:$M$500=P28)>0)*销售明细!$O$2:$O$500) -> 22870 | R28: =IFERROR(Q28/SUM($Q$26:$Q$32),0) -> 0.16666667
P29: 京东到家 | Q29: =SUMPRODUCT((销售明细!$A$2:$A$500=$B$3)*--((($D$3="全部")+(销售明细!$B$2:$B$500=$D$3))>0)*--((($F$3="全部")+(销售明细!$C$2:$C$500=$F$3))>0)*--((($H$3="全部")+(销售明细!$D$2:$D$500=$H$3))>0)*--((($J$3="全部")+(销售明细!$L$2:$L$500=$J$3))>0)*--((销售明细!$M$2:$M$500=P29)>0)*销售明细!$O$2:$O$500) -> 22870 | R29: =IFERROR(Q29/SUM($Q$26:$Q$32),0) -> 0.16666667
P30: 美团 | Q30: =SUMPRODUCT((销售明细!$A$2:$A$500=$B$3)*--((($D$3="全部")+(销售明细!$B$2:$B$500=$D$3))>0)*--((($F$3="全部")+(销售明细!$C$2:$C$500=$F$3))>0)*--((($H$3="全部")+(销售明细!$D$2:$D$500=$H$3))>0)*--((($J$3="全部")+(销售明细!$L$2:$L$500=$J$3))>0)*--((销售明细!$M$2:$M$500=P30)>0)*销售明细!$O$2:$O$500) -> 22870 | R30: =IFERROR(Q30/SUM($Q$26:$Q$32),0) -> 0.16666667
P31: 天虹到家 | Q31: =SUMPRODUCT((销售明细!$A$2:$A$500=$B$3)*--((($D$3="全部")+(销售明细!$B$2:$B$500=$D$3))>0)*--((($F$3="全部")+(销售明细!$C$2:$C$500=$F$3))>0)*--((($H$3="全部")+(销售明细!$D$2:$D$500=$H$3))>0)*--((($J$3="全部")+(销售明细!$L$2:$L$500=$J$3))>0)*--((销售明细!$M$2:$M$500=P31)>0)*销售明细!$O$2:$O$500) -> 22870 | R31: =IFERROR(Q31/SUM($Q$26:$Q$32),0) -> 0.16666667
P32: 其他 | Q32: =SUMPRODUCT((销售明细!$A$2:$A$500=$B$3)*--((($D$3="全部")+(销售明细!$B$2:$B$500=$D$3))>0)*--((($F$3="全部")+(销售明细!$C$2:$C$500=$F$3))>0)*--((($H$3="全部")+(销售明细!$D$2:$D$500=$H$3))>0)*--((($J$3="全部")+(销售明细!$L$2:$L$500=$J$3))>0)*--(ISNA(MATCH(销售明细!$M$2:$M$500,{"POS","线下","线上","京东到家","美团","天虹到家"},0)))*销售明细!$O$2:$O$500) -> 0 | R32: =IFERROR(Q32/SUM($Q$26:$Q$32),0) -> 0
P36: 大区 | Q36: 平均周转 | R36: 超60天门店
P37: 华东 | Q37: =IFERROR(SUMPRODUCT((库存明细!$A$2:$A$500=$B$3)*--((库存明细!$C$2:$C$500=P37)>0)*--((($D$3="全部")+(库存明细!$B$2:$B$500=$D$3))>0)*--((($H$3="全部")+(库存明细!$D$2:$D$500=$H$3))>0)*库存明细!$N$2:$N$500)/SUMPRODUCT((库存明细!$A$2:$A$500=$B$3)*--((库存明细!$C$2:$C$500=P37)>0)*--((($D$3="全部")+(库存明细!$B$2:$B$500=$D$3))>0)*--((($H$3="全部")+(库存明细!$D$2:$D$500=$H$3))>0)*--(库存明细!$N$2:$N$500<>"")),0) -> 84.024509 | R37: =COUNTIFS(库存明细!$A$2:$A$500,$B$3,库存明细!$C$2:$C$500,P37,库存明细!$O$2:$O$500,"Y") -> 0
P38: 华南 | Q38: =IFERROR(SUMPRODUCT((库存明细!$A$2:$A$500=$B$3)*--((库存明细!$C$2:$C$500=P38)>0)*--((($D$3="全部")+(库存明细!$B$2:$B$500=$D$3))>0)*--((($H$3="全部")+(库存明细!$D$2:$D$500=$H$3))>0)*库存明细!$N$2:$N$500)/SUMPRODUCT((库存明细!$A$2:$A$500=$B$3)*--((库存明细!$C$2:$C$500=P38)>0)*--((($D$3="全部")+(库存明细!$B$2:$B$500=$D$3))>0)*--((($H$3="全部")+(库存明细!$D$2:$D$500=$H$3))>0)*--(库存明细!$N$2:$N$500<>"")),0) -> 84.024509 | R38: =COUNTIFS(库存明细!$A$2:$A$500,$B$3,库存明细!$C$2:$C$500,P38,库存明细!$O$2:$O$500,"Y") -> 1
P39: 华北 | Q39: =IFERROR(SUMPRODUCT((库存明细!$A$2:$A$500=$B$3)*--((库存明细!$C$2:$C$500=P39)>0)*--((($D$3="全部")+(库存明细!$B$2:$B$500=$D$3))>0)*--((($H$3="全部")+(库存明细!$D$2:$D$500=$H$3))>0)*库存明细!$N$2:$N$500)/SUMPRODUCT((库存明细!$A$2:$A$500=$B$3)*--((库存明细!$C$2:$C$500=P39)>0)*--((($D$3="全部")+(库存明细!$B$2:$B$500=$D$3))>0)*--((($H$3="全部")+(库存明细!$D$2:$D$500=$H$3))>0)*--(库存明细!$N$2:$N$500<>"")),0) -> 84.024509 | R39: =COUNTIFS(库存明细!$A$2:$A$500,$B$3,库存明细!$C$2:$C$500,P39,库存明细!$O$2:$O$500,"Y") -> 0
P40: 华中 | Q40: =IFERROR(SUMPRODUCT((库存明细!$A$2:$A$500=$B$3)*--((库存明细!$C$2:$C$500=P40)>0)*--((($D$3="全部")+(库存明细!$B$2:$B$500=$D$3))>0)*--((($H$3="全部")+(库存明细!$D$2:$D$500=$H$3))>0)*库存明细!$N$2:$N$500)/SUMPRODUCT((库存明细!$A$2:$A$500=$B$3)*--((库存明细!$C$2:$C$500=P40)>0)*--((($D$3="全部")+(库存明细!$B$2:$B$500=$D$3))>0)*--((($H$3="全部")+(库存明细!$D$2:$D$500=$H$3))>0)*--(库存明细!$N$2:$N$500<>"")),0) -> 84.024509 | R40: =COUNTIFS(库存明细!$A$2:$A$500,$B$3,库存明细!$C$2:$C$500,P40,库存明细!$O$2:$O$500,"Y") -> 0
P41: 东北 | Q41: =IFERROR(SUMPRODUCT((库存明细!$A$2:$A$500=$B$3)*--((库存明细!$C$2:$C$500=P41)>0)*--((($D$3="全部")+(库存明细!$B$2:$B$500=$D$3))>0)*--((($H$3="全部")+(库存明细!$D$2:$D$500=$H$3))>0)*库存明细!$N$2:$N$500)/SUMPRODUCT((库存明细!$A$2:$A$500=$B$3)*--((库存明细!$C$2:$C$500=P41)>0)*--((($D$3="全部")+(库存明细!$B$2:$B$500=$D$3))>0)*--((($H$3="全部")+(库存明细!$D$2:$D$500=$H$3))>0)*--(库存明细!$N$2:$N$500<>"")),0) -> 84.024509 | R41: =COUNTIFS(库存明细!$A$2:$A$500,$B$3,库存明细!$C$2:$C$500,P41,库存明细!$O$2:$O$500,"Y") -> 1
Y43: 门店名称 | Z43: 销售数量 | AA43: 销售金额 | AB43: 库存数量 | AC43: 周转天数
Y44: =门店维表!C2 -> 闸北店 | Z44: =SUMIFS(销售明细!$N$2:$N$500,销售明细!$A$2:$A$500,$B$3,销售明细!$F$2:$F$500,Y44) -> 235 | AA44: =SUMIFS(销售明细!$O$2:$O$500,销售明细!$A$2:$A$500,$B$3,销售明细!$F$2:$F$500,Y44) -> 5235 | AB44: =SUMIFS(库存明细!$J$2:$J$500,库存明细!$A$2:$A$500,$B$3,库存明细!$F$2:$F$500,Y44) -> 15089 | AC44: =IFERROR(AB44/Z44,"") -> 64.208511
P45: 品项 | Q45: 销售额 | R45: 销量 | Y45: =门店维表!C3 -> 杨浦店 | Z45: =SUMIFS(销售明细!$N$2:$N$500,销售明细!$A$2:$A$500,$B$3,销售明细!$F$2:$F$500,Y45) -> 0 | AA45: =SUMIFS(销售明细!$O$2:$O$500,销售明细!$A$2:$A$500,$B$3,销售明细!$F$2:$F$500,Y45) -> 0 | AB45: =SUMIFS(库存明细!$J$2:$J$500,库存明细!$A$2:$A$500,$B$3,库存明细!$F$2:$F$500,Y45) -> 0 | AC45: =IFERROR(AB45/Z45,"")
...

Sheet 销售明细
A1: 数据日期 | B1: KA系统 | C1: 大区 | D1: 省份 | E1: 门店编码 | F1: 门店名称 | G1: 是否DC | H1: 商品编码 | I1: 商品条码 | J1: 商品名称 | K1: 规格 | L1: 温层 | M1: 渠道 | N1: 销售数量 | O1: 销售金额 | P1: 含税口径 | Q1: 动销标记 | R1: 备注
A2: 46166 | B2: 大润发 | C2: 华东 | D2: 上海 | E2: 1001 | F2: 闸北店 | G2: 否 | H2: 4354168 | I2: 697000000001 | J2: 脱骨侠无骨鸡爪(柠檬味) | K2: 158g/袋 | L2: 常温 | M2: 线下 | N2: 210 | O2: 4675 | P2: 含税 | Q2: Y
A3: 46166 | B3: 大润发 | C3: 华东 | D3: 江苏 | E3: 1002 | F3: 杨浦店 | G3: 否 | H3: 4354169 | I3: 697000000002 | J3: 脱骨侠无骨鸡爪(泡椒味) | K3: 158g/袋 | L3: 常温 | M3: 京东到家 | N3: 86 | O3: 1978 | P3: 含税 | Q3: Y
A4: 46167 | B4: 大润发 | C4: 华南 | D4: 广东 | E4: 5001 | F4: 广州天河店 | G4: 否 | H4: 4502138 | I4: 697000000003 | J4: 脱骨侠虎皮凤爪(白松露味) | K4: 220g/盒 | L4: 冷藏 | M4: 美团 | N4: 134 | O4: 3350 | P4: 含税 | Q4: Y
A5: 46167 | B5: 沃尔玛 | C5: 华南 | D5: 广东 | E5: 101 | F5: 沃尔玛广州天河店 | G5: 否 | H5: 25354863 | I5: 0697765695110 | J5: 常温脱骨侠无骨鸡爪柠檬 | K5: 158g/袋 | L5: 常温 | M5: POS | N5: 190 | O5: 3800 | P5: 未税 | Q5: Y
A6: 46168 | B6: 华润 | C6: 华北 | D6: 北京 | E6: 204392 | F6: 皇姑店 | G6: 否 | H6: 5150673 | I6: 6973883075622 | J6: 脱骨侠无骨鸡爪(柠檬味)158g | K6: 158g/袋 | L6: 常温 | M6: 线下 | N6: 150 | O6: 2895 | P6: 含税 | Q6: Y
A7: 46168 | B7: 盒马 | C7: 华中 | D7: 湖北 | E7: HM001 | F7: 武汉珞狮路店 | G7: 否 | H7: 431448153 | I7: 6973883075387 | J7: 盒马工坊 蒜香无骨鸡爪 230g | K7: 230g/盒 | L7: 冷藏 | M7: POS | N7: 980 | O7: 12740 | P7: 含税 | Q7: Y
A8: 46169 | B8: 永辉 | C8: 华东 | D8: 浙江 | E8: 9626 | F8: 滨江区龙湖天街店 | G8: 否 | H8: 1830795 | I8: 6973883073277 | J8: 脱骨侠蒜香酸甜辣无骨鸡爪780g | K8: 780g/罐 | L8: 冷藏 | M8: POS | N8: 52 | O8: 2225 | P8: 含税 | Q8: Y
A9: 46169 | B9: 天虹 | C9: 华南 | D9: 广东 | E9: 104 | F9: 深圳创业天虹 | G9: 否 | H9: v000110869 | I9: 6977656954114 | J9: 脱骨侠双椒无骨鸭掌 | K9: 320g/袋 | L9: 冷藏 | M9: 天虹到家 | N9: 72 | O9: 2729 | P9: 含税 | Q9: Y
A10: 46170 | B10: 比优特 | C10: 东北 | D10: 黑龙江 | E10: 2201 | F10: 麓林山店 | G10: 否 | H10: 1156752 | I10: 6973883073277 | J10: 脱骨侠无骨鸡爪蒜香酸甜辣780g | K10: 780g/罐 | L10: 冷藏 | M10: POS | N10: 18 | O10: 629 | P10: 含税 | Q10: Y
A11: 46170 | B11: 家得福 | C11: 华东 | D11: 江苏 | E11: 1001 | F11: 家得福海棠店 | G11: 否 | H11: 10081319 | I11: 6973883073284 | J11: 脱骨侠酸辣柠檬无骨鸡爪780g | K11: 780g/罐 | L11: 冷藏 | M11: POS | N11: 35 | O11: 1033 | P11: 含税 | Q11: Y
A12: 46171 | B12: 大润发 | C12: 华北 | D12: 天津 | E12: 6001 | F12: 天津南开店 | G12: 否 | H12: 4354172 | I12: 697000000004 | J12: 脱骨侠盐焗鸡爪 | K12: 138g/袋 | L12: 常温 | M12: 线下 | N12: 98 | O12: 1421 | P12: 含税 | Q12: Y
A13: 46171 | B13: 沃尔玛 | C13: 华东 | D13: 浙江 | E13: 2470 | F13: 沃尔玛赤峰玉龙大街店 | G13: 否 | H13: 25325573 | I13: 0697388307468 | J13: 冷藏蒜香凤爪 | K13: 230g/盒 | L13: 冷藏 | M13: POS | N13: 79 | O13: 2500 | P13: 未税 | Q13: Y
... A16: 46172 | B16: 天虹 | C16: 华南 | D16: 广东 | E16: 104 | F16: 深圳创业天虹 | G16: 否 | H16: v000110869 | I16: 6977656954114 | J16: 脱骨侠双椒无骨鸭掌 | K16: 320g/袋 | L16: 冷藏 | M16: 京东到家 | N16: 88 | O16: 3335 | P16: 含税 | Q16: Y

Sheet 库存明细
A1: 数据日期 | B1: KA系统 | C1: 大区 | D1: 省份 | E1: 门店编码 | F1: 门店名称 | G1: 是否DC | H1: 商品编码 | I1: 商品名称 | J1: 门店库存 | K1: DC库存 | L1: 在途/待收 | M1: 近7日平均销量 | N1: 周转天数 | O1: 是否超60天 | P1: 备注
A2: 46172 | B2: 大润发 | C2: 华东 | D2: 上海 | E2: 1001 | F2: 闸北店 | G2: 否 | H2: 4354168 | I2: 脱骨侠无骨鸡爪(柠檬味) | J2: 15089 | K2: 1950 | L2: 725 | M2: 620 | N2: =IFERROR(J2/M2,"") -> 24.337097 | O2: =IF(N2="","",IF(N2>60,"Y","N")) -> N
A3: 46172 | B3: 大润发 | C3: 华南 | D3: 广东 | E3: 5001 | F3: 广州天河店 | G3: 否 | H3: 4502138 | I3: 脱骨侠虎皮凤爪(白松露味) | J3: 13619 | K3: 1250 | L3: 550 | M3: 210 | N3: =IFERROR(J3/M3,"") -> 64.852381 | O3: =IF(N3="","",IF(N3>60,"Y","N")) -> Y
A4: 46172 | B4: 沃尔玛 | C4: 华南 | D4: 广东 | E4: 101 | F4: 沃尔玛广州天河店 | G4: 否 | H4: 25354863 | I4: 常温脱骨侠无骨鸡爪柠檬 | J4: 30943 | K4: 0 | L4: 840 | M4: 1408 | N4: =IFERROR(J4/M4,"") -> 21.976562 | O4: =IF(N4="","",IF(N4>60,"Y","N")) -> N
A5: 46172 | B5: 华润 | C5: 华北 | D5: 北京 | E5: 204392 | F5: 皇姑店 | G5: 否 | H5: 5150673 | I5: 脱骨侠无骨鸡爪(柠檬味)158g | J5: 5233 | K5: 0 | L5: 0 | M5: 245 | N5: =IFERROR(J5/M5,"") -> 21.359184 | O5: =IF(N5="","",IF(N5>60,"Y","N")) -> N
A6: 46172 | B6: 盒马 | C6: 华中 | D6: 湖北 | E6: HM001 | F6: 武汉珞狮路店 | G6: 否 | H6: 431448153 | I6: 盒马工坊 蒜香无骨鸡爪 230g | J6: 94942 | K6: 0 | L6: 21250 | M6: 20146 | N6: =IFERROR(J6/M6,"") -> 4.7126973 | O6: =IF(N6="","",IF(N6>60,"Y","N")) -> N
A7: 46172 | B7: 永辉 | C7: 华东 | D7: 浙江 | E7: 9626 | F7: 滨江区龙湖天街店 | G7: 否 | H7: 1830795 | I7: 脱骨侠蒜香酸甜辣无骨鸡爪780g | J7: 74 | K7: 0 | L7: 0 | M7: 7 | N7: =IFERROR(J7/M7,"") -> 10.571429 | O7: =IF(N7="","",IF(N7>60,"Y","N")) -> N
A8: 46172 | B8: 天虹 | C8: 华南 | D8: 广东 | E8: 104 | F8: 深圳创业天虹 | G8: 否 | H8: v000110869 | I8: 脱骨侠双椒无骨鸭掌 | J8: 5444 | K8: 0 | L8: 0 | M8: 129 | N8: =IFERROR(J8/M8,"") -> 42.20155 | O8: =IF(N8="","",IF(N8>60,"Y","N")) -> N
A9: 46172 | B9: 比优特 | C9: 东北 | D9: 黑龙江 | E9: 2201 | F9: 麓林山店 | G9: 否 | H9: 1156752 | I9: 脱骨侠无骨鸡爪蒜香酸甜辣780g | J9: 15925 | K9: 0 | L9: 0 | M9: 31 | N9: =IFERROR(J9/M9,"") -> 513.70968 | O9: =IF(N9="","",IF(N9>60,"Y","N")) -> Y
A10: 46172 | B10: 家得福 | C10: 华东 | D10: 江苏 | E10: 1001 | F10: 家得福海棠店 | G10: 否 | H10: 10081319 | I10: 脱骨侠酸辣柠檬无骨鸡爪780g | J10: 315 | K10: 0 | L10: 0 | M10: 6 | N10: =IFERROR(J10/M10,"") -> 52.5 | O10: =IF(N10="","",IF(N10>60,"Y","N")) -> N

Sheet 出货退货
A1: 数据日期 | B1: KA系统 | C1: 大区 | D1: 省份 | E1: 门店编码 | F1: 门店名称 | G1: 商品编码 | H1: 商品名称 | I1: 出货数量 | J1: 出货金额 | K1: 退货数量 | L1: 退货金额 | M1: 出货字段来源 | N1: 退货字段来源 | O1: 备注
A2: 46172 | B2: 盒马 | C2: 华中 | D2: 湖北 | E2: HM001 | F2: 武汉珞狮路店 | G2: 431448153 | H2: 盒马工坊 蒜香无骨鸡爪 230g | I2: 24043 | K2: 120 | M2: 当天入库采购件数数量 | N2: 退货数量
A3: 46172 | B3: 家得福 | C3: 华东 | D3: 江苏 | E3: 1001 | F3: 家得福海棠店 | G3: 10081319 | H3: 脱骨侠酸辣柠檬无骨鸡爪780g | I3: 315 | J3: 9050 | K3: 0 | L3: 0 | M3: 进货数量/含税进货金额 | N3: 含税退补金额
A4: 46172 | B4: 大润发 | C4: 华东 | D4: 上海 | E4: 1001 | F4: 闸北店 | G4: 4354168 | H4: 脱骨侠无骨鸡爪(柠檬味) | I4: 725 | M4: 待收 | N4: 源表无退货发生 | O4: 待收不等于真实出货，需业务确认
A5: 46172 | B5: 沃尔玛 | C5: 华南 | D5: 广东 | E5: 101 | F5: 沃尔玛广州天河店 | G5: 25354863 | H5: 常温脱骨侠无骨鸡爪柠檬 | M5: 缺进货源 | N5: 缺退货源 | O5: 需补退货/进货明细

Sheet 门店维表
A1: KA系统 | B1: 门店编码 | C1: 门店名称 | D1: 是否DC | E1: 大区 | F1: 省份 | G1: 城市 | H1: 内外区 | I1: 门店状态
A2: 大润发 | B2: 1001 | C2: 闸北店 | D2: 否 | E2: 华东 | F2: 上海 | G2: 上海 | H2: 内区 | I2: 开业
A3: 大润发 | B3: 1002 | C3: 杨浦店 | D3: 否 | E3: 华东 | F3: 上海 | G3: 上海 | H3: 内区 | I3: 开业
A4: 大润发 | B4: 5001 | C4: 广州天河店 | D4: 否 | E4: 华南 | F4: 广东 | G4: 广州 | H4: 外区 | I4: 开业
A5: 沃尔玛 | B5: 101 | C5: 沃尔玛广州天河店 | D5: 否 | E5: 华南 | F5: 广东 | G5: 广州 | H5: 外区 | I5: 开业
A6: 华润 | B6: 204392 | C6: 皇姑店 | D6: 否 | E6: 华北 | F6: 北京 | G6: 北京 | H6: 外区 | I6: 开业
A7: 盒马 | B7: HM001 | C7: 武汉珞狮路店 | D7: 否 | E7: 华中 | F7: 湖北 | G7: 武汉 | H7: 外区 | I7: 开业
A8: 永辉 | B8: 9626 | C8: 滨江区龙湖天街店 | D8: 否 | E8: 华东 | F8: 浙江 | G8: 杭州 | H8: 内区 | I8: 开业
A9: 天虹 | B9: 104 | C9: 深圳创业天虹 | D9: 否 | E9: 华南 | F9: 广东 | G9: 深圳 | H9: 外区 | I9: 开业
A10: 比优特 | B10: 2201 | C10: 麓林山店 | D10: 否 | E10: 东北 | F10: 黑龙江 | G10: 鹤岗 | H10: 外区 | I10: 开业
A11: 家得福 | B11: 1001 | C11: 家得福海棠店 | D11: 否 | E11: 华东 | F11: 江苏 | G11: 连云港 | H11: 内区 | I11: 开业

Sheet 商品维表
A1: KA系统 | B1: 商品编码 | C1: 商品条码 | D1: 统一商品名 | E1: 系统商品名 | F1: 规格 | G1: 温层 | H1: 口味 | I1: 产品线 | J1: 是否核心品
A2: 大润发 | B2: 4354168 | C2: 697000000001 | D2: 无骨鸡爪 柠檬味 158g | E2: 脱骨侠无骨鸡爪(柠檬味) | F2: 158g/袋 | G2: 常温 | H2: 柠檬 | I2: 无骨鸡爪 | J2: Y
A3: 大润发 | B3: 4502138 | C3: 697000000003 | D3: 虎皮凤爪 白松露味 | E3: 脱骨侠虎皮凤爪(白松露味) | F3: 220g/盒 | G3: 冷藏 | H3: 白松露 | I3: 虎皮凤爪 | J3: Y
A4: 沃尔玛 | B4: 25354863 | C4: 0697765695110 | D4: 无骨鸡爪 柠檬味 158g | E4: 常温脱骨侠无骨鸡爪柠檬 | F4: 158g/袋 | G4: 常温 | H4: 柠檬 | I4: 无骨鸡爪 | J4: Y
A5: 盒马 | B5: 431448153 | C5: 6973883075387 | D5: 蒜香无骨鸡爪 230g | E5: 盒马工坊 蒜香无骨鸡爪 230g | F5: 230g/盒 | G5: 冷藏 | H5: 蒜香 | I5: 无骨鸡爪 | J5: Y
A6: 天虹 | B6: v000110869 | C6: 6977656954114 | D6: 双椒无骨鸭掌 320g | E6: 脱骨侠双椒无骨鸭掌 | F6: 320g/袋 | G6: 冷藏 | H6: 双椒 | I6: 鸭掌 | J6: Y

Sheet 指标口径
A1: 指标 | B1: 计算口径 | C1: 建议字段/公式 | D1: 注意事项
A2: 销售数量 | B2: 按日期、系统、门店、商品、渠道汇总 POS 销售数量 | C2: SUMIFS(销售明细[销售数量], ...) | D2: 不同系统最小单位需统一
A3: 销售金额 | B3: 按同维度汇总 POS 销售金额，优先含税口径 | C3: SUMIFS(销售明细[销售金额], ...) | D3: 沃尔玛部分为未税，需保留标签或换算
A4: 出货数量 | B4: 优先取进货/入库/日收/月收/待收等字段 | C4: 出货退货[出货数量] | D4: 待收不一定等于真实出货
A5: 近7日平均销量 | B5: 建议 D-7 至 D-1 销售数量合计 / 7 | C5: SUMIFS(...)/7 | D5: 不建议包含数据日
A6: 门店库存周转天数 | B6: 门店库存 / 近7日平均销量 | C6: '=IFERROR(门店库存/近7日平均销量,"") | D6: 均销为0且有库存时标记无动销库存
A7: PSD | B7: 销售数量 / 有库存门店数 | C7: 销售数量/有库存门店数 | D7: 需确认分母沿用现有日报口径
A8: 超60天门店数 | B8: 周转天数>60 且门店库存>0 的门店数 | C8: COUNTIFS(...) | D8: 排除 DC、闭店、小店需依赖门店维表
A9: 退货率 | B9: 当月退货数量 / 当月进货数量 | C9: 退货数量/进货数量 | D9: 沃尔玛当前缺退货/进货源
